2025-05-14 18:55:06,830 INFO    MainThread:2633 [wandb_init.py:setup_run_log_directory():724] Logging user logs to /Users/stephenmarcou/Documents/ETH Zurich/Semester 2/AI Center Projects in Machine Learning/pmlr25-lpn/src/wandb/run-20250514_185506-3ei0s5s5/logs/debug.log
2025-05-14 18:55:06,830 INFO    MainThread:2633 [wandb_init.py:setup_run_log_directory():725] Logging internal logs to /Users/stephenmarcou/Documents/ETH Zurich/Semester 2/AI Center Projects in Machine Learning/pmlr25-lpn/src/wandb/run-20250514_185506-3ei0s5s5/logs/debug-internal.log
2025-05-14 18:55:06,831 INFO    MainThread:2633 [wandb_init.py:monkeypatch_ipython():643] configuring jupyter hooks <wandb.sdk.wandb_init._WandbInit object at 0x1710fe7a0>
2025-05-14 18:55:06,831 INFO    MainThread:2633 [wandb_init.py:init():852] calling init triggers
2025-05-14 18:55:06,831 INFO    MainThread:2633 [wandb_init.py:init():857] wandb.init called with sweep_config: {}
config: {'_wandb': {}}
2025-05-14 18:55:06,831 INFO    MainThread:2633 [wandb_init.py:init():893] starting backend
2025-05-14 18:55:06,831 INFO    MainThread:2633 [wandb_init.py:init():897] sending inform_init request
2025-05-14 18:55:06,836 INFO    MainThread:2633 [backend.py:_multiprocessing_setup():101] multiprocessing start_methods=spawn,fork,forkserver, using: spawn
2025-05-14 18:55:06,836 INFO    MainThread:2633 [wandb_init.py:init():907] backend started and connected
2025-05-14 18:55:06,843 INFO    MainThread:2633 [wandb_run.py:_label_probe_notebook():1369] probe notebook
2025-05-14 18:55:06,855 INFO    MainThread:2633 [wandb_init.py:init():1002] updated telemetry
2025-05-14 18:55:07,009 INFO    MainThread:2633 [wandb_init.py:init():1026] communicating run to backend with 90.0 second timeout
2025-05-14 18:55:08,751 INFO    MainThread:2633 [wandb_init.py:init():1101] starting run threads in backend
2025-05-14 18:55:08,857 INFO    MainThread:2633 [wandb_run.py:_console_start():2566] atexit reg
2025-05-14 18:55:08,857 INFO    MainThread:2633 [wandb_run.py:_redirect():2414] redirect: wrap_raw
2025-05-14 18:55:08,857 INFO    MainThread:2633 [wandb_run.py:_redirect():2483] Wrapping output streams.
2025-05-14 18:55:08,857 INFO    MainThread:2633 [wandb_run.py:_redirect():2506] Redirects installed.
2025-05-14 18:55:08,858 INFO    MainThread:2633 [wandb_init.py:init():1147] run started, returning control to user process
2025-05-14 19:57:59,266 WARNING MsgRouterThr:2633 [router.py:message_loop():63] [no run ID] message_loop has been closed
Traceback (most recent call last):
  File "/opt/miniconda3/envs/lpn_py310/lib/python3.10/site-packages/wandb/sdk/interface/router_sock.py", line 27, in _read_message
    return self._sock_client.read_server_response(timeout=1)
  File "/opt/miniconda3/envs/lpn_py310/lib/python3.10/site-packages/wandb/sdk/lib/sock_client.py", line 235, in read_server_response
    data = self._read_packet_bytes(timeout=timeout)
  File "/opt/miniconda3/envs/lpn_py310/lib/python3.10/site-packages/wandb/sdk/lib/sock_client.py", line 220, in _read_packet_bytes
    raise SockClientClosedError
wandb.sdk.lib.sock_client.SockClientClosedError

The above exception was the direct cause of the following exception:

Traceback (most recent call last):
  File "/opt/miniconda3/envs/lpn_py310/lib/python3.10/site-packages/wandb/sdk/interface/router.py", line 56, in message_loop
    msg = self._read_message()
  File "/opt/miniconda3/envs/lpn_py310/lib/python3.10/site-packages/wandb/sdk/interface/router_sock.py", line 29, in _read_message
    raise MessageRouterClosedError from e
wandb.sdk.interface.router.MessageRouterClosedError
2025-05-14 19:57:59,310 INFO    MsgRouterThr:2633 [mailbox.py:close():129] [no run ID] Closing mailbox, abandoning 9 handles.
2025-05-14 19:57:59,507 INFO    MainThread:2633 [wandb_init.py:_post_run_cell_hook():613] [no run ID] resuming backend
2025-05-14 19:58:01,312 INFO    MainThread:2633 [jupyter.py:save_ipynb():401] [no run ID] not saving jupyter notebook
2025-05-14 19:58:01,313 INFO    MainThread:2633 [wandb_init.py:_pre_run_cell_hook():602] [no run ID] pausing backend
2025-05-14 19:58:01,315 ERROR   MainThread:2633 [redirect.py:_on_write():664] [no run ID] error in stdout callback
Traceback (most recent call last):
  File "/opt/miniconda3/envs/lpn_py310/lib/python3.10/site-packages/IPython/core/events.py", line 82, in trigger
    func(*args, **kwargs)
  File "/opt/miniconda3/envs/lpn_py310/lib/python3.10/site-packages/wandb/sdk/wandb_init.py", line 603, in _pre_run_cell_hook
    self.backend.interface.publish_pause()
  File "/opt/miniconda3/envs/lpn_py310/lib/python3.10/site-packages/wandb/sdk/interface/interface.py", line 771, in publish_pause
    self._publish_pause(pause)
  File "/opt/miniconda3/envs/lpn_py310/lib/python3.10/site-packages/wandb/sdk/interface/interface_shared.py", line 289, in _publish_pause
    self._publish(rec)
  File "/opt/miniconda3/envs/lpn_py310/lib/python3.10/site-packages/wandb/sdk/interface/interface_sock.py", line 39, in _publish
    self._sock_client.send_record_publish(record)
  File "/opt/miniconda3/envs/lpn_py310/lib/python3.10/site-packages/wandb/sdk/lib/sock_client.py", line 174, in send_record_publish
    self.send_server_request(server_req)
  File "/opt/miniconda3/envs/lpn_py310/lib/python3.10/site-packages/wandb/sdk/lib/sock_client.py", line 154, in send_server_request
    self._send_message(msg)
  File "/opt/miniconda3/envs/lpn_py310/lib/python3.10/site-packages/wandb/sdk/lib/sock_client.py", line 151, in _send_message
    self._sendall_with_error_handle(header + data)
  File "/opt/miniconda3/envs/lpn_py310/lib/python3.10/site-packages/wandb/sdk/lib/sock_client.py", line 130, in _sendall_with_error_handle
    sent = self._sock.send(data)
BrokenPipeError: [Errno 32] Broken pipe

During handling of the above exception, another exception occurred:

Traceback (most recent call last):
  File "/opt/miniconda3/envs/lpn_py310/lib/python3.10/site-packages/wandb/sdk/lib/redirect.py", line 662, in _on_write
    cb(written_data)
  File "/opt/miniconda3/envs/lpn_py310/lib/python3.10/site-packages/wandb/sdk/wandb_run.py", line 2487, in <lambda>
    lambda data: self._console_raw_callback("stdout", data),
  File "/opt/miniconda3/envs/lpn_py310/lib/python3.10/site-packages/wandb/sdk/wandb_run.py", line 406, in wrapper
    return func(self, *args, **kwargs)
  File "/opt/miniconda3/envs/lpn_py310/lib/python3.10/site-packages/wandb/sdk/wandb_run.py", line 464, in wrapper_fn
    return func(self, *args, **kwargs)
  File "/opt/miniconda3/envs/lpn_py310/lib/python3.10/site-packages/wandb/sdk/wandb_run.py", line 1632, in _console_raw_callback
    self._backend.interface.publish_output_raw(name, data)
  File "/opt/miniconda3/envs/lpn_py310/lib/python3.10/site-packages/wandb/sdk/interface/interface.py", line 763, in publish_output_raw
    self._publish_output_raw(o)
  File "/opt/miniconda3/envs/lpn_py310/lib/python3.10/site-packages/wandb/sdk/interface/interface_shared.py", line 38, in _publish_output_raw
    self._publish(rec)
  File "/opt/miniconda3/envs/lpn_py310/lib/python3.10/site-packages/wandb/sdk/interface/interface_sock.py", line 39, in _publish
    self._sock_client.send_record_publish(record)
  File "/opt/miniconda3/envs/lpn_py310/lib/python3.10/site-packages/wandb/sdk/lib/sock_client.py", line 174, in send_record_publish
    self.send_server_request(server_req)
  File "/opt/miniconda3/envs/lpn_py310/lib/python3.10/site-packages/wandb/sdk/lib/sock_client.py", line 154, in send_server_request
    self._send_message(msg)
  File "/opt/miniconda3/envs/lpn_py310/lib/python3.10/site-packages/wandb/sdk/lib/sock_client.py", line 151, in _send_message
    self._sendall_with_error_handle(header + data)
  File "/opt/miniconda3/envs/lpn_py310/lib/python3.10/site-packages/wandb/sdk/lib/sock_client.py", line 130, in _sendall_with_error_handle
    sent = self._sock.send(data)
BrokenPipeError: [Errno 32] Broken pipe
2025-05-14 19:58:01,323 ERROR   MainThread:2633 [redirect.py:_on_write():664] [no run ID] error in stdout callback
Traceback (most recent call last):
  File "/opt/miniconda3/envs/lpn_py310/lib/python3.10/site-packages/IPython/core/events.py", line 82, in trigger
    func(*args, **kwargs)
  File "/opt/miniconda3/envs/lpn_py310/lib/python3.10/site-packages/wandb/sdk/wandb_init.py", line 603, in _pre_run_cell_hook
    self.backend.interface.publish_pause()
  File "/opt/miniconda3/envs/lpn_py310/lib/python3.10/site-packages/wandb/sdk/interface/interface.py", line 771, in publish_pause
    self._publish_pause(pause)
  File "/opt/miniconda3/envs/lpn_py310/lib/python3.10/site-packages/wandb/sdk/interface/interface_shared.py", line 289, in _publish_pause
    self._publish(rec)
  File "/opt/miniconda3/envs/lpn_py310/lib/python3.10/site-packages/wandb/sdk/interface/interface_sock.py", line 39, in _publish
    self._sock_client.send_record_publish(record)
  File "/opt/miniconda3/envs/lpn_py310/lib/python3.10/site-packages/wandb/sdk/lib/sock_client.py", line 174, in send_record_publish
    self.send_server_request(server_req)
  File "/opt/miniconda3/envs/lpn_py310/lib/python3.10/site-packages/wandb/sdk/lib/sock_client.py", line 154, in send_server_request
    self._send_message(msg)
  File "/opt/miniconda3/envs/lpn_py310/lib/python3.10/site-packages/wandb/sdk/lib/sock_client.py", line 151, in _send_message
    self._sendall_with_error_handle(header + data)
  File "/opt/miniconda3/envs/lpn_py310/lib/python3.10/site-packages/wandb/sdk/lib/sock_client.py", line 130, in _sendall_with_error_handle
    sent = self._sock.send(data)
BrokenPipeError: [Errno 32] Broken pipe

During handling of the above exception, another exception occurred:

Traceback (most recent call last):
  File "/opt/miniconda3/envs/lpn_py310/lib/python3.10/site-packages/wandb/sdk/lib/redirect.py", line 662, in _on_write
    cb(written_data)
  File "/opt/miniconda3/envs/lpn_py310/lib/python3.10/site-packages/wandb/sdk/wandb_run.py", line 2487, in <lambda>
    lambda data: self._console_raw_callback("stdout", data),
  File "/opt/miniconda3/envs/lpn_py310/lib/python3.10/site-packages/wandb/sdk/wandb_run.py", line 406, in wrapper
    return func(self, *args, **kwargs)
  File "/opt/miniconda3/envs/lpn_py310/lib/python3.10/site-packages/wandb/sdk/wandb_run.py", line 464, in wrapper_fn
    return func(self, *args, **kwargs)
  File "/opt/miniconda3/envs/lpn_py310/lib/python3.10/site-packages/wandb/sdk/wandb_run.py", line 1632, in _console_raw_callback
    self._backend.interface.publish_output_raw(name, data)
  File "/opt/miniconda3/envs/lpn_py310/lib/python3.10/site-packages/wandb/sdk/interface/interface.py", line 763, in publish_output_raw
    self._publish_output_raw(o)
  File "/opt/miniconda3/envs/lpn_py310/lib/python3.10/site-packages/wandb/sdk/interface/interface_shared.py", line 38, in _publish_output_raw
    self._publish(rec)
  File "/opt/miniconda3/envs/lpn_py310/lib/python3.10/site-packages/wandb/sdk/interface/interface_sock.py", line 39, in _publish
    self._sock_client.send_record_publish(record)
  File "/opt/miniconda3/envs/lpn_py310/lib/python3.10/site-packages/wandb/sdk/lib/sock_client.py", line 174, in send_record_publish
    self.send_server_request(server_req)
  File "/opt/miniconda3/envs/lpn_py310/lib/python3.10/site-packages/wandb/sdk/lib/sock_client.py", line 154, in send_server_request
    self._send_message(msg)
  File "/opt/miniconda3/envs/lpn_py310/lib/python3.10/site-packages/wandb/sdk/lib/sock_client.py", line 151, in _send_message
    self._sendall_with_error_handle(header + data)
  File "/opt/miniconda3/envs/lpn_py310/lib/python3.10/site-packages/wandb/sdk/lib/sock_client.py", line 130, in _sendall_with_error_handle
    sent = self._sock.send(data)
BrokenPipeError: [Errno 32] Broken pipe
2025-05-14 19:58:01,506 INFO    MainThread:2633 [wandb_init.py:_post_run_cell_hook():613] [no run ID] resuming backend
2025-05-14 19:58:01,508 ERROR   MainThread:2633 [redirect.py:_on_write():664] [no run ID] error in stdout callback
Traceback (most recent call last):
  File "/opt/miniconda3/envs/lpn_py310/lib/python3.10/site-packages/IPython/core/events.py", line 82, in trigger
    func(*args, **kwargs)
  File "/opt/miniconda3/envs/lpn_py310/lib/python3.10/site-packages/wandb/sdk/wandb_init.py", line 614, in _post_run_cell_hook
    self.backend.interface.publish_resume()
  File "/opt/miniconda3/envs/lpn_py310/lib/python3.10/site-packages/wandb/sdk/interface/interface.py", line 779, in publish_resume
    self._publish_resume(resume)
  File "/opt/miniconda3/envs/lpn_py310/lib/python3.10/site-packages/wandb/sdk/interface/interface_shared.py", line 293, in _publish_resume
    self._publish(rec)
  File "/opt/miniconda3/envs/lpn_py310/lib/python3.10/site-packages/wandb/sdk/interface/interface_sock.py", line 39, in _publish
    self._sock_client.send_record_publish(record)
  File "/opt/miniconda3/envs/lpn_py310/lib/python3.10/site-packages/wandb/sdk/lib/sock_client.py", line 174, in send_record_publish
    self.send_server_request(server_req)
  File "/opt/miniconda3/envs/lpn_py310/lib/python3.10/site-packages/wandb/sdk/lib/sock_client.py", line 154, in send_server_request
    self._send_message(msg)
  File "/opt/miniconda3/envs/lpn_py310/lib/python3.10/site-packages/wandb/sdk/lib/sock_client.py", line 151, in _send_message
    self._sendall_with_error_handle(header + data)
  File "/opt/miniconda3/envs/lpn_py310/lib/python3.10/site-packages/wandb/sdk/lib/sock_client.py", line 130, in _sendall_with_error_handle
    sent = self._sock.send(data)
BrokenPipeError: [Errno 32] Broken pipe

During handling of the above exception, another exception occurred:

Traceback (most recent call last):
  File "/opt/miniconda3/envs/lpn_py310/lib/python3.10/site-packages/wandb/sdk/lib/redirect.py", line 662, in _on_write
    cb(written_data)
  File "/opt/miniconda3/envs/lpn_py310/lib/python3.10/site-packages/wandb/sdk/wandb_run.py", line 2487, in <lambda>
    lambda data: self._console_raw_callback("stdout", data),
  File "/opt/miniconda3/envs/lpn_py310/lib/python3.10/site-packages/wandb/sdk/wandb_run.py", line 406, in wrapper
    return func(self, *args, **kwargs)
  File "/opt/miniconda3/envs/lpn_py310/lib/python3.10/site-packages/wandb/sdk/wandb_run.py", line 464, in wrapper_fn
    return func(self, *args, **kwargs)
  File "/opt/miniconda3/envs/lpn_py310/lib/python3.10/site-packages/wandb/sdk/wandb_run.py", line 1632, in _console_raw_callback
    self._backend.interface.publish_output_raw(name, data)
  File "/opt/miniconda3/envs/lpn_py310/lib/python3.10/site-packages/wandb/sdk/interface/interface.py", line 763, in publish_output_raw
    self._publish_output_raw(o)
  File "/opt/miniconda3/envs/lpn_py310/lib/python3.10/site-packages/wandb/sdk/interface/interface_shared.py", line 38, in _publish_output_raw
    self._publish(rec)
  File "/opt/miniconda3/envs/lpn_py310/lib/python3.10/site-packages/wandb/sdk/interface/interface_sock.py", line 39, in _publish
    self._sock_client.send_record_publish(record)
  File "/opt/miniconda3/envs/lpn_py310/lib/python3.10/site-packages/wandb/sdk/lib/sock_client.py", line 174, in send_record_publish
    self.send_server_request(server_req)
  File "/opt/miniconda3/envs/lpn_py310/lib/python3.10/site-packages/wandb/sdk/lib/sock_client.py", line 154, in send_server_request
    self._send_message(msg)
  File "/opt/miniconda3/envs/lpn_py310/lib/python3.10/site-packages/wandb/sdk/lib/sock_client.py", line 151, in _send_message
    self._sendall_with_error_handle(header + data)
  File "/opt/miniconda3/envs/lpn_py310/lib/python3.10/site-packages/wandb/sdk/lib/sock_client.py", line 130, in _sendall_with_error_handle
    sent = self._sock.send(data)
BrokenPipeError: [Errno 32] Broken pipe
2025-05-14 19:58:01,508 ERROR   MainThread:2633 [redirect.py:_on_write():664] [no run ID] error in stdout callback
Traceback (most recent call last):
  File "/opt/miniconda3/envs/lpn_py310/lib/python3.10/site-packages/IPython/core/events.py", line 82, in trigger
    func(*args, **kwargs)
  File "/opt/miniconda3/envs/lpn_py310/lib/python3.10/site-packages/wandb/sdk/wandb_init.py", line 614, in _post_run_cell_hook
    self.backend.interface.publish_resume()
  File "/opt/miniconda3/envs/lpn_py310/lib/python3.10/site-packages/wandb/sdk/interface/interface.py", line 779, in publish_resume
    self._publish_resume(resume)
  File "/opt/miniconda3/envs/lpn_py310/lib/python3.10/site-packages/wandb/sdk/interface/interface_shared.py", line 293, in _publish_resume
    self._publish(rec)
  File "/opt/miniconda3/envs/lpn_py310/lib/python3.10/site-packages/wandb/sdk/interface/interface_sock.py", line 39, in _publish
    self._sock_client.send_record_publish(record)
  File "/opt/miniconda3/envs/lpn_py310/lib/python3.10/site-packages/wandb/sdk/lib/sock_client.py", line 174, in send_record_publish
    self.send_server_request(server_req)
  File "/opt/miniconda3/envs/lpn_py310/lib/python3.10/site-packages/wandb/sdk/lib/sock_client.py", line 154, in send_server_request
    self._send_message(msg)
  File "/opt/miniconda3/envs/lpn_py310/lib/python3.10/site-packages/wandb/sdk/lib/sock_client.py", line 151, in _send_message
    self._sendall_with_error_handle(header + data)
  File "/opt/miniconda3/envs/lpn_py310/lib/python3.10/site-packages/wandb/sdk/lib/sock_client.py", line 130, in _sendall_with_error_handle
    sent = self._sock.send(data)
BrokenPipeError: [Errno 32] Broken pipe

During handling of the above exception, another exception occurred:

Traceback (most recent call last):
  File "/opt/miniconda3/envs/lpn_py310/lib/python3.10/site-packages/wandb/sdk/lib/redirect.py", line 662, in _on_write
    cb(written_data)
  File "/opt/miniconda3/envs/lpn_py310/lib/python3.10/site-packages/wandb/sdk/wandb_run.py", line 2487, in <lambda>
    lambda data: self._console_raw_callback("stdout", data),
  File "/opt/miniconda3/envs/lpn_py310/lib/python3.10/site-packages/wandb/sdk/wandb_run.py", line 406, in wrapper
    return func(self, *args, **kwargs)
  File "/opt/miniconda3/envs/lpn_py310/lib/python3.10/site-packages/wandb/sdk/wandb_run.py", line 464, in wrapper_fn
    return func(self, *args, **kwargs)
  File "/opt/miniconda3/envs/lpn_py310/lib/python3.10/site-packages/wandb/sdk/wandb_run.py", line 1632, in _console_raw_callback
    self._backend.interface.publish_output_raw(name, data)
  File "/opt/miniconda3/envs/lpn_py310/lib/python3.10/site-packages/wandb/sdk/interface/interface.py", line 763, in publish_output_raw
    self._publish_output_raw(o)
  File "/opt/miniconda3/envs/lpn_py310/lib/python3.10/site-packages/wandb/sdk/interface/interface_shared.py", line 38, in _publish_output_raw
    self._publish(rec)
  File "/opt/miniconda3/envs/lpn_py310/lib/python3.10/site-packages/wandb/sdk/interface/interface_sock.py", line 39, in _publish
    self._sock_client.send_record_publish(record)
  File "/opt/miniconda3/envs/lpn_py310/lib/python3.10/site-packages/wandb/sdk/lib/sock_client.py", line 174, in send_record_publish
    self.send_server_request(server_req)
  File "/opt/miniconda3/envs/lpn_py310/lib/python3.10/site-packages/wandb/sdk/lib/sock_client.py", line 154, in send_server_request
    self._send_message(msg)
  File "/opt/miniconda3/envs/lpn_py310/lib/python3.10/site-packages/wandb/sdk/lib/sock_client.py", line 151, in _send_message
    self._sendall_with_error_handle(header + data)
  File "/opt/miniconda3/envs/lpn_py310/lib/python3.10/site-packages/wandb/sdk/lib/sock_client.py", line 130, in _sendall_with_error_handle
    sent = self._sock.send(data)
BrokenPipeError: [Errno 32] Broken pipe
2025-05-14 19:58:01,567 INFO    MainThread:2633 [jupyter.py:save_ipynb():401] [no run ID] not saving jupyter notebook
2025-05-14 19:58:01,567 INFO    MainThread:2633 [wandb_init.py:_pre_run_cell_hook():602] [no run ID] pausing backend
2025-05-14 19:58:01,568 ERROR   MainThread:2633 [redirect.py:_on_write():664] [no run ID] error in stdout callback
Traceback (most recent call last):
  File "/opt/miniconda3/envs/lpn_py310/lib/python3.10/site-packages/IPython/core/events.py", line 82, in trigger
    func(*args, **kwargs)
  File "/opt/miniconda3/envs/lpn_py310/lib/python3.10/site-packages/wandb/sdk/wandb_init.py", line 603, in _pre_run_cell_hook
    self.backend.interface.publish_pause()
  File "/opt/miniconda3/envs/lpn_py310/lib/python3.10/site-packages/wandb/sdk/interface/interface.py", line 771, in publish_pause
    self._publish_pause(pause)
  File "/opt/miniconda3/envs/lpn_py310/lib/python3.10/site-packages/wandb/sdk/interface/interface_shared.py", line 289, in _publish_pause
    self._publish(rec)
  File "/opt/miniconda3/envs/lpn_py310/lib/python3.10/site-packages/wandb/sdk/interface/interface_sock.py", line 39, in _publish
    self._sock_client.send_record_publish(record)
  File "/opt/miniconda3/envs/lpn_py310/lib/python3.10/site-packages/wandb/sdk/lib/sock_client.py", line 174, in send_record_publish
    self.send_server_request(server_req)
  File "/opt/miniconda3/envs/lpn_py310/lib/python3.10/site-packages/wandb/sdk/lib/sock_client.py", line 154, in send_server_request
    self._send_message(msg)
  File "/opt/miniconda3/envs/lpn_py310/lib/python3.10/site-packages/wandb/sdk/lib/sock_client.py", line 151, in _send_message
    self._sendall_with_error_handle(header + data)
  File "/opt/miniconda3/envs/lpn_py310/lib/python3.10/site-packages/wandb/sdk/lib/sock_client.py", line 130, in _sendall_with_error_handle
    sent = self._sock.send(data)
BrokenPipeError: [Errno 32] Broken pipe

During handling of the above exception, another exception occurred:

Traceback (most recent call last):
  File "/opt/miniconda3/envs/lpn_py310/lib/python3.10/site-packages/wandb/sdk/lib/redirect.py", line 662, in _on_write
    cb(written_data)
  File "/opt/miniconda3/envs/lpn_py310/lib/python3.10/site-packages/wandb/sdk/wandb_run.py", line 2487, in <lambda>
    lambda data: self._console_raw_callback("stdout", data),
  File "/opt/miniconda3/envs/lpn_py310/lib/python3.10/site-packages/wandb/sdk/wandb_run.py", line 406, in wrapper
    return func(self, *args, **kwargs)
  File "/opt/miniconda3/envs/lpn_py310/lib/python3.10/site-packages/wandb/sdk/wandb_run.py", line 464, in wrapper_fn
    return func(self, *args, **kwargs)
  File "/opt/miniconda3/envs/lpn_py310/lib/python3.10/site-packages/wandb/sdk/wandb_run.py", line 1632, in _console_raw_callback
    self._backend.interface.publish_output_raw(name, data)
  File "/opt/miniconda3/envs/lpn_py310/lib/python3.10/site-packages/wandb/sdk/interface/interface.py", line 763, in publish_output_raw
    self._publish_output_raw(o)
  File "/opt/miniconda3/envs/lpn_py310/lib/python3.10/site-packages/wandb/sdk/interface/interface_shared.py", line 38, in _publish_output_raw
    self._publish(rec)
  File "/opt/miniconda3/envs/lpn_py310/lib/python3.10/site-packages/wandb/sdk/interface/interface_sock.py", line 39, in _publish
    self._sock_client.send_record_publish(record)
  File "/opt/miniconda3/envs/lpn_py310/lib/python3.10/site-packages/wandb/sdk/lib/sock_client.py", line 174, in send_record_publish
    self.send_server_request(server_req)
  File "/opt/miniconda3/envs/lpn_py310/lib/python3.10/site-packages/wandb/sdk/lib/sock_client.py", line 154, in send_server_request
    self._send_message(msg)
  File "/opt/miniconda3/envs/lpn_py310/lib/python3.10/site-packages/wandb/sdk/lib/sock_client.py", line 151, in _send_message
    self._sendall_with_error_handle(header + data)
  File "/opt/miniconda3/envs/lpn_py310/lib/python3.10/site-packages/wandb/sdk/lib/sock_client.py", line 130, in _sendall_with_error_handle
    sent = self._sock.send(data)
BrokenPipeError: [Errno 32] Broken pipe
2025-05-14 19:58:01,569 ERROR   MainThread:2633 [redirect.py:_on_write():664] [no run ID] error in stdout callback
Traceback (most recent call last):
  File "/opt/miniconda3/envs/lpn_py310/lib/python3.10/site-packages/IPython/core/events.py", line 82, in trigger
    func(*args, **kwargs)
  File "/opt/miniconda3/envs/lpn_py310/lib/python3.10/site-packages/wandb/sdk/wandb_init.py", line 603, in _pre_run_cell_hook
    self.backend.interface.publish_pause()
  File "/opt/miniconda3/envs/lpn_py310/lib/python3.10/site-packages/wandb/sdk/interface/interface.py", line 771, in publish_pause
    self._publish_pause(pause)
  File "/opt/miniconda3/envs/lpn_py310/lib/python3.10/site-packages/wandb/sdk/interface/interface_shared.py", line 289, in _publish_pause
    self._publish(rec)
  File "/opt/miniconda3/envs/lpn_py310/lib/python3.10/site-packages/wandb/sdk/interface/interface_sock.py", line 39, in _publish
    self._sock_client.send_record_publish(record)
  File "/opt/miniconda3/envs/lpn_py310/lib/python3.10/site-packages/wandb/sdk/lib/sock_client.py", line 174, in send_record_publish
    self.send_server_request(server_req)
  File "/opt/miniconda3/envs/lpn_py310/lib/python3.10/site-packages/wandb/sdk/lib/sock_client.py", line 154, in send_server_request
    self._send_message(msg)
  File "/opt/miniconda3/envs/lpn_py310/lib/python3.10/site-packages/wandb/sdk/lib/sock_client.py", line 151, in _send_message
    self._sendall_with_error_handle(header + data)
  File "/opt/miniconda3/envs/lpn_py310/lib/python3.10/site-packages/wandb/sdk/lib/sock_client.py", line 130, in _sendall_with_error_handle
    sent = self._sock.send(data)
BrokenPipeError: [Errno 32] Broken pipe

During handling of the above exception, another exception occurred:

Traceback (most recent call last):
  File "/opt/miniconda3/envs/lpn_py310/lib/python3.10/site-packages/wandb/sdk/lib/redirect.py", line 662, in _on_write
    cb(written_data)
  File "/opt/miniconda3/envs/lpn_py310/lib/python3.10/site-packages/wandb/sdk/wandb_run.py", line 2487, in <lambda>
    lambda data: self._console_raw_callback("stdout", data),
  File "/opt/miniconda3/envs/lpn_py310/lib/python3.10/site-packages/wandb/sdk/wandb_run.py", line 406, in wrapper
    return func(self, *args, **kwargs)
  File "/opt/miniconda3/envs/lpn_py310/lib/python3.10/site-packages/wandb/sdk/wandb_run.py", line 464, in wrapper_fn
    return func(self, *args, **kwargs)
  File "/opt/miniconda3/envs/lpn_py310/lib/python3.10/site-packages/wandb/sdk/wandb_run.py", line 1632, in _console_raw_callback
    self._backend.interface.publish_output_raw(name, data)
  File "/opt/miniconda3/envs/lpn_py310/lib/python3.10/site-packages/wandb/sdk/interface/interface.py", line 763, in publish_output_raw
    self._publish_output_raw(o)
  File "/opt/miniconda3/envs/lpn_py310/lib/python3.10/site-packages/wandb/sdk/interface/interface_shared.py", line 38, in _publish_output_raw
    self._publish(rec)
  File "/opt/miniconda3/envs/lpn_py310/lib/python3.10/site-packages/wandb/sdk/interface/interface_sock.py", line 39, in _publish
    self._sock_client.send_record_publish(record)
  File "/opt/miniconda3/envs/lpn_py310/lib/python3.10/site-packages/wandb/sdk/lib/sock_client.py", line 174, in send_record_publish
    self.send_server_request(server_req)
  File "/opt/miniconda3/envs/lpn_py310/lib/python3.10/site-packages/wandb/sdk/lib/sock_client.py", line 154, in send_server_request
    self._send_message(msg)
  File "/opt/miniconda3/envs/lpn_py310/lib/python3.10/site-packages/wandb/sdk/lib/sock_client.py", line 151, in _send_message
    self._sendall_with_error_handle(header + data)
  File "/opt/miniconda3/envs/lpn_py310/lib/python3.10/site-packages/wandb/sdk/lib/sock_client.py", line 130, in _sendall_with_error_handle
    sent = self._sock.send(data)
BrokenPipeError: [Errno 32] Broken pipe
2025-05-14 19:58:01,604 INFO    MainThread:2633 [wandb_init.py:_post_run_cell_hook():613] [no run ID] resuming backend
2025-05-14 19:58:01,604 ERROR   MainThread:2633 [redirect.py:_on_write():664] [no run ID] error in stdout callback
Traceback (most recent call last):
  File "/opt/miniconda3/envs/lpn_py310/lib/python3.10/site-packages/IPython/core/events.py", line 82, in trigger
    func(*args, **kwargs)
  File "/opt/miniconda3/envs/lpn_py310/lib/python3.10/site-packages/wandb/sdk/wandb_init.py", line 614, in _post_run_cell_hook
    self.backend.interface.publish_resume()
  File "/opt/miniconda3/envs/lpn_py310/lib/python3.10/site-packages/wandb/sdk/interface/interface.py", line 779, in publish_resume
    self._publish_resume(resume)
  File "/opt/miniconda3/envs/lpn_py310/lib/python3.10/site-packages/wandb/sdk/interface/interface_shared.py", line 293, in _publish_resume
    self._publish(rec)
  File "/opt/miniconda3/envs/lpn_py310/lib/python3.10/site-packages/wandb/sdk/interface/interface_sock.py", line 39, in _publish
    self._sock_client.send_record_publish(record)
  File "/opt/miniconda3/envs/lpn_py310/lib/python3.10/site-packages/wandb/sdk/lib/sock_client.py", line 174, in send_record_publish
    self.send_server_request(server_req)
  File "/opt/miniconda3/envs/lpn_py310/lib/python3.10/site-packages/wandb/sdk/lib/sock_client.py", line 154, in send_server_request
    self._send_message(msg)
  File "/opt/miniconda3/envs/lpn_py310/lib/python3.10/site-packages/wandb/sdk/lib/sock_client.py", line 151, in _send_message
    self._sendall_with_error_handle(header + data)
  File "/opt/miniconda3/envs/lpn_py310/lib/python3.10/site-packages/wandb/sdk/lib/sock_client.py", line 130, in _sendall_with_error_handle
    sent = self._sock.send(data)
BrokenPipeError: [Errno 32] Broken pipe

During handling of the above exception, another exception occurred:

Traceback (most recent call last):
  File "/opt/miniconda3/envs/lpn_py310/lib/python3.10/site-packages/wandb/sdk/lib/redirect.py", line 662, in _on_write
    cb(written_data)
  File "/opt/miniconda3/envs/lpn_py310/lib/python3.10/site-packages/wandb/sdk/wandb_run.py", line 2487, in <lambda>
    lambda data: self._console_raw_callback("stdout", data),
  File "/opt/miniconda3/envs/lpn_py310/lib/python3.10/site-packages/wandb/sdk/wandb_run.py", line 406, in wrapper
    return func(self, *args, **kwargs)
  File "/opt/miniconda3/envs/lpn_py310/lib/python3.10/site-packages/wandb/sdk/wandb_run.py", line 464, in wrapper_fn
    return func(self, *args, **kwargs)
  File "/opt/miniconda3/envs/lpn_py310/lib/python3.10/site-packages/wandb/sdk/wandb_run.py", line 1632, in _console_raw_callback
    self._backend.interface.publish_output_raw(name, data)
  File "/opt/miniconda3/envs/lpn_py310/lib/python3.10/site-packages/wandb/sdk/interface/interface.py", line 763, in publish_output_raw
    self._publish_output_raw(o)
  File "/opt/miniconda3/envs/lpn_py310/lib/python3.10/site-packages/wandb/sdk/interface/interface_shared.py", line 38, in _publish_output_raw
    self._publish(rec)
  File "/opt/miniconda3/envs/lpn_py310/lib/python3.10/site-packages/wandb/sdk/interface/interface_sock.py", line 39, in _publish
    self._sock_client.send_record_publish(record)
  File "/opt/miniconda3/envs/lpn_py310/lib/python3.10/site-packages/wandb/sdk/lib/sock_client.py", line 174, in send_record_publish
    self.send_server_request(server_req)
  File "/opt/miniconda3/envs/lpn_py310/lib/python3.10/site-packages/wandb/sdk/lib/sock_client.py", line 154, in send_server_request
    self._send_message(msg)
  File "/opt/miniconda3/envs/lpn_py310/lib/python3.10/site-packages/wandb/sdk/lib/sock_client.py", line 151, in _send_message
    self._sendall_with_error_handle(header + data)
  File "/opt/miniconda3/envs/lpn_py310/lib/python3.10/site-packages/wandb/sdk/lib/sock_client.py", line 130, in _sendall_with_error_handle
    sent = self._sock.send(data)
BrokenPipeError: [Errno 32] Broken pipe
2025-05-14 19:58:01,605 ERROR   MainThread:2633 [redirect.py:_on_write():664] [no run ID] error in stdout callback
Traceback (most recent call last):
  File "/opt/miniconda3/envs/lpn_py310/lib/python3.10/site-packages/IPython/core/events.py", line 82, in trigger
    func(*args, **kwargs)
  File "/opt/miniconda3/envs/lpn_py310/lib/python3.10/site-packages/wandb/sdk/wandb_init.py", line 614, in _post_run_cell_hook
    self.backend.interface.publish_resume()
  File "/opt/miniconda3/envs/lpn_py310/lib/python3.10/site-packages/wandb/sdk/interface/interface.py", line 779, in publish_resume
    self._publish_resume(resume)
  File "/opt/miniconda3/envs/lpn_py310/lib/python3.10/site-packages/wandb/sdk/interface/interface_shared.py", line 293, in _publish_resume
    self._publish(rec)
  File "/opt/miniconda3/envs/lpn_py310/lib/python3.10/site-packages/wandb/sdk/interface/interface_sock.py", line 39, in _publish
    self._sock_client.send_record_publish(record)
  File "/opt/miniconda3/envs/lpn_py310/lib/python3.10/site-packages/wandb/sdk/lib/sock_client.py", line 174, in send_record_publish
    self.send_server_request(server_req)
  File "/opt/miniconda3/envs/lpn_py310/lib/python3.10/site-packages/wandb/sdk/lib/sock_client.py", line 154, in send_server_request
    self._send_message(msg)
  File "/opt/miniconda3/envs/lpn_py310/lib/python3.10/site-packages/wandb/sdk/lib/sock_client.py", line 151, in _send_message
    self._sendall_with_error_handle(header + data)
  File "/opt/miniconda3/envs/lpn_py310/lib/python3.10/site-packages/wandb/sdk/lib/sock_client.py", line 130, in _sendall_with_error_handle
    sent = self._sock.send(data)
BrokenPipeError: [Errno 32] Broken pipe

During handling of the above exception, another exception occurred:

Traceback (most recent call last):
  File "/opt/miniconda3/envs/lpn_py310/lib/python3.10/site-packages/wandb/sdk/lib/redirect.py", line 662, in _on_write
    cb(written_data)
  File "/opt/miniconda3/envs/lpn_py310/lib/python3.10/site-packages/wandb/sdk/wandb_run.py", line 2487, in <lambda>
    lambda data: self._console_raw_callback("stdout", data),
  File "/opt/miniconda3/envs/lpn_py310/lib/python3.10/site-packages/wandb/sdk/wandb_run.py", line 406, in wrapper
    return func(self, *args, **kwargs)
  File "/opt/miniconda3/envs/lpn_py310/lib/python3.10/site-packages/wandb/sdk/wandb_run.py", line 464, in wrapper_fn
    return func(self, *args, **kwargs)
  File "/opt/miniconda3/envs/lpn_py310/lib/python3.10/site-packages/wandb/sdk/wandb_run.py", line 1632, in _console_raw_callback
    self._backend.interface.publish_output_raw(name, data)
  File "/opt/miniconda3/envs/lpn_py310/lib/python3.10/site-packages/wandb/sdk/interface/interface.py", line 763, in publish_output_raw
    self._publish_output_raw(o)
  File "/opt/miniconda3/envs/lpn_py310/lib/python3.10/site-packages/wandb/sdk/interface/interface_shared.py", line 38, in _publish_output_raw
    self._publish(rec)
  File "/opt/miniconda3/envs/lpn_py310/lib/python3.10/site-packages/wandb/sdk/interface/interface_sock.py", line 39, in _publish
    self._sock_client.send_record_publish(record)
  File "/opt/miniconda3/envs/lpn_py310/lib/python3.10/site-packages/wandb/sdk/lib/sock_client.py", line 174, in send_record_publish
    self.send_server_request(server_req)
  File "/opt/miniconda3/envs/lpn_py310/lib/python3.10/site-packages/wandb/sdk/lib/sock_client.py", line 154, in send_server_request
    self._send_message(msg)
  File "/opt/miniconda3/envs/lpn_py310/lib/python3.10/site-packages/wandb/sdk/lib/sock_client.py", line 151, in _send_message
    self._sendall_with_error_handle(header + data)
  File "/opt/miniconda3/envs/lpn_py310/lib/python3.10/site-packages/wandb/sdk/lib/sock_client.py", line 130, in _sendall_with_error_handle
    sent = self._sock.send(data)
BrokenPipeError: [Errno 32] Broken pipe
2025-05-14 19:58:01,646 INFO    MainThread:2633 [jupyter.py:save_ipynb():401] [no run ID] not saving jupyter notebook
2025-05-14 19:58:01,646 INFO    MainThread:2633 [wandb_init.py:_pre_run_cell_hook():602] [no run ID] pausing backend
2025-05-14 19:58:01,647 ERROR   MainThread:2633 [redirect.py:_on_write():664] [no run ID] error in stdout callback
Traceback (most recent call last):
  File "/opt/miniconda3/envs/lpn_py310/lib/python3.10/site-packages/IPython/core/events.py", line 82, in trigger
    func(*args, **kwargs)
  File "/opt/miniconda3/envs/lpn_py310/lib/python3.10/site-packages/wandb/sdk/wandb_init.py", line 603, in _pre_run_cell_hook
    self.backend.interface.publish_pause()
  File "/opt/miniconda3/envs/lpn_py310/lib/python3.10/site-packages/wandb/sdk/interface/interface.py", line 771, in publish_pause
    self._publish_pause(pause)
  File "/opt/miniconda3/envs/lpn_py310/lib/python3.10/site-packages/wandb/sdk/interface/interface_shared.py", line 289, in _publish_pause
    self._publish(rec)
  File "/opt/miniconda3/envs/lpn_py310/lib/python3.10/site-packages/wandb/sdk/interface/interface_sock.py", line 39, in _publish
    self._sock_client.send_record_publish(record)
  File "/opt/miniconda3/envs/lpn_py310/lib/python3.10/site-packages/wandb/sdk/lib/sock_client.py", line 174, in send_record_publish
    self.send_server_request(server_req)
  File "/opt/miniconda3/envs/lpn_py310/lib/python3.10/site-packages/wandb/sdk/lib/sock_client.py", line 154, in send_server_request
    self._send_message(msg)
  File "/opt/miniconda3/envs/lpn_py310/lib/python3.10/site-packages/wandb/sdk/lib/sock_client.py", line 151, in _send_message
    self._sendall_with_error_handle(header + data)
  File "/opt/miniconda3/envs/lpn_py310/lib/python3.10/site-packages/wandb/sdk/lib/sock_client.py", line 130, in _sendall_with_error_handle
    sent = self._sock.send(data)
BrokenPipeError: [Errno 32] Broken pipe

During handling of the above exception, another exception occurred:

Traceback (most recent call last):
  File "/opt/miniconda3/envs/lpn_py310/lib/python3.10/site-packages/wandb/sdk/lib/redirect.py", line 662, in _on_write
    cb(written_data)
  File "/opt/miniconda3/envs/lpn_py310/lib/python3.10/site-packages/wandb/sdk/wandb_run.py", line 2487, in <lambda>
    lambda data: self._console_raw_callback("stdout", data),
  File "/opt/miniconda3/envs/lpn_py310/lib/python3.10/site-packages/wandb/sdk/wandb_run.py", line 406, in wrapper
    return func(self, *args, **kwargs)
  File "/opt/miniconda3/envs/lpn_py310/lib/python3.10/site-packages/wandb/sdk/wandb_run.py", line 464, in wrapper_fn
    return func(self, *args, **kwargs)
  File "/opt/miniconda3/envs/lpn_py310/lib/python3.10/site-packages/wandb/sdk/wandb_run.py", line 1632, in _console_raw_callback
    self._backend.interface.publish_output_raw(name, data)
  File "/opt/miniconda3/envs/lpn_py310/lib/python3.10/site-packages/wandb/sdk/interface/interface.py", line 763, in publish_output_raw
    self._publish_output_raw(o)
  File "/opt/miniconda3/envs/lpn_py310/lib/python3.10/site-packages/wandb/sdk/interface/interface_shared.py", line 38, in _publish_output_raw
    self._publish(rec)
  File "/opt/miniconda3/envs/lpn_py310/lib/python3.10/site-packages/wandb/sdk/interface/interface_sock.py", line 39, in _publish
    self._sock_client.send_record_publish(record)
  File "/opt/miniconda3/envs/lpn_py310/lib/python3.10/site-packages/wandb/sdk/lib/sock_client.py", line 174, in send_record_publish
    self.send_server_request(server_req)
  File "/opt/miniconda3/envs/lpn_py310/lib/python3.10/site-packages/wandb/sdk/lib/sock_client.py", line 154, in send_server_request
    self._send_message(msg)
  File "/opt/miniconda3/envs/lpn_py310/lib/python3.10/site-packages/wandb/sdk/lib/sock_client.py", line 151, in _send_message
    self._sendall_with_error_handle(header + data)
  File "/opt/miniconda3/envs/lpn_py310/lib/python3.10/site-packages/wandb/sdk/lib/sock_client.py", line 130, in _sendall_with_error_handle
    sent = self._sock.send(data)
BrokenPipeError: [Errno 32] Broken pipe
2025-05-14 19:58:01,647 ERROR   MainThread:2633 [redirect.py:_on_write():664] [no run ID] error in stdout callback
Traceback (most recent call last):
  File "/opt/miniconda3/envs/lpn_py310/lib/python3.10/site-packages/IPython/core/events.py", line 82, in trigger
    func(*args, **kwargs)
  File "/opt/miniconda3/envs/lpn_py310/lib/python3.10/site-packages/wandb/sdk/wandb_init.py", line 603, in _pre_run_cell_hook
    self.backend.interface.publish_pause()
  File "/opt/miniconda3/envs/lpn_py310/lib/python3.10/site-packages/wandb/sdk/interface/interface.py", line 771, in publish_pause
    self._publish_pause(pause)
  File "/opt/miniconda3/envs/lpn_py310/lib/python3.10/site-packages/wandb/sdk/interface/interface_shared.py", line 289, in _publish_pause
    self._publish(rec)
  File "/opt/miniconda3/envs/lpn_py310/lib/python3.10/site-packages/wandb/sdk/interface/interface_sock.py", line 39, in _publish
    self._sock_client.send_record_publish(record)
  File "/opt/miniconda3/envs/lpn_py310/lib/python3.10/site-packages/wandb/sdk/lib/sock_client.py", line 174, in send_record_publish
    self.send_server_request(server_req)
  File "/opt/miniconda3/envs/lpn_py310/lib/python3.10/site-packages/wandb/sdk/lib/sock_client.py", line 154, in send_server_request
    self._send_message(msg)
  File "/opt/miniconda3/envs/lpn_py310/lib/python3.10/site-packages/wandb/sdk/lib/sock_client.py", line 151, in _send_message
    self._sendall_with_error_handle(header + data)
  File "/opt/miniconda3/envs/lpn_py310/lib/python3.10/site-packages/wandb/sdk/lib/sock_client.py", line 130, in _sendall_with_error_handle
    sent = self._sock.send(data)
BrokenPipeError: [Errno 32] Broken pipe

During handling of the above exception, another exception occurred:

Traceback (most recent call last):
  File "/opt/miniconda3/envs/lpn_py310/lib/python3.10/site-packages/wandb/sdk/lib/redirect.py", line 662, in _on_write
    cb(written_data)
  File "/opt/miniconda3/envs/lpn_py310/lib/python3.10/site-packages/wandb/sdk/wandb_run.py", line 2487, in <lambda>
    lambda data: self._console_raw_callback("stdout", data),
  File "/opt/miniconda3/envs/lpn_py310/lib/python3.10/site-packages/wandb/sdk/wandb_run.py", line 406, in wrapper
    return func(self, *args, **kwargs)
  File "/opt/miniconda3/envs/lpn_py310/lib/python3.10/site-packages/wandb/sdk/wandb_run.py", line 464, in wrapper_fn
    return func(self, *args, **kwargs)
  File "/opt/miniconda3/envs/lpn_py310/lib/python3.10/site-packages/wandb/sdk/wandb_run.py", line 1632, in _console_raw_callback
    self._backend.interface.publish_output_raw(name, data)
  File "/opt/miniconda3/envs/lpn_py310/lib/python3.10/site-packages/wandb/sdk/interface/interface.py", line 763, in publish_output_raw
    self._publish_output_raw(o)
  File "/opt/miniconda3/envs/lpn_py310/lib/python3.10/site-packages/wandb/sdk/interface/interface_shared.py", line 38, in _publish_output_raw
    self._publish(rec)
  File "/opt/miniconda3/envs/lpn_py310/lib/python3.10/site-packages/wandb/sdk/interface/interface_sock.py", line 39, in _publish
    self._sock_client.send_record_publish(record)
  File "/opt/miniconda3/envs/lpn_py310/lib/python3.10/site-packages/wandb/sdk/lib/sock_client.py", line 174, in send_record_publish
    self.send_server_request(server_req)
  File "/opt/miniconda3/envs/lpn_py310/lib/python3.10/site-packages/wandb/sdk/lib/sock_client.py", line 154, in send_server_request
    self._send_message(msg)
  File "/opt/miniconda3/envs/lpn_py310/lib/python3.10/site-packages/wandb/sdk/lib/sock_client.py", line 151, in _send_message
    self._sendall_with_error_handle(header + data)
  File "/opt/miniconda3/envs/lpn_py310/lib/python3.10/site-packages/wandb/sdk/lib/sock_client.py", line 130, in _sendall_with_error_handle
    sent = self._sock.send(data)
BrokenPipeError: [Errno 32] Broken pipe
2025-05-14 19:58:01,692 INFO    MainThread:2633 [wandb_init.py:_post_run_cell_hook():613] [no run ID] resuming backend
2025-05-14 19:58:01,693 ERROR   MainThread:2633 [redirect.py:_on_write():664] [no run ID] error in stdout callback
Traceback (most recent call last):
  File "/opt/miniconda3/envs/lpn_py310/lib/python3.10/site-packages/IPython/core/events.py", line 82, in trigger
    func(*args, **kwargs)
  File "/opt/miniconda3/envs/lpn_py310/lib/python3.10/site-packages/wandb/sdk/wandb_init.py", line 614, in _post_run_cell_hook
    self.backend.interface.publish_resume()
  File "/opt/miniconda3/envs/lpn_py310/lib/python3.10/site-packages/wandb/sdk/interface/interface.py", line 779, in publish_resume
    self._publish_resume(resume)
  File "/opt/miniconda3/envs/lpn_py310/lib/python3.10/site-packages/wandb/sdk/interface/interface_shared.py", line 293, in _publish_resume
    self._publish(rec)
  File "/opt/miniconda3/envs/lpn_py310/lib/python3.10/site-packages/wandb/sdk/interface/interface_sock.py", line 39, in _publish
    self._sock_client.send_record_publish(record)
  File "/opt/miniconda3/envs/lpn_py310/lib/python3.10/site-packages/wandb/sdk/lib/sock_client.py", line 174, in send_record_publish
    self.send_server_request(server_req)
  File "/opt/miniconda3/envs/lpn_py310/lib/python3.10/site-packages/wandb/sdk/lib/sock_client.py", line 154, in send_server_request
    self._send_message(msg)
  File "/opt/miniconda3/envs/lpn_py310/lib/python3.10/site-packages/wandb/sdk/lib/sock_client.py", line 151, in _send_message
    self._sendall_with_error_handle(header + data)
  File "/opt/miniconda3/envs/lpn_py310/lib/python3.10/site-packages/wandb/sdk/lib/sock_client.py", line 130, in _sendall_with_error_handle
    sent = self._sock.send(data)
BrokenPipeError: [Errno 32] Broken pipe

During handling of the above exception, another exception occurred:

Traceback (most recent call last):
  File "/opt/miniconda3/envs/lpn_py310/lib/python3.10/site-packages/wandb/sdk/lib/redirect.py", line 662, in _on_write
    cb(written_data)
  File "/opt/miniconda3/envs/lpn_py310/lib/python3.10/site-packages/wandb/sdk/wandb_run.py", line 2487, in <lambda>
    lambda data: self._console_raw_callback("stdout", data),
  File "/opt/miniconda3/envs/lpn_py310/lib/python3.10/site-packages/wandb/sdk/wandb_run.py", line 406, in wrapper
    return func(self, *args, **kwargs)
  File "/opt/miniconda3/envs/lpn_py310/lib/python3.10/site-packages/wandb/sdk/wandb_run.py", line 464, in wrapper_fn
    return func(self, *args, **kwargs)
  File "/opt/miniconda3/envs/lpn_py310/lib/python3.10/site-packages/wandb/sdk/wandb_run.py", line 1632, in _console_raw_callback
    self._backend.interface.publish_output_raw(name, data)
  File "/opt/miniconda3/envs/lpn_py310/lib/python3.10/site-packages/wandb/sdk/interface/interface.py", line 763, in publish_output_raw
    self._publish_output_raw(o)
  File "/opt/miniconda3/envs/lpn_py310/lib/python3.10/site-packages/wandb/sdk/interface/interface_shared.py", line 38, in _publish_output_raw
    self._publish(rec)
  File "/opt/miniconda3/envs/lpn_py310/lib/python3.10/site-packages/wandb/sdk/interface/interface_sock.py", line 39, in _publish
    self._sock_client.send_record_publish(record)
  File "/opt/miniconda3/envs/lpn_py310/lib/python3.10/site-packages/wandb/sdk/lib/sock_client.py", line 174, in send_record_publish
    self.send_server_request(server_req)
  File "/opt/miniconda3/envs/lpn_py310/lib/python3.10/site-packages/wandb/sdk/lib/sock_client.py", line 154, in send_server_request
    self._send_message(msg)
  File "/opt/miniconda3/envs/lpn_py310/lib/python3.10/site-packages/wandb/sdk/lib/sock_client.py", line 151, in _send_message
    self._sendall_with_error_handle(header + data)
  File "/opt/miniconda3/envs/lpn_py310/lib/python3.10/site-packages/wandb/sdk/lib/sock_client.py", line 130, in _sendall_with_error_handle
    sent = self._sock.send(data)
BrokenPipeError: [Errno 32] Broken pipe
2025-05-14 19:58:01,693 ERROR   MainThread:2633 [redirect.py:_on_write():664] [no run ID] error in stdout callback
Traceback (most recent call last):
  File "/opt/miniconda3/envs/lpn_py310/lib/python3.10/site-packages/IPython/core/events.py", line 82, in trigger
    func(*args, **kwargs)
  File "/opt/miniconda3/envs/lpn_py310/lib/python3.10/site-packages/wandb/sdk/wandb_init.py", line 614, in _post_run_cell_hook
    self.backend.interface.publish_resume()
  File "/opt/miniconda3/envs/lpn_py310/lib/python3.10/site-packages/wandb/sdk/interface/interface.py", line 779, in publish_resume
    self._publish_resume(resume)
  File "/opt/miniconda3/envs/lpn_py310/lib/python3.10/site-packages/wandb/sdk/interface/interface_shared.py", line 293, in _publish_resume
    self._publish(rec)
  File "/opt/miniconda3/envs/lpn_py310/lib/python3.10/site-packages/wandb/sdk/interface/interface_sock.py", line 39, in _publish
    self._sock_client.send_record_publish(record)
  File "/opt/miniconda3/envs/lpn_py310/lib/python3.10/site-packages/wandb/sdk/lib/sock_client.py", line 174, in send_record_publish
    self.send_server_request(server_req)
  File "/opt/miniconda3/envs/lpn_py310/lib/python3.10/site-packages/wandb/sdk/lib/sock_client.py", line 154, in send_server_request
    self._send_message(msg)
  File "/opt/miniconda3/envs/lpn_py310/lib/python3.10/site-packages/wandb/sdk/lib/sock_client.py", line 151, in _send_message
    self._sendall_with_error_handle(header + data)
  File "/opt/miniconda3/envs/lpn_py310/lib/python3.10/site-packages/wandb/sdk/lib/sock_client.py", line 130, in _sendall_with_error_handle
    sent = self._sock.send(data)
BrokenPipeError: [Errno 32] Broken pipe

During handling of the above exception, another exception occurred:

Traceback (most recent call last):
  File "/opt/miniconda3/envs/lpn_py310/lib/python3.10/site-packages/wandb/sdk/lib/redirect.py", line 662, in _on_write
    cb(written_data)
  File "/opt/miniconda3/envs/lpn_py310/lib/python3.10/site-packages/wandb/sdk/wandb_run.py", line 2487, in <lambda>
    lambda data: self._console_raw_callback("stdout", data),
  File "/opt/miniconda3/envs/lpn_py310/lib/python3.10/site-packages/wandb/sdk/wandb_run.py", line 406, in wrapper
    return func(self, *args, **kwargs)
  File "/opt/miniconda3/envs/lpn_py310/lib/python3.10/site-packages/wandb/sdk/wandb_run.py", line 464, in wrapper_fn
    return func(self, *args, **kwargs)
  File "/opt/miniconda3/envs/lpn_py310/lib/python3.10/site-packages/wandb/sdk/wandb_run.py", line 1632, in _console_raw_callback
    self._backend.interface.publish_output_raw(name, data)
  File "/opt/miniconda3/envs/lpn_py310/lib/python3.10/site-packages/wandb/sdk/interface/interface.py", line 763, in publish_output_raw
    self._publish_output_raw(o)
  File "/opt/miniconda3/envs/lpn_py310/lib/python3.10/site-packages/wandb/sdk/interface/interface_shared.py", line 38, in _publish_output_raw
    self._publish(rec)
  File "/opt/miniconda3/envs/lpn_py310/lib/python3.10/site-packages/wandb/sdk/interface/interface_sock.py", line 39, in _publish
    self._sock_client.send_record_publish(record)
  File "/opt/miniconda3/envs/lpn_py310/lib/python3.10/site-packages/wandb/sdk/lib/sock_client.py", line 174, in send_record_publish
    self.send_server_request(server_req)
  File "/opt/miniconda3/envs/lpn_py310/lib/python3.10/site-packages/wandb/sdk/lib/sock_client.py", line 154, in send_server_request
    self._send_message(msg)
  File "/opt/miniconda3/envs/lpn_py310/lib/python3.10/site-packages/wandb/sdk/lib/sock_client.py", line 151, in _send_message
    self._sendall_with_error_handle(header + data)
  File "/opt/miniconda3/envs/lpn_py310/lib/python3.10/site-packages/wandb/sdk/lib/sock_client.py", line 130, in _sendall_with_error_handle
    sent = self._sock.send(data)
BrokenPipeError: [Errno 32] Broken pipe
2025-05-14 19:58:01,732 INFO    MainThread:2633 [jupyter.py:save_ipynb():401] [no run ID] not saving jupyter notebook
2025-05-14 19:58:01,733 INFO    MainThread:2633 [wandb_init.py:_pre_run_cell_hook():602] [no run ID] pausing backend
2025-05-14 19:58:01,733 ERROR   MainThread:2633 [redirect.py:_on_write():664] [no run ID] error in stdout callback
Traceback (most recent call last):
  File "/opt/miniconda3/envs/lpn_py310/lib/python3.10/site-packages/IPython/core/events.py", line 82, in trigger
    func(*args, **kwargs)
  File "/opt/miniconda3/envs/lpn_py310/lib/python3.10/site-packages/wandb/sdk/wandb_init.py", line 603, in _pre_run_cell_hook
    self.backend.interface.publish_pause()
  File "/opt/miniconda3/envs/lpn_py310/lib/python3.10/site-packages/wandb/sdk/interface/interface.py", line 771, in publish_pause
    self._publish_pause(pause)
  File "/opt/miniconda3/envs/lpn_py310/lib/python3.10/site-packages/wandb/sdk/interface/interface_shared.py", line 289, in _publish_pause
    self._publish(rec)
  File "/opt/miniconda3/envs/lpn_py310/lib/python3.10/site-packages/wandb/sdk/interface/interface_sock.py", line 39, in _publish
    self._sock_client.send_record_publish(record)
  File "/opt/miniconda3/envs/lpn_py310/lib/python3.10/site-packages/wandb/sdk/lib/sock_client.py", line 174, in send_record_publish
    self.send_server_request(server_req)
  File "/opt/miniconda3/envs/lpn_py310/lib/python3.10/site-packages/wandb/sdk/lib/sock_client.py", line 154, in send_server_request
    self._send_message(msg)
  File "/opt/miniconda3/envs/lpn_py310/lib/python3.10/site-packages/wandb/sdk/lib/sock_client.py", line 151, in _send_message
    self._sendall_with_error_handle(header + data)
  File "/opt/miniconda3/envs/lpn_py310/lib/python3.10/site-packages/wandb/sdk/lib/sock_client.py", line 130, in _sendall_with_error_handle
    sent = self._sock.send(data)
BrokenPipeError: [Errno 32] Broken pipe

During handling of the above exception, another exception occurred:

Traceback (most recent call last):
  File "/opt/miniconda3/envs/lpn_py310/lib/python3.10/site-packages/wandb/sdk/lib/redirect.py", line 662, in _on_write
    cb(written_data)
  File "/opt/miniconda3/envs/lpn_py310/lib/python3.10/site-packages/wandb/sdk/wandb_run.py", line 2487, in <lambda>
    lambda data: self._console_raw_callback("stdout", data),
  File "/opt/miniconda3/envs/lpn_py310/lib/python3.10/site-packages/wandb/sdk/wandb_run.py", line 406, in wrapper
    return func(self, *args, **kwargs)
  File "/opt/miniconda3/envs/lpn_py310/lib/python3.10/site-packages/wandb/sdk/wandb_run.py", line 464, in wrapper_fn
    return func(self, *args, **kwargs)
  File "/opt/miniconda3/envs/lpn_py310/lib/python3.10/site-packages/wandb/sdk/wandb_run.py", line 1632, in _console_raw_callback
    self._backend.interface.publish_output_raw(name, data)
  File "/opt/miniconda3/envs/lpn_py310/lib/python3.10/site-packages/wandb/sdk/interface/interface.py", line 763, in publish_output_raw
    self._publish_output_raw(o)
  File "/opt/miniconda3/envs/lpn_py310/lib/python3.10/site-packages/wandb/sdk/interface/interface_shared.py", line 38, in _publish_output_raw
    self._publish(rec)
  File "/opt/miniconda3/envs/lpn_py310/lib/python3.10/site-packages/wandb/sdk/interface/interface_sock.py", line 39, in _publish
    self._sock_client.send_record_publish(record)
  File "/opt/miniconda3/envs/lpn_py310/lib/python3.10/site-packages/wandb/sdk/lib/sock_client.py", line 174, in send_record_publish
    self.send_server_request(server_req)
  File "/opt/miniconda3/envs/lpn_py310/lib/python3.10/site-packages/wandb/sdk/lib/sock_client.py", line 154, in send_server_request
    self._send_message(msg)
  File "/opt/miniconda3/envs/lpn_py310/lib/python3.10/site-packages/wandb/sdk/lib/sock_client.py", line 151, in _send_message
    self._sendall_with_error_handle(header + data)
  File "/opt/miniconda3/envs/lpn_py310/lib/python3.10/site-packages/wandb/sdk/lib/sock_client.py", line 130, in _sendall_with_error_handle
    sent = self._sock.send(data)
BrokenPipeError: [Errno 32] Broken pipe
2025-05-14 19:58:01,734 ERROR   MainThread:2633 [redirect.py:_on_write():664] [no run ID] error in stdout callback
Traceback (most recent call last):
  File "/opt/miniconda3/envs/lpn_py310/lib/python3.10/site-packages/IPython/core/events.py", line 82, in trigger
    func(*args, **kwargs)
  File "/opt/miniconda3/envs/lpn_py310/lib/python3.10/site-packages/wandb/sdk/wandb_init.py", line 603, in _pre_run_cell_hook
    self.backend.interface.publish_pause()
  File "/opt/miniconda3/envs/lpn_py310/lib/python3.10/site-packages/wandb/sdk/interface/interface.py", line 771, in publish_pause
    self._publish_pause(pause)
  File "/opt/miniconda3/envs/lpn_py310/lib/python3.10/site-packages/wandb/sdk/interface/interface_shared.py", line 289, in _publish_pause
    self._publish(rec)
  File "/opt/miniconda3/envs/lpn_py310/lib/python3.10/site-packages/wandb/sdk/interface/interface_sock.py", line 39, in _publish
    self._sock_client.send_record_publish(record)
  File "/opt/miniconda3/envs/lpn_py310/lib/python3.10/site-packages/wandb/sdk/lib/sock_client.py", line 174, in send_record_publish
    self.send_server_request(server_req)
  File "/opt/miniconda3/envs/lpn_py310/lib/python3.10/site-packages/wandb/sdk/lib/sock_client.py", line 154, in send_server_request
    self._send_message(msg)
  File "/opt/miniconda3/envs/lpn_py310/lib/python3.10/site-packages/wandb/sdk/lib/sock_client.py", line 151, in _send_message
    self._sendall_with_error_handle(header + data)
  File "/opt/miniconda3/envs/lpn_py310/lib/python3.10/site-packages/wandb/sdk/lib/sock_client.py", line 130, in _sendall_with_error_handle
    sent = self._sock.send(data)
BrokenPipeError: [Errno 32] Broken pipe

During handling of the above exception, another exception occurred:

Traceback (most recent call last):
  File "/opt/miniconda3/envs/lpn_py310/lib/python3.10/site-packages/wandb/sdk/lib/redirect.py", line 662, in _on_write
    cb(written_data)
  File "/opt/miniconda3/envs/lpn_py310/lib/python3.10/site-packages/wandb/sdk/wandb_run.py", line 2487, in <lambda>
    lambda data: self._console_raw_callback("stdout", data),
  File "/opt/miniconda3/envs/lpn_py310/lib/python3.10/site-packages/wandb/sdk/wandb_run.py", line 406, in wrapper
    return func(self, *args, **kwargs)
  File "/opt/miniconda3/envs/lpn_py310/lib/python3.10/site-packages/wandb/sdk/wandb_run.py", line 464, in wrapper_fn
    return func(self, *args, **kwargs)
  File "/opt/miniconda3/envs/lpn_py310/lib/python3.10/site-packages/wandb/sdk/wandb_run.py", line 1632, in _console_raw_callback
    self._backend.interface.publish_output_raw(name, data)
  File "/opt/miniconda3/envs/lpn_py310/lib/python3.10/site-packages/wandb/sdk/interface/interface.py", line 763, in publish_output_raw
    self._publish_output_raw(o)
  File "/opt/miniconda3/envs/lpn_py310/lib/python3.10/site-packages/wandb/sdk/interface/interface_shared.py", line 38, in _publish_output_raw
    self._publish(rec)
  File "/opt/miniconda3/envs/lpn_py310/lib/python3.10/site-packages/wandb/sdk/interface/interface_sock.py", line 39, in _publish
    self._sock_client.send_record_publish(record)
  File "/opt/miniconda3/envs/lpn_py310/lib/python3.10/site-packages/wandb/sdk/lib/sock_client.py", line 174, in send_record_publish
    self.send_server_request(server_req)
  File "/opt/miniconda3/envs/lpn_py310/lib/python3.10/site-packages/wandb/sdk/lib/sock_client.py", line 154, in send_server_request
    self._send_message(msg)
  File "/opt/miniconda3/envs/lpn_py310/lib/python3.10/site-packages/wandb/sdk/lib/sock_client.py", line 151, in _send_message
    self._sendall_with_error_handle(header + data)
  File "/opt/miniconda3/envs/lpn_py310/lib/python3.10/site-packages/wandb/sdk/lib/sock_client.py", line 130, in _sendall_with_error_handle
    sent = self._sock.send(data)
BrokenPipeError: [Errno 32] Broken pipe
2025-05-14 19:58:01,768 INFO    MainThread:2633 [wandb_init.py:_post_run_cell_hook():613] [no run ID] resuming backend
2025-05-14 19:58:01,768 ERROR   MainThread:2633 [redirect.py:_on_write():664] [no run ID] error in stdout callback
Traceback (most recent call last):
  File "/opt/miniconda3/envs/lpn_py310/lib/python3.10/site-packages/IPython/core/events.py", line 82, in trigger
    func(*args, **kwargs)
  File "/opt/miniconda3/envs/lpn_py310/lib/python3.10/site-packages/wandb/sdk/wandb_init.py", line 614, in _post_run_cell_hook
    self.backend.interface.publish_resume()
  File "/opt/miniconda3/envs/lpn_py310/lib/python3.10/site-packages/wandb/sdk/interface/interface.py", line 779, in publish_resume
    self._publish_resume(resume)
  File "/opt/miniconda3/envs/lpn_py310/lib/python3.10/site-packages/wandb/sdk/interface/interface_shared.py", line 293, in _publish_resume
    self._publish(rec)
  File "/opt/miniconda3/envs/lpn_py310/lib/python3.10/site-packages/wandb/sdk/interface/interface_sock.py", line 39, in _publish
    self._sock_client.send_record_publish(record)
  File "/opt/miniconda3/envs/lpn_py310/lib/python3.10/site-packages/wandb/sdk/lib/sock_client.py", line 174, in send_record_publish
    self.send_server_request(server_req)
  File "/opt/miniconda3/envs/lpn_py310/lib/python3.10/site-packages/wandb/sdk/lib/sock_client.py", line 154, in send_server_request
    self._send_message(msg)
  File "/opt/miniconda3/envs/lpn_py310/lib/python3.10/site-packages/wandb/sdk/lib/sock_client.py", line 151, in _send_message
    self._sendall_with_error_handle(header + data)
  File "/opt/miniconda3/envs/lpn_py310/lib/python3.10/site-packages/wandb/sdk/lib/sock_client.py", line 130, in _sendall_with_error_handle
    sent = self._sock.send(data)
BrokenPipeError: [Errno 32] Broken pipe

During handling of the above exception, another exception occurred:

Traceback (most recent call last):
  File "/opt/miniconda3/envs/lpn_py310/lib/python3.10/site-packages/wandb/sdk/lib/redirect.py", line 662, in _on_write
    cb(written_data)
  File "/opt/miniconda3/envs/lpn_py310/lib/python3.10/site-packages/wandb/sdk/wandb_run.py", line 2487, in <lambda>
    lambda data: self._console_raw_callback("stdout", data),
  File "/opt/miniconda3/envs/lpn_py310/lib/python3.10/site-packages/wandb/sdk/wandb_run.py", line 406, in wrapper
    return func(self, *args, **kwargs)
  File "/opt/miniconda3/envs/lpn_py310/lib/python3.10/site-packages/wandb/sdk/wandb_run.py", line 464, in wrapper_fn
    return func(self, *args, **kwargs)
  File "/opt/miniconda3/envs/lpn_py310/lib/python3.10/site-packages/wandb/sdk/wandb_run.py", line 1632, in _console_raw_callback
    self._backend.interface.publish_output_raw(name, data)
  File "/opt/miniconda3/envs/lpn_py310/lib/python3.10/site-packages/wandb/sdk/interface/interface.py", line 763, in publish_output_raw
    self._publish_output_raw(o)
  File "/opt/miniconda3/envs/lpn_py310/lib/python3.10/site-packages/wandb/sdk/interface/interface_shared.py", line 38, in _publish_output_raw
    self._publish(rec)
  File "/opt/miniconda3/envs/lpn_py310/lib/python3.10/site-packages/wandb/sdk/interface/interface_sock.py", line 39, in _publish
    self._sock_client.send_record_publish(record)
  File "/opt/miniconda3/envs/lpn_py310/lib/python3.10/site-packages/wandb/sdk/lib/sock_client.py", line 174, in send_record_publish
    self.send_server_request(server_req)
  File "/opt/miniconda3/envs/lpn_py310/lib/python3.10/site-packages/wandb/sdk/lib/sock_client.py", line 154, in send_server_request
    self._send_message(msg)
  File "/opt/miniconda3/envs/lpn_py310/lib/python3.10/site-packages/wandb/sdk/lib/sock_client.py", line 151, in _send_message
    self._sendall_with_error_handle(header + data)
  File "/opt/miniconda3/envs/lpn_py310/lib/python3.10/site-packages/wandb/sdk/lib/sock_client.py", line 130, in _sendall_with_error_handle
    sent = self._sock.send(data)
BrokenPipeError: [Errno 32] Broken pipe
2025-05-14 19:58:01,770 ERROR   MainThread:2633 [redirect.py:_on_write():664] [no run ID] error in stdout callback
Traceback (most recent call last):
  File "/opt/miniconda3/envs/lpn_py310/lib/python3.10/site-packages/IPython/core/events.py", line 82, in trigger
    func(*args, **kwargs)
  File "/opt/miniconda3/envs/lpn_py310/lib/python3.10/site-packages/wandb/sdk/wandb_init.py", line 614, in _post_run_cell_hook
    self.backend.interface.publish_resume()
  File "/opt/miniconda3/envs/lpn_py310/lib/python3.10/site-packages/wandb/sdk/interface/interface.py", line 779, in publish_resume
    self._publish_resume(resume)
  File "/opt/miniconda3/envs/lpn_py310/lib/python3.10/site-packages/wandb/sdk/interface/interface_shared.py", line 293, in _publish_resume
    self._publish(rec)
  File "/opt/miniconda3/envs/lpn_py310/lib/python3.10/site-packages/wandb/sdk/interface/interface_sock.py", line 39, in _publish
    self._sock_client.send_record_publish(record)
  File "/opt/miniconda3/envs/lpn_py310/lib/python3.10/site-packages/wandb/sdk/lib/sock_client.py", line 174, in send_record_publish
    self.send_server_request(server_req)
  File "/opt/miniconda3/envs/lpn_py310/lib/python3.10/site-packages/wandb/sdk/lib/sock_client.py", line 154, in send_server_request
    self._send_message(msg)
  File "/opt/miniconda3/envs/lpn_py310/lib/python3.10/site-packages/wandb/sdk/lib/sock_client.py", line 151, in _send_message
    self._sendall_with_error_handle(header + data)
  File "/opt/miniconda3/envs/lpn_py310/lib/python3.10/site-packages/wandb/sdk/lib/sock_client.py", line 130, in _sendall_with_error_handle
    sent = self._sock.send(data)
BrokenPipeError: [Errno 32] Broken pipe

During handling of the above exception, another exception occurred:

Traceback (most recent call last):
  File "/opt/miniconda3/envs/lpn_py310/lib/python3.10/site-packages/wandb/sdk/lib/redirect.py", line 662, in _on_write
    cb(written_data)
  File "/opt/miniconda3/envs/lpn_py310/lib/python3.10/site-packages/wandb/sdk/wandb_run.py", line 2487, in <lambda>
    lambda data: self._console_raw_callback("stdout", data),
  File "/opt/miniconda3/envs/lpn_py310/lib/python3.10/site-packages/wandb/sdk/wandb_run.py", line 406, in wrapper
    return func(self, *args, **kwargs)
  File "/opt/miniconda3/envs/lpn_py310/lib/python3.10/site-packages/wandb/sdk/wandb_run.py", line 464, in wrapper_fn
    return func(self, *args, **kwargs)
  File "/opt/miniconda3/envs/lpn_py310/lib/python3.10/site-packages/wandb/sdk/wandb_run.py", line 1632, in _console_raw_callback
    self._backend.interface.publish_output_raw(name, data)
  File "/opt/miniconda3/envs/lpn_py310/lib/python3.10/site-packages/wandb/sdk/interface/interface.py", line 763, in publish_output_raw
    self._publish_output_raw(o)
  File "/opt/miniconda3/envs/lpn_py310/lib/python3.10/site-packages/wandb/sdk/interface/interface_shared.py", line 38, in _publish_output_raw
    self._publish(rec)
  File "/opt/miniconda3/envs/lpn_py310/lib/python3.10/site-packages/wandb/sdk/interface/interface_sock.py", line 39, in _publish
    self._sock_client.send_record_publish(record)
  File "/opt/miniconda3/envs/lpn_py310/lib/python3.10/site-packages/wandb/sdk/lib/sock_client.py", line 174, in send_record_publish
    self.send_server_request(server_req)
  File "/opt/miniconda3/envs/lpn_py310/lib/python3.10/site-packages/wandb/sdk/lib/sock_client.py", line 154, in send_server_request
    self._send_message(msg)
  File "/opt/miniconda3/envs/lpn_py310/lib/python3.10/site-packages/wandb/sdk/lib/sock_client.py", line 151, in _send_message
    self._sendall_with_error_handle(header + data)
  File "/opt/miniconda3/envs/lpn_py310/lib/python3.10/site-packages/wandb/sdk/lib/sock_client.py", line 130, in _sendall_with_error_handle
    sent = self._sock.send(data)
BrokenPipeError: [Errno 32] Broken pipe
2025-05-14 19:58:01,809 INFO    MainThread:2633 [jupyter.py:save_ipynb():401] [no run ID] not saving jupyter notebook
2025-05-14 19:58:01,809 INFO    MainThread:2633 [wandb_init.py:_pre_run_cell_hook():602] [no run ID] pausing backend
2025-05-14 19:58:01,809 ERROR   MainThread:2633 [redirect.py:_on_write():664] [no run ID] error in stdout callback
Traceback (most recent call last):
  File "/opt/miniconda3/envs/lpn_py310/lib/python3.10/site-packages/IPython/core/events.py", line 82, in trigger
    func(*args, **kwargs)
  File "/opt/miniconda3/envs/lpn_py310/lib/python3.10/site-packages/wandb/sdk/wandb_init.py", line 603, in _pre_run_cell_hook
    self.backend.interface.publish_pause()
  File "/opt/miniconda3/envs/lpn_py310/lib/python3.10/site-packages/wandb/sdk/interface/interface.py", line 771, in publish_pause
    self._publish_pause(pause)
  File "/opt/miniconda3/envs/lpn_py310/lib/python3.10/site-packages/wandb/sdk/interface/interface_shared.py", line 289, in _publish_pause
    self._publish(rec)
  File "/opt/miniconda3/envs/lpn_py310/lib/python3.10/site-packages/wandb/sdk/interface/interface_sock.py", line 39, in _publish
    self._sock_client.send_record_publish(record)
  File "/opt/miniconda3/envs/lpn_py310/lib/python3.10/site-packages/wandb/sdk/lib/sock_client.py", line 174, in send_record_publish
    self.send_server_request(server_req)
  File "/opt/miniconda3/envs/lpn_py310/lib/python3.10/site-packages/wandb/sdk/lib/sock_client.py", line 154, in send_server_request
    self._send_message(msg)
  File "/opt/miniconda3/envs/lpn_py310/lib/python3.10/site-packages/wandb/sdk/lib/sock_client.py", line 151, in _send_message
    self._sendall_with_error_handle(header + data)
  File "/opt/miniconda3/envs/lpn_py310/lib/python3.10/site-packages/wandb/sdk/lib/sock_client.py", line 130, in _sendall_with_error_handle
    sent = self._sock.send(data)
BrokenPipeError: [Errno 32] Broken pipe

During handling of the above exception, another exception occurred:

Traceback (most recent call last):
  File "/opt/miniconda3/envs/lpn_py310/lib/python3.10/site-packages/wandb/sdk/lib/redirect.py", line 662, in _on_write
    cb(written_data)
  File "/opt/miniconda3/envs/lpn_py310/lib/python3.10/site-packages/wandb/sdk/wandb_run.py", line 2487, in <lambda>
    lambda data: self._console_raw_callback("stdout", data),
  File "/opt/miniconda3/envs/lpn_py310/lib/python3.10/site-packages/wandb/sdk/wandb_run.py", line 406, in wrapper
    return func(self, *args, **kwargs)
  File "/opt/miniconda3/envs/lpn_py310/lib/python3.10/site-packages/wandb/sdk/wandb_run.py", line 464, in wrapper_fn
    return func(self, *args, **kwargs)
  File "/opt/miniconda3/envs/lpn_py310/lib/python3.10/site-packages/wandb/sdk/wandb_run.py", line 1632, in _console_raw_callback
    self._backend.interface.publish_output_raw(name, data)
  File "/opt/miniconda3/envs/lpn_py310/lib/python3.10/site-packages/wandb/sdk/interface/interface.py", line 763, in publish_output_raw
    self._publish_output_raw(o)
  File "/opt/miniconda3/envs/lpn_py310/lib/python3.10/site-packages/wandb/sdk/interface/interface_shared.py", line 38, in _publish_output_raw
    self._publish(rec)
  File "/opt/miniconda3/envs/lpn_py310/lib/python3.10/site-packages/wandb/sdk/interface/interface_sock.py", line 39, in _publish
    self._sock_client.send_record_publish(record)
  File "/opt/miniconda3/envs/lpn_py310/lib/python3.10/site-packages/wandb/sdk/lib/sock_client.py", line 174, in send_record_publish
    self.send_server_request(server_req)
  File "/opt/miniconda3/envs/lpn_py310/lib/python3.10/site-packages/wandb/sdk/lib/sock_client.py", line 154, in send_server_request
    self._send_message(msg)
  File "/opt/miniconda3/envs/lpn_py310/lib/python3.10/site-packages/wandb/sdk/lib/sock_client.py", line 151, in _send_message
    self._sendall_with_error_handle(header + data)
  File "/opt/miniconda3/envs/lpn_py310/lib/python3.10/site-packages/wandb/sdk/lib/sock_client.py", line 130, in _sendall_with_error_handle
    sent = self._sock.send(data)
BrokenPipeError: [Errno 32] Broken pipe
2025-05-14 19:58:01,810 ERROR   MainThread:2633 [redirect.py:_on_write():664] [no run ID] error in stdout callback
Traceback (most recent call last):
  File "/opt/miniconda3/envs/lpn_py310/lib/python3.10/site-packages/IPython/core/events.py", line 82, in trigger
    func(*args, **kwargs)
  File "/opt/miniconda3/envs/lpn_py310/lib/python3.10/site-packages/wandb/sdk/wandb_init.py", line 603, in _pre_run_cell_hook
    self.backend.interface.publish_pause()
  File "/opt/miniconda3/envs/lpn_py310/lib/python3.10/site-packages/wandb/sdk/interface/interface.py", line 771, in publish_pause
    self._publish_pause(pause)
  File "/opt/miniconda3/envs/lpn_py310/lib/python3.10/site-packages/wandb/sdk/interface/interface_shared.py", line 289, in _publish_pause
    self._publish(rec)
  File "/opt/miniconda3/envs/lpn_py310/lib/python3.10/site-packages/wandb/sdk/interface/interface_sock.py", line 39, in _publish
    self._sock_client.send_record_publish(record)
  File "/opt/miniconda3/envs/lpn_py310/lib/python3.10/site-packages/wandb/sdk/lib/sock_client.py", line 174, in send_record_publish
    self.send_server_request(server_req)
  File "/opt/miniconda3/envs/lpn_py310/lib/python3.10/site-packages/wandb/sdk/lib/sock_client.py", line 154, in send_server_request
    self._send_message(msg)
  File "/opt/miniconda3/envs/lpn_py310/lib/python3.10/site-packages/wandb/sdk/lib/sock_client.py", line 151, in _send_message
    self._sendall_with_error_handle(header + data)
  File "/opt/miniconda3/envs/lpn_py310/lib/python3.10/site-packages/wandb/sdk/lib/sock_client.py", line 130, in _sendall_with_error_handle
    sent = self._sock.send(data)
BrokenPipeError: [Errno 32] Broken pipe

During handling of the above exception, another exception occurred:

Traceback (most recent call last):
  File "/opt/miniconda3/envs/lpn_py310/lib/python3.10/site-packages/wandb/sdk/lib/redirect.py", line 662, in _on_write
    cb(written_data)
  File "/opt/miniconda3/envs/lpn_py310/lib/python3.10/site-packages/wandb/sdk/wandb_run.py", line 2487, in <lambda>
    lambda data: self._console_raw_callback("stdout", data),
  File "/opt/miniconda3/envs/lpn_py310/lib/python3.10/site-packages/wandb/sdk/wandb_run.py", line 406, in wrapper
    return func(self, *args, **kwargs)
  File "/opt/miniconda3/envs/lpn_py310/lib/python3.10/site-packages/wandb/sdk/wandb_run.py", line 464, in wrapper_fn
    return func(self, *args, **kwargs)
  File "/opt/miniconda3/envs/lpn_py310/lib/python3.10/site-packages/wandb/sdk/wandb_run.py", line 1632, in _console_raw_callback
    self._backend.interface.publish_output_raw(name, data)
  File "/opt/miniconda3/envs/lpn_py310/lib/python3.10/site-packages/wandb/sdk/interface/interface.py", line 763, in publish_output_raw
    self._publish_output_raw(o)
  File "/opt/miniconda3/envs/lpn_py310/lib/python3.10/site-packages/wandb/sdk/interface/interface_shared.py", line 38, in _publish_output_raw
    self._publish(rec)
  File "/opt/miniconda3/envs/lpn_py310/lib/python3.10/site-packages/wandb/sdk/interface/interface_sock.py", line 39, in _publish
    self._sock_client.send_record_publish(record)
  File "/opt/miniconda3/envs/lpn_py310/lib/python3.10/site-packages/wandb/sdk/lib/sock_client.py", line 174, in send_record_publish
    self.send_server_request(server_req)
  File "/opt/miniconda3/envs/lpn_py310/lib/python3.10/site-packages/wandb/sdk/lib/sock_client.py", line 154, in send_server_request
    self._send_message(msg)
  File "/opt/miniconda3/envs/lpn_py310/lib/python3.10/site-packages/wandb/sdk/lib/sock_client.py", line 151, in _send_message
    self._sendall_with_error_handle(header + data)
  File "/opt/miniconda3/envs/lpn_py310/lib/python3.10/site-packages/wandb/sdk/lib/sock_client.py", line 130, in _sendall_with_error_handle
    sent = self._sock.send(data)
BrokenPipeError: [Errno 32] Broken pipe
2025-05-14 19:58:01,858 ERROR   MainThread:2633 [redirect.py:_on_write():664] [no run ID] error in stdout callback
Traceback (most recent call last):
  File "/opt/miniconda3/envs/lpn_py310/lib/python3.10/site-packages/wandb/sdk/lib/redirect.py", line 662, in _on_write
    cb(written_data)
  File "/opt/miniconda3/envs/lpn_py310/lib/python3.10/site-packages/wandb/sdk/wandb_run.py", line 2487, in <lambda>
    lambda data: self._console_raw_callback("stdout", data),
  File "/opt/miniconda3/envs/lpn_py310/lib/python3.10/site-packages/wandb/sdk/wandb_run.py", line 406, in wrapper
    return func(self, *args, **kwargs)
  File "/opt/miniconda3/envs/lpn_py310/lib/python3.10/site-packages/wandb/sdk/wandb_run.py", line 464, in wrapper_fn
    return func(self, *args, **kwargs)
  File "/opt/miniconda3/envs/lpn_py310/lib/python3.10/site-packages/wandb/sdk/wandb_run.py", line 1632, in _console_raw_callback
    self._backend.interface.publish_output_raw(name, data)
  File "/opt/miniconda3/envs/lpn_py310/lib/python3.10/site-packages/wandb/sdk/interface/interface.py", line 763, in publish_output_raw
    self._publish_output_raw(o)
  File "/opt/miniconda3/envs/lpn_py310/lib/python3.10/site-packages/wandb/sdk/interface/interface_shared.py", line 38, in _publish_output_raw
    self._publish(rec)
  File "/opt/miniconda3/envs/lpn_py310/lib/python3.10/site-packages/wandb/sdk/interface/interface_sock.py", line 39, in _publish
    self._sock_client.send_record_publish(record)
  File "/opt/miniconda3/envs/lpn_py310/lib/python3.10/site-packages/wandb/sdk/lib/sock_client.py", line 174, in send_record_publish
    self.send_server_request(server_req)
  File "/opt/miniconda3/envs/lpn_py310/lib/python3.10/site-packages/wandb/sdk/lib/sock_client.py", line 154, in send_server_request
    self._send_message(msg)
  File "/opt/miniconda3/envs/lpn_py310/lib/python3.10/site-packages/wandb/sdk/lib/sock_client.py", line 151, in _send_message
    self._sendall_with_error_handle(header + data)
  File "/opt/miniconda3/envs/lpn_py310/lib/python3.10/site-packages/wandb/sdk/lib/sock_client.py", line 130, in _sendall_with_error_handle
    sent = self._sock.send(data)
BrokenPipeError: [Errno 32] Broken pipe
2025-05-14 19:58:01,858 ERROR   MainThread:2633 [redirect.py:_on_write():664] [no run ID] error in stdout callback
Traceback (most recent call last):
  File "/opt/miniconda3/envs/lpn_py310/lib/python3.10/site-packages/wandb/sdk/lib/redirect.py", line 662, in _on_write
    cb(written_data)
  File "/opt/miniconda3/envs/lpn_py310/lib/python3.10/site-packages/wandb/sdk/wandb_run.py", line 2487, in <lambda>
    lambda data: self._console_raw_callback("stdout", data),
  File "/opt/miniconda3/envs/lpn_py310/lib/python3.10/site-packages/wandb/sdk/wandb_run.py", line 406, in wrapper
    return func(self, *args, **kwargs)
  File "/opt/miniconda3/envs/lpn_py310/lib/python3.10/site-packages/wandb/sdk/wandb_run.py", line 464, in wrapper_fn
    return func(self, *args, **kwargs)
  File "/opt/miniconda3/envs/lpn_py310/lib/python3.10/site-packages/wandb/sdk/wandb_run.py", line 1632, in _console_raw_callback
    self._backend.interface.publish_output_raw(name, data)
  File "/opt/miniconda3/envs/lpn_py310/lib/python3.10/site-packages/wandb/sdk/interface/interface.py", line 763, in publish_output_raw
    self._publish_output_raw(o)
  File "/opt/miniconda3/envs/lpn_py310/lib/python3.10/site-packages/wandb/sdk/interface/interface_shared.py", line 38, in _publish_output_raw
    self._publish(rec)
  File "/opt/miniconda3/envs/lpn_py310/lib/python3.10/site-packages/wandb/sdk/interface/interface_sock.py", line 39, in _publish
    self._sock_client.send_record_publish(record)
  File "/opt/miniconda3/envs/lpn_py310/lib/python3.10/site-packages/wandb/sdk/lib/sock_client.py", line 174, in send_record_publish
    self.send_server_request(server_req)
  File "/opt/miniconda3/envs/lpn_py310/lib/python3.10/site-packages/wandb/sdk/lib/sock_client.py", line 154, in send_server_request
    self._send_message(msg)
  File "/opt/miniconda3/envs/lpn_py310/lib/python3.10/site-packages/wandb/sdk/lib/sock_client.py", line 151, in _send_message
    self._sendall_with_error_handle(header + data)
  File "/opt/miniconda3/envs/lpn_py310/lib/python3.10/site-packages/wandb/sdk/lib/sock_client.py", line 130, in _sendall_with_error_handle
    sent = self._sock.send(data)
BrokenPipeError: [Errno 32] Broken pipe
2025-05-14 19:58:01,859 ERROR   MainThread:2633 [redirect.py:_on_write():664] [no run ID] error in stdout callback
Traceback (most recent call last):
  File "/opt/miniconda3/envs/lpn_py310/lib/python3.10/site-packages/wandb/sdk/lib/redirect.py", line 662, in _on_write
    cb(written_data)
  File "/opt/miniconda3/envs/lpn_py310/lib/python3.10/site-packages/wandb/sdk/wandb_run.py", line 2487, in <lambda>
    lambda data: self._console_raw_callback("stdout", data),
  File "/opt/miniconda3/envs/lpn_py310/lib/python3.10/site-packages/wandb/sdk/wandb_run.py", line 406, in wrapper
    return func(self, *args, **kwargs)
  File "/opt/miniconda3/envs/lpn_py310/lib/python3.10/site-packages/wandb/sdk/wandb_run.py", line 464, in wrapper_fn
    return func(self, *args, **kwargs)
  File "/opt/miniconda3/envs/lpn_py310/lib/python3.10/site-packages/wandb/sdk/wandb_run.py", line 1632, in _console_raw_callback
    self._backend.interface.publish_output_raw(name, data)
  File "/opt/miniconda3/envs/lpn_py310/lib/python3.10/site-packages/wandb/sdk/interface/interface.py", line 763, in publish_output_raw
    self._publish_output_raw(o)
  File "/opt/miniconda3/envs/lpn_py310/lib/python3.10/site-packages/wandb/sdk/interface/interface_shared.py", line 38, in _publish_output_raw
    self._publish(rec)
  File "/opt/miniconda3/envs/lpn_py310/lib/python3.10/site-packages/wandb/sdk/interface/interface_sock.py", line 39, in _publish
    self._sock_client.send_record_publish(record)
  File "/opt/miniconda3/envs/lpn_py310/lib/python3.10/site-packages/wandb/sdk/lib/sock_client.py", line 174, in send_record_publish
    self.send_server_request(server_req)
  File "/opt/miniconda3/envs/lpn_py310/lib/python3.10/site-packages/wandb/sdk/lib/sock_client.py", line 154, in send_server_request
    self._send_message(msg)
  File "/opt/miniconda3/envs/lpn_py310/lib/python3.10/site-packages/wandb/sdk/lib/sock_client.py", line 151, in _send_message
    self._sendall_with_error_handle(header + data)
  File "/opt/miniconda3/envs/lpn_py310/lib/python3.10/site-packages/wandb/sdk/lib/sock_client.py", line 130, in _sendall_with_error_handle
    sent = self._sock.send(data)
BrokenPipeError: [Errno 32] Broken pipe
2025-05-14 19:58:01,860 ERROR   MainThread:2633 [redirect.py:_on_write():664] [no run ID] error in stdout callback
Traceback (most recent call last):
  File "/opt/miniconda3/envs/lpn_py310/lib/python3.10/site-packages/wandb/sdk/lib/redirect.py", line 662, in _on_write
    cb(written_data)
  File "/opt/miniconda3/envs/lpn_py310/lib/python3.10/site-packages/wandb/sdk/wandb_run.py", line 2487, in <lambda>
    lambda data: self._console_raw_callback("stdout", data),
  File "/opt/miniconda3/envs/lpn_py310/lib/python3.10/site-packages/wandb/sdk/wandb_run.py", line 406, in wrapper
    return func(self, *args, **kwargs)
  File "/opt/miniconda3/envs/lpn_py310/lib/python3.10/site-packages/wandb/sdk/wandb_run.py", line 464, in wrapper_fn
    return func(self, *args, **kwargs)
  File "/opt/miniconda3/envs/lpn_py310/lib/python3.10/site-packages/wandb/sdk/wandb_run.py", line 1632, in _console_raw_callback
    self._backend.interface.publish_output_raw(name, data)
  File "/opt/miniconda3/envs/lpn_py310/lib/python3.10/site-packages/wandb/sdk/interface/interface.py", line 763, in publish_output_raw
    self._publish_output_raw(o)
  File "/opt/miniconda3/envs/lpn_py310/lib/python3.10/site-packages/wandb/sdk/interface/interface_shared.py", line 38, in _publish_output_raw
    self._publish(rec)
  File "/opt/miniconda3/envs/lpn_py310/lib/python3.10/site-packages/wandb/sdk/interface/interface_sock.py", line 39, in _publish
    self._sock_client.send_record_publish(record)
  File "/opt/miniconda3/envs/lpn_py310/lib/python3.10/site-packages/wandb/sdk/lib/sock_client.py", line 174, in send_record_publish
    self.send_server_request(server_req)
  File "/opt/miniconda3/envs/lpn_py310/lib/python3.10/site-packages/wandb/sdk/lib/sock_client.py", line 154, in send_server_request
    self._send_message(msg)
  File "/opt/miniconda3/envs/lpn_py310/lib/python3.10/site-packages/wandb/sdk/lib/sock_client.py", line 151, in _send_message
    self._sendall_with_error_handle(header + data)
  File "/opt/miniconda3/envs/lpn_py310/lib/python3.10/site-packages/wandb/sdk/lib/sock_client.py", line 130, in _sendall_with_error_handle
    sent = self._sock.send(data)
BrokenPipeError: [Errno 32] Broken pipe
2025-05-14 19:58:01,860 INFO    MainThread:2633 [wandb_init.py:_post_run_cell_hook():613] [no run ID] resuming backend
2025-05-14 19:58:01,860 ERROR   MainThread:2633 [redirect.py:_on_write():664] [no run ID] error in stdout callback
Traceback (most recent call last):
  File "/opt/miniconda3/envs/lpn_py310/lib/python3.10/site-packages/IPython/core/events.py", line 82, in trigger
    func(*args, **kwargs)
  File "/opt/miniconda3/envs/lpn_py310/lib/python3.10/site-packages/wandb/sdk/wandb_init.py", line 614, in _post_run_cell_hook
    self.backend.interface.publish_resume()
  File "/opt/miniconda3/envs/lpn_py310/lib/python3.10/site-packages/wandb/sdk/interface/interface.py", line 779, in publish_resume
    self._publish_resume(resume)
  File "/opt/miniconda3/envs/lpn_py310/lib/python3.10/site-packages/wandb/sdk/interface/interface_shared.py", line 293, in _publish_resume
    self._publish(rec)
  File "/opt/miniconda3/envs/lpn_py310/lib/python3.10/site-packages/wandb/sdk/interface/interface_sock.py", line 39, in _publish
    self._sock_client.send_record_publish(record)
  File "/opt/miniconda3/envs/lpn_py310/lib/python3.10/site-packages/wandb/sdk/lib/sock_client.py", line 174, in send_record_publish
    self.send_server_request(server_req)
  File "/opt/miniconda3/envs/lpn_py310/lib/python3.10/site-packages/wandb/sdk/lib/sock_client.py", line 154, in send_server_request
    self._send_message(msg)
  File "/opt/miniconda3/envs/lpn_py310/lib/python3.10/site-packages/wandb/sdk/lib/sock_client.py", line 151, in _send_message
    self._sendall_with_error_handle(header + data)
  File "/opt/miniconda3/envs/lpn_py310/lib/python3.10/site-packages/wandb/sdk/lib/sock_client.py", line 130, in _sendall_with_error_handle
    sent = self._sock.send(data)
BrokenPipeError: [Errno 32] Broken pipe

During handling of the above exception, another exception occurred:

Traceback (most recent call last):
  File "/opt/miniconda3/envs/lpn_py310/lib/python3.10/site-packages/wandb/sdk/lib/redirect.py", line 662, in _on_write
    cb(written_data)
  File "/opt/miniconda3/envs/lpn_py310/lib/python3.10/site-packages/wandb/sdk/wandb_run.py", line 2487, in <lambda>
    lambda data: self._console_raw_callback("stdout", data),
  File "/opt/miniconda3/envs/lpn_py310/lib/python3.10/site-packages/wandb/sdk/wandb_run.py", line 406, in wrapper
    return func(self, *args, **kwargs)
  File "/opt/miniconda3/envs/lpn_py310/lib/python3.10/site-packages/wandb/sdk/wandb_run.py", line 464, in wrapper_fn
    return func(self, *args, **kwargs)
  File "/opt/miniconda3/envs/lpn_py310/lib/python3.10/site-packages/wandb/sdk/wandb_run.py", line 1632, in _console_raw_callback
    self._backend.interface.publish_output_raw(name, data)
  File "/opt/miniconda3/envs/lpn_py310/lib/python3.10/site-packages/wandb/sdk/interface/interface.py", line 763, in publish_output_raw
    self._publish_output_raw(o)
  File "/opt/miniconda3/envs/lpn_py310/lib/python3.10/site-packages/wandb/sdk/interface/interface_shared.py", line 38, in _publish_output_raw
    self._publish(rec)
  File "/opt/miniconda3/envs/lpn_py310/lib/python3.10/site-packages/wandb/sdk/interface/interface_sock.py", line 39, in _publish
    self._sock_client.send_record_publish(record)
  File "/opt/miniconda3/envs/lpn_py310/lib/python3.10/site-packages/wandb/sdk/lib/sock_client.py", line 174, in send_record_publish
    self.send_server_request(server_req)
  File "/opt/miniconda3/envs/lpn_py310/lib/python3.10/site-packages/wandb/sdk/lib/sock_client.py", line 154, in send_server_request
    self._send_message(msg)
  File "/opt/miniconda3/envs/lpn_py310/lib/python3.10/site-packages/wandb/sdk/lib/sock_client.py", line 151, in _send_message
    self._sendall_with_error_handle(header + data)
  File "/opt/miniconda3/envs/lpn_py310/lib/python3.10/site-packages/wandb/sdk/lib/sock_client.py", line 130, in _sendall_with_error_handle
    sent = self._sock.send(data)
BrokenPipeError: [Errno 32] Broken pipe
2025-05-14 19:58:01,860 ERROR   MainThread:2633 [redirect.py:_on_write():664] [no run ID] error in stdout callback
Traceback (most recent call last):
  File "/opt/miniconda3/envs/lpn_py310/lib/python3.10/site-packages/IPython/core/events.py", line 82, in trigger
    func(*args, **kwargs)
  File "/opt/miniconda3/envs/lpn_py310/lib/python3.10/site-packages/wandb/sdk/wandb_init.py", line 614, in _post_run_cell_hook
    self.backend.interface.publish_resume()
  File "/opt/miniconda3/envs/lpn_py310/lib/python3.10/site-packages/wandb/sdk/interface/interface.py", line 779, in publish_resume
    self._publish_resume(resume)
  File "/opt/miniconda3/envs/lpn_py310/lib/python3.10/site-packages/wandb/sdk/interface/interface_shared.py", line 293, in _publish_resume
    self._publish(rec)
  File "/opt/miniconda3/envs/lpn_py310/lib/python3.10/site-packages/wandb/sdk/interface/interface_sock.py", line 39, in _publish
    self._sock_client.send_record_publish(record)
  File "/opt/miniconda3/envs/lpn_py310/lib/python3.10/site-packages/wandb/sdk/lib/sock_client.py", line 174, in send_record_publish
    self.send_server_request(server_req)
  File "/opt/miniconda3/envs/lpn_py310/lib/python3.10/site-packages/wandb/sdk/lib/sock_client.py", line 154, in send_server_request
    self._send_message(msg)
  File "/opt/miniconda3/envs/lpn_py310/lib/python3.10/site-packages/wandb/sdk/lib/sock_client.py", line 151, in _send_message
    self._sendall_with_error_handle(header + data)
  File "/opt/miniconda3/envs/lpn_py310/lib/python3.10/site-packages/wandb/sdk/lib/sock_client.py", line 130, in _sendall_with_error_handle
    sent = self._sock.send(data)
BrokenPipeError: [Errno 32] Broken pipe

During handling of the above exception, another exception occurred:

Traceback (most recent call last):
  File "/opt/miniconda3/envs/lpn_py310/lib/python3.10/site-packages/wandb/sdk/lib/redirect.py", line 662, in _on_write
    cb(written_data)
  File "/opt/miniconda3/envs/lpn_py310/lib/python3.10/site-packages/wandb/sdk/wandb_run.py", line 2487, in <lambda>
    lambda data: self._console_raw_callback("stdout", data),
  File "/opt/miniconda3/envs/lpn_py310/lib/python3.10/site-packages/wandb/sdk/wandb_run.py", line 406, in wrapper
    return func(self, *args, **kwargs)
  File "/opt/miniconda3/envs/lpn_py310/lib/python3.10/site-packages/wandb/sdk/wandb_run.py", line 464, in wrapper_fn
    return func(self, *args, **kwargs)
  File "/opt/miniconda3/envs/lpn_py310/lib/python3.10/site-packages/wandb/sdk/wandb_run.py", line 1632, in _console_raw_callback
    self._backend.interface.publish_output_raw(name, data)
  File "/opt/miniconda3/envs/lpn_py310/lib/python3.10/site-packages/wandb/sdk/interface/interface.py", line 763, in publish_output_raw
    self._publish_output_raw(o)
  File "/opt/miniconda3/envs/lpn_py310/lib/python3.10/site-packages/wandb/sdk/interface/interface_shared.py", line 38, in _publish_output_raw
    self._publish(rec)
  File "/opt/miniconda3/envs/lpn_py310/lib/python3.10/site-packages/wandb/sdk/interface/interface_sock.py", line 39, in _publish
    self._sock_client.send_record_publish(record)
  File "/opt/miniconda3/envs/lpn_py310/lib/python3.10/site-packages/wandb/sdk/lib/sock_client.py", line 174, in send_record_publish
    self.send_server_request(server_req)
  File "/opt/miniconda3/envs/lpn_py310/lib/python3.10/site-packages/wandb/sdk/lib/sock_client.py", line 154, in send_server_request
    self._send_message(msg)
  File "/opt/miniconda3/envs/lpn_py310/lib/python3.10/site-packages/wandb/sdk/lib/sock_client.py", line 151, in _send_message
    self._sendall_with_error_handle(header + data)
  File "/opt/miniconda3/envs/lpn_py310/lib/python3.10/site-packages/wandb/sdk/lib/sock_client.py", line 130, in _sendall_with_error_handle
    sent = self._sock.send(data)
BrokenPipeError: [Errno 32] Broken pipe
2025-05-14 19:58:01,909 INFO    MainThread:2633 [jupyter.py:save_ipynb():401] [no run ID] not saving jupyter notebook
2025-05-14 19:58:01,909 INFO    MainThread:2633 [wandb_init.py:_pre_run_cell_hook():602] [no run ID] pausing backend
2025-05-14 19:58:01,910 ERROR   MainThread:2633 [redirect.py:_on_write():664] [no run ID] error in stdout callback
Traceback (most recent call last):
  File "/opt/miniconda3/envs/lpn_py310/lib/python3.10/site-packages/IPython/core/events.py", line 82, in trigger
    func(*args, **kwargs)
  File "/opt/miniconda3/envs/lpn_py310/lib/python3.10/site-packages/wandb/sdk/wandb_init.py", line 603, in _pre_run_cell_hook
    self.backend.interface.publish_pause()
  File "/opt/miniconda3/envs/lpn_py310/lib/python3.10/site-packages/wandb/sdk/interface/interface.py", line 771, in publish_pause
    self._publish_pause(pause)
  File "/opt/miniconda3/envs/lpn_py310/lib/python3.10/site-packages/wandb/sdk/interface/interface_shared.py", line 289, in _publish_pause
    self._publish(rec)
  File "/opt/miniconda3/envs/lpn_py310/lib/python3.10/site-packages/wandb/sdk/interface/interface_sock.py", line 39, in _publish
    self._sock_client.send_record_publish(record)
  File "/opt/miniconda3/envs/lpn_py310/lib/python3.10/site-packages/wandb/sdk/lib/sock_client.py", line 174, in send_record_publish
    self.send_server_request(server_req)
  File "/opt/miniconda3/envs/lpn_py310/lib/python3.10/site-packages/wandb/sdk/lib/sock_client.py", line 154, in send_server_request
    self._send_message(msg)
  File "/opt/miniconda3/envs/lpn_py310/lib/python3.10/site-packages/wandb/sdk/lib/sock_client.py", line 151, in _send_message
    self._sendall_with_error_handle(header + data)
  File "/opt/miniconda3/envs/lpn_py310/lib/python3.10/site-packages/wandb/sdk/lib/sock_client.py", line 130, in _sendall_with_error_handle
    sent = self._sock.send(data)
BrokenPipeError: [Errno 32] Broken pipe

During handling of the above exception, another exception occurred:

Traceback (most recent call last):
  File "/opt/miniconda3/envs/lpn_py310/lib/python3.10/site-packages/wandb/sdk/lib/redirect.py", line 662, in _on_write
    cb(written_data)
  File "/opt/miniconda3/envs/lpn_py310/lib/python3.10/site-packages/wandb/sdk/wandb_run.py", line 2487, in <lambda>
    lambda data: self._console_raw_callback("stdout", data),
  File "/opt/miniconda3/envs/lpn_py310/lib/python3.10/site-packages/wandb/sdk/wandb_run.py", line 406, in wrapper
    return func(self, *args, **kwargs)
  File "/opt/miniconda3/envs/lpn_py310/lib/python3.10/site-packages/wandb/sdk/wandb_run.py", line 464, in wrapper_fn
    return func(self, *args, **kwargs)
  File "/opt/miniconda3/envs/lpn_py310/lib/python3.10/site-packages/wandb/sdk/wandb_run.py", line 1632, in _console_raw_callback
    self._backend.interface.publish_output_raw(name, data)
  File "/opt/miniconda3/envs/lpn_py310/lib/python3.10/site-packages/wandb/sdk/interface/interface.py", line 763, in publish_output_raw
    self._publish_output_raw(o)
  File "/opt/miniconda3/envs/lpn_py310/lib/python3.10/site-packages/wandb/sdk/interface/interface_shared.py", line 38, in _publish_output_raw
    self._publish(rec)
  File "/opt/miniconda3/envs/lpn_py310/lib/python3.10/site-packages/wandb/sdk/interface/interface_sock.py", line 39, in _publish
    self._sock_client.send_record_publish(record)
  File "/opt/miniconda3/envs/lpn_py310/lib/python3.10/site-packages/wandb/sdk/lib/sock_client.py", line 174, in send_record_publish
    self.send_server_request(server_req)
  File "/opt/miniconda3/envs/lpn_py310/lib/python3.10/site-packages/wandb/sdk/lib/sock_client.py", line 154, in send_server_request
    self._send_message(msg)
  File "/opt/miniconda3/envs/lpn_py310/lib/python3.10/site-packages/wandb/sdk/lib/sock_client.py", line 151, in _send_message
    self._sendall_with_error_handle(header + data)
  File "/opt/miniconda3/envs/lpn_py310/lib/python3.10/site-packages/wandb/sdk/lib/sock_client.py", line 130, in _sendall_with_error_handle
    sent = self._sock.send(data)
BrokenPipeError: [Errno 32] Broken pipe
2025-05-14 19:58:01,910 ERROR   MainThread:2633 [redirect.py:_on_write():664] [no run ID] error in stdout callback
Traceback (most recent call last):
  File "/opt/miniconda3/envs/lpn_py310/lib/python3.10/site-packages/IPython/core/events.py", line 82, in trigger
    func(*args, **kwargs)
  File "/opt/miniconda3/envs/lpn_py310/lib/python3.10/site-packages/wandb/sdk/wandb_init.py", line 603, in _pre_run_cell_hook
    self.backend.interface.publish_pause()
  File "/opt/miniconda3/envs/lpn_py310/lib/python3.10/site-packages/wandb/sdk/interface/interface.py", line 771, in publish_pause
    self._publish_pause(pause)
  File "/opt/miniconda3/envs/lpn_py310/lib/python3.10/site-packages/wandb/sdk/interface/interface_shared.py", line 289, in _publish_pause
    self._publish(rec)
  File "/opt/miniconda3/envs/lpn_py310/lib/python3.10/site-packages/wandb/sdk/interface/interface_sock.py", line 39, in _publish
    self._sock_client.send_record_publish(record)
  File "/opt/miniconda3/envs/lpn_py310/lib/python3.10/site-packages/wandb/sdk/lib/sock_client.py", line 174, in send_record_publish
    self.send_server_request(server_req)
  File "/opt/miniconda3/envs/lpn_py310/lib/python3.10/site-packages/wandb/sdk/lib/sock_client.py", line 154, in send_server_request
    self._send_message(msg)
  File "/opt/miniconda3/envs/lpn_py310/lib/python3.10/site-packages/wandb/sdk/lib/sock_client.py", line 151, in _send_message
    self._sendall_with_error_handle(header + data)
  File "/opt/miniconda3/envs/lpn_py310/lib/python3.10/site-packages/wandb/sdk/lib/sock_client.py", line 130, in _sendall_with_error_handle
    sent = self._sock.send(data)
BrokenPipeError: [Errno 32] Broken pipe

During handling of the above exception, another exception occurred:

Traceback (most recent call last):
  File "/opt/miniconda3/envs/lpn_py310/lib/python3.10/site-packages/wandb/sdk/lib/redirect.py", line 662, in _on_write
    cb(written_data)
  File "/opt/miniconda3/envs/lpn_py310/lib/python3.10/site-packages/wandb/sdk/wandb_run.py", line 2487, in <lambda>
    lambda data: self._console_raw_callback("stdout", data),
  File "/opt/miniconda3/envs/lpn_py310/lib/python3.10/site-packages/wandb/sdk/wandb_run.py", line 406, in wrapper
    return func(self, *args, **kwargs)
  File "/opt/miniconda3/envs/lpn_py310/lib/python3.10/site-packages/wandb/sdk/wandb_run.py", line 464, in wrapper_fn
    return func(self, *args, **kwargs)
  File "/opt/miniconda3/envs/lpn_py310/lib/python3.10/site-packages/wandb/sdk/wandb_run.py", line 1632, in _console_raw_callback
    self._backend.interface.publish_output_raw(name, data)
  File "/opt/miniconda3/envs/lpn_py310/lib/python3.10/site-packages/wandb/sdk/interface/interface.py", line 763, in publish_output_raw
    self._publish_output_raw(o)
  File "/opt/miniconda3/envs/lpn_py310/lib/python3.10/site-packages/wandb/sdk/interface/interface_shared.py", line 38, in _publish_output_raw
    self._publish(rec)
  File "/opt/miniconda3/envs/lpn_py310/lib/python3.10/site-packages/wandb/sdk/interface/interface_sock.py", line 39, in _publish
    self._sock_client.send_record_publish(record)
  File "/opt/miniconda3/envs/lpn_py310/lib/python3.10/site-packages/wandb/sdk/lib/sock_client.py", line 174, in send_record_publish
    self.send_server_request(server_req)
  File "/opt/miniconda3/envs/lpn_py310/lib/python3.10/site-packages/wandb/sdk/lib/sock_client.py", line 154, in send_server_request
    self._send_message(msg)
  File "/opt/miniconda3/envs/lpn_py310/lib/python3.10/site-packages/wandb/sdk/lib/sock_client.py", line 151, in _send_message
    self._sendall_with_error_handle(header + data)
  File "/opt/miniconda3/envs/lpn_py310/lib/python3.10/site-packages/wandb/sdk/lib/sock_client.py", line 130, in _sendall_with_error_handle
    sent = self._sock.send(data)
BrokenPipeError: [Errno 32] Broken pipe
2025-05-14 19:58:01,995 INFO    MainThread:2633 [wandb_init.py:_post_run_cell_hook():613] [no run ID] resuming backend
2025-05-14 19:58:01,996 ERROR   MainThread:2633 [redirect.py:_on_write():664] [no run ID] error in stdout callback
Traceback (most recent call last):
  File "/opt/miniconda3/envs/lpn_py310/lib/python3.10/site-packages/IPython/core/events.py", line 82, in trigger
    func(*args, **kwargs)
  File "/opt/miniconda3/envs/lpn_py310/lib/python3.10/site-packages/wandb/sdk/wandb_init.py", line 614, in _post_run_cell_hook
    self.backend.interface.publish_resume()
  File "/opt/miniconda3/envs/lpn_py310/lib/python3.10/site-packages/wandb/sdk/interface/interface.py", line 779, in publish_resume
    self._publish_resume(resume)
  File "/opt/miniconda3/envs/lpn_py310/lib/python3.10/site-packages/wandb/sdk/interface/interface_shared.py", line 293, in _publish_resume
    self._publish(rec)
  File "/opt/miniconda3/envs/lpn_py310/lib/python3.10/site-packages/wandb/sdk/interface/interface_sock.py", line 39, in _publish
    self._sock_client.send_record_publish(record)
  File "/opt/miniconda3/envs/lpn_py310/lib/python3.10/site-packages/wandb/sdk/lib/sock_client.py", line 174, in send_record_publish
    self.send_server_request(server_req)
  File "/opt/miniconda3/envs/lpn_py310/lib/python3.10/site-packages/wandb/sdk/lib/sock_client.py", line 154, in send_server_request
    self._send_message(msg)
  File "/opt/miniconda3/envs/lpn_py310/lib/python3.10/site-packages/wandb/sdk/lib/sock_client.py", line 151, in _send_message
    self._sendall_with_error_handle(header + data)
  File "/opt/miniconda3/envs/lpn_py310/lib/python3.10/site-packages/wandb/sdk/lib/sock_client.py", line 130, in _sendall_with_error_handle
    sent = self._sock.send(data)
BrokenPipeError: [Errno 32] Broken pipe

During handling of the above exception, another exception occurred:

Traceback (most recent call last):
  File "/opt/miniconda3/envs/lpn_py310/lib/python3.10/site-packages/wandb/sdk/lib/redirect.py", line 662, in _on_write
    cb(written_data)
  File "/opt/miniconda3/envs/lpn_py310/lib/python3.10/site-packages/wandb/sdk/wandb_run.py", line 2487, in <lambda>
    lambda data: self._console_raw_callback("stdout", data),
  File "/opt/miniconda3/envs/lpn_py310/lib/python3.10/site-packages/wandb/sdk/wandb_run.py", line 406, in wrapper
    return func(self, *args, **kwargs)
  File "/opt/miniconda3/envs/lpn_py310/lib/python3.10/site-packages/wandb/sdk/wandb_run.py", line 464, in wrapper_fn
    return func(self, *args, **kwargs)
  File "/opt/miniconda3/envs/lpn_py310/lib/python3.10/site-packages/wandb/sdk/wandb_run.py", line 1632, in _console_raw_callback
    self._backend.interface.publish_output_raw(name, data)
  File "/opt/miniconda3/envs/lpn_py310/lib/python3.10/site-packages/wandb/sdk/interface/interface.py", line 763, in publish_output_raw
    self._publish_output_raw(o)
  File "/opt/miniconda3/envs/lpn_py310/lib/python3.10/site-packages/wandb/sdk/interface/interface_shared.py", line 38, in _publish_output_raw
    self._publish(rec)
  File "/opt/miniconda3/envs/lpn_py310/lib/python3.10/site-packages/wandb/sdk/interface/interface_sock.py", line 39, in _publish
    self._sock_client.send_record_publish(record)
  File "/opt/miniconda3/envs/lpn_py310/lib/python3.10/site-packages/wandb/sdk/lib/sock_client.py", line 174, in send_record_publish
    self.send_server_request(server_req)
  File "/opt/miniconda3/envs/lpn_py310/lib/python3.10/site-packages/wandb/sdk/lib/sock_client.py", line 154, in send_server_request
    self._send_message(msg)
  File "/opt/miniconda3/envs/lpn_py310/lib/python3.10/site-packages/wandb/sdk/lib/sock_client.py", line 151, in _send_message
    self._sendall_with_error_handle(header + data)
  File "/opt/miniconda3/envs/lpn_py310/lib/python3.10/site-packages/wandb/sdk/lib/sock_client.py", line 130, in _sendall_with_error_handle
    sent = self._sock.send(data)
BrokenPipeError: [Errno 32] Broken pipe
2025-05-14 19:58:01,997 ERROR   MainThread:2633 [redirect.py:_on_write():664] [no run ID] error in stdout callback
Traceback (most recent call last):
  File "/opt/miniconda3/envs/lpn_py310/lib/python3.10/site-packages/IPython/core/events.py", line 82, in trigger
    func(*args, **kwargs)
  File "/opt/miniconda3/envs/lpn_py310/lib/python3.10/site-packages/wandb/sdk/wandb_init.py", line 614, in _post_run_cell_hook
    self.backend.interface.publish_resume()
  File "/opt/miniconda3/envs/lpn_py310/lib/python3.10/site-packages/wandb/sdk/interface/interface.py", line 779, in publish_resume
    self._publish_resume(resume)
  File "/opt/miniconda3/envs/lpn_py310/lib/python3.10/site-packages/wandb/sdk/interface/interface_shared.py", line 293, in _publish_resume
    self._publish(rec)
  File "/opt/miniconda3/envs/lpn_py310/lib/python3.10/site-packages/wandb/sdk/interface/interface_sock.py", line 39, in _publish
    self._sock_client.send_record_publish(record)
  File "/opt/miniconda3/envs/lpn_py310/lib/python3.10/site-packages/wandb/sdk/lib/sock_client.py", line 174, in send_record_publish
    self.send_server_request(server_req)
  File "/opt/miniconda3/envs/lpn_py310/lib/python3.10/site-packages/wandb/sdk/lib/sock_client.py", line 154, in send_server_request
    self._send_message(msg)
  File "/opt/miniconda3/envs/lpn_py310/lib/python3.10/site-packages/wandb/sdk/lib/sock_client.py", line 151, in _send_message
    self._sendall_with_error_handle(header + data)
  File "/opt/miniconda3/envs/lpn_py310/lib/python3.10/site-packages/wandb/sdk/lib/sock_client.py", line 130, in _sendall_with_error_handle
    sent = self._sock.send(data)
BrokenPipeError: [Errno 32] Broken pipe

During handling of the above exception, another exception occurred:

Traceback (most recent call last):
  File "/opt/miniconda3/envs/lpn_py310/lib/python3.10/site-packages/wandb/sdk/lib/redirect.py", line 662, in _on_write
    cb(written_data)
  File "/opt/miniconda3/envs/lpn_py310/lib/python3.10/site-packages/wandb/sdk/wandb_run.py", line 2487, in <lambda>
    lambda data: self._console_raw_callback("stdout", data),
  File "/opt/miniconda3/envs/lpn_py310/lib/python3.10/site-packages/wandb/sdk/wandb_run.py", line 406, in wrapper
    return func(self, *args, **kwargs)
  File "/opt/miniconda3/envs/lpn_py310/lib/python3.10/site-packages/wandb/sdk/wandb_run.py", line 464, in wrapper_fn
    return func(self, *args, **kwargs)
  File "/opt/miniconda3/envs/lpn_py310/lib/python3.10/site-packages/wandb/sdk/wandb_run.py", line 1632, in _console_raw_callback
    self._backend.interface.publish_output_raw(name, data)
  File "/opt/miniconda3/envs/lpn_py310/lib/python3.10/site-packages/wandb/sdk/interface/interface.py", line 763, in publish_output_raw
    self._publish_output_raw(o)
  File "/opt/miniconda3/envs/lpn_py310/lib/python3.10/site-packages/wandb/sdk/interface/interface_shared.py", line 38, in _publish_output_raw
    self._publish(rec)
  File "/opt/miniconda3/envs/lpn_py310/lib/python3.10/site-packages/wandb/sdk/interface/interface_sock.py", line 39, in _publish
    self._sock_client.send_record_publish(record)
  File "/opt/miniconda3/envs/lpn_py310/lib/python3.10/site-packages/wandb/sdk/lib/sock_client.py", line 174, in send_record_publish
    self.send_server_request(server_req)
  File "/opt/miniconda3/envs/lpn_py310/lib/python3.10/site-packages/wandb/sdk/lib/sock_client.py", line 154, in send_server_request
    self._send_message(msg)
  File "/opt/miniconda3/envs/lpn_py310/lib/python3.10/site-packages/wandb/sdk/lib/sock_client.py", line 151, in _send_message
    self._sendall_with_error_handle(header + data)
  File "/opt/miniconda3/envs/lpn_py310/lib/python3.10/site-packages/wandb/sdk/lib/sock_client.py", line 130, in _sendall_with_error_handle
    sent = self._sock.send(data)
BrokenPipeError: [Errno 32] Broken pipe
2025-05-14 19:58:02,046 INFO    MainThread:2633 [jupyter.py:save_ipynb():401] [no run ID] not saving jupyter notebook
2025-05-14 19:58:02,048 INFO    MainThread:2633 [wandb_init.py:_pre_run_cell_hook():602] [no run ID] pausing backend
2025-05-14 19:58:02,049 ERROR   MainThread:2633 [redirect.py:_on_write():664] [no run ID] error in stdout callback
Traceback (most recent call last):
  File "/opt/miniconda3/envs/lpn_py310/lib/python3.10/site-packages/IPython/core/events.py", line 82, in trigger
    func(*args, **kwargs)
  File "/opt/miniconda3/envs/lpn_py310/lib/python3.10/site-packages/wandb/sdk/wandb_init.py", line 603, in _pre_run_cell_hook
    self.backend.interface.publish_pause()
  File "/opt/miniconda3/envs/lpn_py310/lib/python3.10/site-packages/wandb/sdk/interface/interface.py", line 771, in publish_pause
    self._publish_pause(pause)
  File "/opt/miniconda3/envs/lpn_py310/lib/python3.10/site-packages/wandb/sdk/interface/interface_shared.py", line 289, in _publish_pause
    self._publish(rec)
  File "/opt/miniconda3/envs/lpn_py310/lib/python3.10/site-packages/wandb/sdk/interface/interface_sock.py", line 39, in _publish
    self._sock_client.send_record_publish(record)
  File "/opt/miniconda3/envs/lpn_py310/lib/python3.10/site-packages/wandb/sdk/lib/sock_client.py", line 174, in send_record_publish
    self.send_server_request(server_req)
  File "/opt/miniconda3/envs/lpn_py310/lib/python3.10/site-packages/wandb/sdk/lib/sock_client.py", line 154, in send_server_request
    self._send_message(msg)
  File "/opt/miniconda3/envs/lpn_py310/lib/python3.10/site-packages/wandb/sdk/lib/sock_client.py", line 151, in _send_message
    self._sendall_with_error_handle(header + data)
  File "/opt/miniconda3/envs/lpn_py310/lib/python3.10/site-packages/wandb/sdk/lib/sock_client.py", line 130, in _sendall_with_error_handle
    sent = self._sock.send(data)
BrokenPipeError: [Errno 32] Broken pipe

During handling of the above exception, another exception occurred:

Traceback (most recent call last):
  File "/opt/miniconda3/envs/lpn_py310/lib/python3.10/site-packages/wandb/sdk/lib/redirect.py", line 662, in _on_write
    cb(written_data)
  File "/opt/miniconda3/envs/lpn_py310/lib/python3.10/site-packages/wandb/sdk/wandb_run.py", line 2487, in <lambda>
    lambda data: self._console_raw_callback("stdout", data),
  File "/opt/miniconda3/envs/lpn_py310/lib/python3.10/site-packages/wandb/sdk/wandb_run.py", line 406, in wrapper
    return func(self, *args, **kwargs)
  File "/opt/miniconda3/envs/lpn_py310/lib/python3.10/site-packages/wandb/sdk/wandb_run.py", line 464, in wrapper_fn
    return func(self, *args, **kwargs)
  File "/opt/miniconda3/envs/lpn_py310/lib/python3.10/site-packages/wandb/sdk/wandb_run.py", line 1632, in _console_raw_callback
    self._backend.interface.publish_output_raw(name, data)
  File "/opt/miniconda3/envs/lpn_py310/lib/python3.10/site-packages/wandb/sdk/interface/interface.py", line 763, in publish_output_raw
    self._publish_output_raw(o)
  File "/opt/miniconda3/envs/lpn_py310/lib/python3.10/site-packages/wandb/sdk/interface/interface_shared.py", line 38, in _publish_output_raw
    self._publish(rec)
  File "/opt/miniconda3/envs/lpn_py310/lib/python3.10/site-packages/wandb/sdk/interface/interface_sock.py", line 39, in _publish
    self._sock_client.send_record_publish(record)
  File "/opt/miniconda3/envs/lpn_py310/lib/python3.10/site-packages/wandb/sdk/lib/sock_client.py", line 174, in send_record_publish
    self.send_server_request(server_req)
  File "/opt/miniconda3/envs/lpn_py310/lib/python3.10/site-packages/wandb/sdk/lib/sock_client.py", line 154, in send_server_request
    self._send_message(msg)
  File "/opt/miniconda3/envs/lpn_py310/lib/python3.10/site-packages/wandb/sdk/lib/sock_client.py", line 151, in _send_message
    self._sendall_with_error_handle(header + data)
  File "/opt/miniconda3/envs/lpn_py310/lib/python3.10/site-packages/wandb/sdk/lib/sock_client.py", line 130, in _sendall_with_error_handle
    sent = self._sock.send(data)
BrokenPipeError: [Errno 32] Broken pipe
2025-05-14 19:58:02,050 ERROR   MainThread:2633 [redirect.py:_on_write():664] [no run ID] error in stdout callback
Traceback (most recent call last):
  File "/opt/miniconda3/envs/lpn_py310/lib/python3.10/site-packages/IPython/core/events.py", line 82, in trigger
    func(*args, **kwargs)
  File "/opt/miniconda3/envs/lpn_py310/lib/python3.10/site-packages/wandb/sdk/wandb_init.py", line 603, in _pre_run_cell_hook
    self.backend.interface.publish_pause()
  File "/opt/miniconda3/envs/lpn_py310/lib/python3.10/site-packages/wandb/sdk/interface/interface.py", line 771, in publish_pause
    self._publish_pause(pause)
  File "/opt/miniconda3/envs/lpn_py310/lib/python3.10/site-packages/wandb/sdk/interface/interface_shared.py", line 289, in _publish_pause
    self._publish(rec)
  File "/opt/miniconda3/envs/lpn_py310/lib/python3.10/site-packages/wandb/sdk/interface/interface_sock.py", line 39, in _publish
    self._sock_client.send_record_publish(record)
  File "/opt/miniconda3/envs/lpn_py310/lib/python3.10/site-packages/wandb/sdk/lib/sock_client.py", line 174, in send_record_publish
    self.send_server_request(server_req)
  File "/opt/miniconda3/envs/lpn_py310/lib/python3.10/site-packages/wandb/sdk/lib/sock_client.py", line 154, in send_server_request
    self._send_message(msg)
  File "/opt/miniconda3/envs/lpn_py310/lib/python3.10/site-packages/wandb/sdk/lib/sock_client.py", line 151, in _send_message
    self._sendall_with_error_handle(header + data)
  File "/opt/miniconda3/envs/lpn_py310/lib/python3.10/site-packages/wandb/sdk/lib/sock_client.py", line 130, in _sendall_with_error_handle
    sent = self._sock.send(data)
BrokenPipeError: [Errno 32] Broken pipe

During handling of the above exception, another exception occurred:

Traceback (most recent call last):
  File "/opt/miniconda3/envs/lpn_py310/lib/python3.10/site-packages/wandb/sdk/lib/redirect.py", line 662, in _on_write
    cb(written_data)
  File "/opt/miniconda3/envs/lpn_py310/lib/python3.10/site-packages/wandb/sdk/wandb_run.py", line 2487, in <lambda>
    lambda data: self._console_raw_callback("stdout", data),
  File "/opt/miniconda3/envs/lpn_py310/lib/python3.10/site-packages/wandb/sdk/wandb_run.py", line 406, in wrapper
    return func(self, *args, **kwargs)
  File "/opt/miniconda3/envs/lpn_py310/lib/python3.10/site-packages/wandb/sdk/wandb_run.py", line 464, in wrapper_fn
    return func(self, *args, **kwargs)
  File "/opt/miniconda3/envs/lpn_py310/lib/python3.10/site-packages/wandb/sdk/wandb_run.py", line 1632, in _console_raw_callback
    self._backend.interface.publish_output_raw(name, data)
  File "/opt/miniconda3/envs/lpn_py310/lib/python3.10/site-packages/wandb/sdk/interface/interface.py", line 763, in publish_output_raw
    self._publish_output_raw(o)
  File "/opt/miniconda3/envs/lpn_py310/lib/python3.10/site-packages/wandb/sdk/interface/interface_shared.py", line 38, in _publish_output_raw
    self._publish(rec)
  File "/opt/miniconda3/envs/lpn_py310/lib/python3.10/site-packages/wandb/sdk/interface/interface_sock.py", line 39, in _publish
    self._sock_client.send_record_publish(record)
  File "/opt/miniconda3/envs/lpn_py310/lib/python3.10/site-packages/wandb/sdk/lib/sock_client.py", line 174, in send_record_publish
    self.send_server_request(server_req)
  File "/opt/miniconda3/envs/lpn_py310/lib/python3.10/site-packages/wandb/sdk/lib/sock_client.py", line 154, in send_server_request
    self._send_message(msg)
  File "/opt/miniconda3/envs/lpn_py310/lib/python3.10/site-packages/wandb/sdk/lib/sock_client.py", line 151, in _send_message
    self._sendall_with_error_handle(header + data)
  File "/opt/miniconda3/envs/lpn_py310/lib/python3.10/site-packages/wandb/sdk/lib/sock_client.py", line 130, in _sendall_with_error_handle
    sent = self._sock.send(data)
BrokenPipeError: [Errno 32] Broken pipe
2025-05-14 19:58:02,120 INFO    MainThread:2633 [wandb_run.py:_finish():2314] finishing run stephen-marcou-eth-z-rich/deterministic_lpn4sine_cf_maml/3ei0s5s5
2025-05-14 19:58:02,121 ERROR   MainThread:2633 [wandb_init.py:init():1660] [no run ID] error in wandb.init()
Traceback (most recent call last):
  File "/opt/miniconda3/envs/lpn_py310/lib/python3.10/site-packages/wandb/sdk/wandb_init.py", line 1650, in init
    return wi.init(run_settings, run_config, run_printer)
  File "/opt/miniconda3/envs/lpn_py310/lib/python3.10/site-packages/wandb/sdk/wandb_init.py", line 873, in init
    self._wl.finish_all_active_runs()
  File "/opt/miniconda3/envs/lpn_py310/lib/python3.10/site-packages/wandb/sdk/wandb_setup.py", line 150, in finish_all_active_runs
    run.finish()
  File "/opt/miniconda3/envs/lpn_py310/lib/python3.10/site-packages/wandb/sdk/wandb_run.py", line 406, in wrapper
    return func(self, *args, **kwargs)
  File "/opt/miniconda3/envs/lpn_py310/lib/python3.10/site-packages/wandb/sdk/wandb_run.py", line 503, in wrapper
    return func(self, *args, **kwargs)
  File "/opt/miniconda3/envs/lpn_py310/lib/python3.10/site-packages/wandb/sdk/wandb_run.py", line 451, in wrapper
    return func(self, *args, **kwargs)
  File "/opt/miniconda3/envs/lpn_py310/lib/python3.10/site-packages/wandb/sdk/wandb_run.py", line 2302, in finish
    return self._finish(exit_code)
  File "/opt/miniconda3/envs/lpn_py310/lib/python3.10/site-packages/wandb/sdk/wandb_run.py", line 406, in wrapper
    return func(self, *args, **kwargs)
  File "/opt/miniconda3/envs/lpn_py310/lib/python3.10/site-packages/wandb/sdk/wandb_run.py", line 2315, in _finish
    with telemetry.context(run=self) as tel:
  File "/opt/miniconda3/envs/lpn_py310/lib/python3.10/site-packages/wandb/sdk/lib/telemetry.py", line 42, in __exit__
    self._run._telemetry_callback(self._obj)
  File "/opt/miniconda3/envs/lpn_py310/lib/python3.10/site-packages/wandb/sdk/wandb_run.py", line 821, in _telemetry_callback
    self._telemetry_flush()
  File "/opt/miniconda3/envs/lpn_py310/lib/python3.10/site-packages/wandb/sdk/wandb_run.py", line 834, in _telemetry_flush
    self._backend.interface._publish_telemetry(self._telemetry_obj)
  File "/opt/miniconda3/envs/lpn_py310/lib/python3.10/site-packages/wandb/sdk/interface/interface_shared.py", line 60, in _publish_telemetry
    self._publish(rec)
  File "/opt/miniconda3/envs/lpn_py310/lib/python3.10/site-packages/wandb/sdk/interface/interface_sock.py", line 39, in _publish
    self._sock_client.send_record_publish(record)
  File "/opt/miniconda3/envs/lpn_py310/lib/python3.10/site-packages/wandb/sdk/lib/sock_client.py", line 174, in send_record_publish
    self.send_server_request(server_req)
  File "/opt/miniconda3/envs/lpn_py310/lib/python3.10/site-packages/wandb/sdk/lib/sock_client.py", line 154, in send_server_request
    self._send_message(msg)
  File "/opt/miniconda3/envs/lpn_py310/lib/python3.10/site-packages/wandb/sdk/lib/sock_client.py", line 151, in _send_message
    self._sendall_with_error_handle(header + data)
  File "/opt/miniconda3/envs/lpn_py310/lib/python3.10/site-packages/wandb/sdk/lib/sock_client.py", line 130, in _sendall_with_error_handle
    sent = self._sock.send(data)
BrokenPipeError: [Errno 32] Broken pipe
2025-05-14 19:58:02,946 INFO    MainThread:2633 [wandb_init.py:_post_run_cell_hook():613] [no run ID] resuming backend
2025-05-14 19:58:02,947 ERROR   MainThread:2633 [redirect.py:_on_write():664] [no run ID] error in stdout callback
Traceback (most recent call last):
  File "/opt/miniconda3/envs/lpn_py310/lib/python3.10/site-packages/IPython/core/events.py", line 82, in trigger
    func(*args, **kwargs)
  File "/opt/miniconda3/envs/lpn_py310/lib/python3.10/site-packages/wandb/sdk/wandb_init.py", line 614, in _post_run_cell_hook
    self.backend.interface.publish_resume()
  File "/opt/miniconda3/envs/lpn_py310/lib/python3.10/site-packages/wandb/sdk/interface/interface.py", line 779, in publish_resume
    self._publish_resume(resume)
  File "/opt/miniconda3/envs/lpn_py310/lib/python3.10/site-packages/wandb/sdk/interface/interface_shared.py", line 293, in _publish_resume
    self._publish(rec)
  File "/opt/miniconda3/envs/lpn_py310/lib/python3.10/site-packages/wandb/sdk/interface/interface_sock.py", line 39, in _publish
    self._sock_client.send_record_publish(record)
  File "/opt/miniconda3/envs/lpn_py310/lib/python3.10/site-packages/wandb/sdk/lib/sock_client.py", line 174, in send_record_publish
    self.send_server_request(server_req)
  File "/opt/miniconda3/envs/lpn_py310/lib/python3.10/site-packages/wandb/sdk/lib/sock_client.py", line 154, in send_server_request
    self._send_message(msg)
  File "/opt/miniconda3/envs/lpn_py310/lib/python3.10/site-packages/wandb/sdk/lib/sock_client.py", line 151, in _send_message
    self._sendall_with_error_handle(header + data)
  File "/opt/miniconda3/envs/lpn_py310/lib/python3.10/site-packages/wandb/sdk/lib/sock_client.py", line 130, in _sendall_with_error_handle
    sent = self._sock.send(data)
BrokenPipeError: [Errno 32] Broken pipe

During handling of the above exception, another exception occurred:

Traceback (most recent call last):
  File "/opt/miniconda3/envs/lpn_py310/lib/python3.10/site-packages/wandb/sdk/lib/redirect.py", line 662, in _on_write
    cb(written_data)
  File "/opt/miniconda3/envs/lpn_py310/lib/python3.10/site-packages/wandb/sdk/wandb_run.py", line 2487, in <lambda>
    lambda data: self._console_raw_callback("stdout", data),
  File "/opt/miniconda3/envs/lpn_py310/lib/python3.10/site-packages/wandb/sdk/wandb_run.py", line 406, in wrapper
    return func(self, *args, **kwargs)
  File "/opt/miniconda3/envs/lpn_py310/lib/python3.10/site-packages/wandb/sdk/wandb_run.py", line 464, in wrapper_fn
    return func(self, *args, **kwargs)
  File "/opt/miniconda3/envs/lpn_py310/lib/python3.10/site-packages/wandb/sdk/wandb_run.py", line 1632, in _console_raw_callback
    self._backend.interface.publish_output_raw(name, data)
  File "/opt/miniconda3/envs/lpn_py310/lib/python3.10/site-packages/wandb/sdk/interface/interface.py", line 763, in publish_output_raw
    self._publish_output_raw(o)
  File "/opt/miniconda3/envs/lpn_py310/lib/python3.10/site-packages/wandb/sdk/interface/interface_shared.py", line 38, in _publish_output_raw
    self._publish(rec)
  File "/opt/miniconda3/envs/lpn_py310/lib/python3.10/site-packages/wandb/sdk/interface/interface_sock.py", line 39, in _publish
    self._sock_client.send_record_publish(record)
  File "/opt/miniconda3/envs/lpn_py310/lib/python3.10/site-packages/wandb/sdk/lib/sock_client.py", line 174, in send_record_publish
    self.send_server_request(server_req)
  File "/opt/miniconda3/envs/lpn_py310/lib/python3.10/site-packages/wandb/sdk/lib/sock_client.py", line 154, in send_server_request
    self._send_message(msg)
  File "/opt/miniconda3/envs/lpn_py310/lib/python3.10/site-packages/wandb/sdk/lib/sock_client.py", line 151, in _send_message
    self._sendall_with_error_handle(header + data)
  File "/opt/miniconda3/envs/lpn_py310/lib/python3.10/site-packages/wandb/sdk/lib/sock_client.py", line 130, in _sendall_with_error_handle
    sent = self._sock.send(data)
BrokenPipeError: [Errno 32] Broken pipe
2025-05-14 19:58:02,947 ERROR   MainThread:2633 [redirect.py:_on_write():664] [no run ID] error in stdout callback
Traceback (most recent call last):
  File "/opt/miniconda3/envs/lpn_py310/lib/python3.10/site-packages/IPython/core/events.py", line 82, in trigger
    func(*args, **kwargs)
  File "/opt/miniconda3/envs/lpn_py310/lib/python3.10/site-packages/wandb/sdk/wandb_init.py", line 614, in _post_run_cell_hook
    self.backend.interface.publish_resume()
  File "/opt/miniconda3/envs/lpn_py310/lib/python3.10/site-packages/wandb/sdk/interface/interface.py", line 779, in publish_resume
    self._publish_resume(resume)
  File "/opt/miniconda3/envs/lpn_py310/lib/python3.10/site-packages/wandb/sdk/interface/interface_shared.py", line 293, in _publish_resume
    self._publish(rec)
  File "/opt/miniconda3/envs/lpn_py310/lib/python3.10/site-packages/wandb/sdk/interface/interface_sock.py", line 39, in _publish
    self._sock_client.send_record_publish(record)
  File "/opt/miniconda3/envs/lpn_py310/lib/python3.10/site-packages/wandb/sdk/lib/sock_client.py", line 174, in send_record_publish
    self.send_server_request(server_req)
  File "/opt/miniconda3/envs/lpn_py310/lib/python3.10/site-packages/wandb/sdk/lib/sock_client.py", line 154, in send_server_request
    self._send_message(msg)
  File "/opt/miniconda3/envs/lpn_py310/lib/python3.10/site-packages/wandb/sdk/lib/sock_client.py", line 151, in _send_message
    self._sendall_with_error_handle(header + data)
  File "/opt/miniconda3/envs/lpn_py310/lib/python3.10/site-packages/wandb/sdk/lib/sock_client.py", line 130, in _sendall_with_error_handle
    sent = self._sock.send(data)
BrokenPipeError: [Errno 32] Broken pipe

During handling of the above exception, another exception occurred:

Traceback (most recent call last):
  File "/opt/miniconda3/envs/lpn_py310/lib/python3.10/site-packages/wandb/sdk/lib/redirect.py", line 662, in _on_write
    cb(written_data)
  File "/opt/miniconda3/envs/lpn_py310/lib/python3.10/site-packages/wandb/sdk/wandb_run.py", line 2487, in <lambda>
    lambda data: self._console_raw_callback("stdout", data),
  File "/opt/miniconda3/envs/lpn_py310/lib/python3.10/site-packages/wandb/sdk/wandb_run.py", line 406, in wrapper
    return func(self, *args, **kwargs)
  File "/opt/miniconda3/envs/lpn_py310/lib/python3.10/site-packages/wandb/sdk/wandb_run.py", line 464, in wrapper_fn
    return func(self, *args, **kwargs)
  File "/opt/miniconda3/envs/lpn_py310/lib/python3.10/site-packages/wandb/sdk/wandb_run.py", line 1632, in _console_raw_callback
    self._backend.interface.publish_output_raw(name, data)
  File "/opt/miniconda3/envs/lpn_py310/lib/python3.10/site-packages/wandb/sdk/interface/interface.py", line 763, in publish_output_raw
    self._publish_output_raw(o)
  File "/opt/miniconda3/envs/lpn_py310/lib/python3.10/site-packages/wandb/sdk/interface/interface_shared.py", line 38, in _publish_output_raw
    self._publish(rec)
  File "/opt/miniconda3/envs/lpn_py310/lib/python3.10/site-packages/wandb/sdk/interface/interface_sock.py", line 39, in _publish
    self._sock_client.send_record_publish(record)
  File "/opt/miniconda3/envs/lpn_py310/lib/python3.10/site-packages/wandb/sdk/lib/sock_client.py", line 174, in send_record_publish
    self.send_server_request(server_req)
  File "/opt/miniconda3/envs/lpn_py310/lib/python3.10/site-packages/wandb/sdk/lib/sock_client.py", line 154, in send_server_request
    self._send_message(msg)
  File "/opt/miniconda3/envs/lpn_py310/lib/python3.10/site-packages/wandb/sdk/lib/sock_client.py", line 151, in _send_message
    self._sendall_with_error_handle(header + data)
  File "/opt/miniconda3/envs/lpn_py310/lib/python3.10/site-packages/wandb/sdk/lib/sock_client.py", line 130, in _sendall_with_error_handle
    sent = self._sock.send(data)
BrokenPipeError: [Errno 32] Broken pipe
