2025-05-08 17:10:54,825 INFO    MainThread:48740 [wandb_init.py:setup_run_log_directory():724] Logging user logs to /Users/stephenmarcou/Documents/ETH Zurich/Semester 2/AI Center Projects in Machine Learning/pmlr25-lpn/src/wandb/run-20250508_171054-5cni9044/logs/debug.log
2025-05-08 17:10:54,825 INFO    MainThread:48740 [wandb_init.py:setup_run_log_directory():725] Logging internal logs to /Users/stephenmarcou/Documents/ETH Zurich/Semester 2/AI Center Projects in Machine Learning/pmlr25-lpn/src/wandb/run-20250508_171054-5cni9044/logs/debug-internal.log
2025-05-08 17:10:54,826 INFO    MainThread:48740 [wandb_init.py:monkeypatch_ipython():643] configuring jupyter hooks <wandb.sdk.wandb_init._WandbInit object at 0x17110d1e0>
2025-05-08 17:10:54,826 INFO    MainThread:48740 [wandb_init.py:init():852] calling init triggers
2025-05-08 17:10:54,826 INFO    MainThread:48740 [wandb_init.py:init():857] wandb.init called with sweep_config: {}
config: {'_wandb': {}}
2025-05-08 17:10:54,826 INFO    MainThread:48740 [wandb_init.py:init():893] starting backend
2025-05-08 17:10:54,826 INFO    MainThread:48740 [wandb_init.py:init():897] sending inform_init request
2025-05-08 17:10:54,832 INFO    MainThread:48740 [backend.py:_multiprocessing_setup():101] multiprocessing start_methods=spawn,fork,forkserver, using: spawn
2025-05-08 17:10:54,832 INFO    MainThread:48740 [wandb_init.py:init():907] backend started and connected
2025-05-08 17:10:54,860 INFO    MainThread:48740 [wandb_run.py:_label_probe_notebook():1369] probe notebook
2025-05-08 17:10:54,862 INFO    MainThread:48740 [wandb_init.py:init():1002] updated telemetry
2025-05-08 17:10:55,155 INFO    MainThread:48740 [wandb_init.py:init():1026] communicating run to backend with 90.0 second timeout
2025-05-08 17:10:55,835 INFO    MainThread:48740 [wandb_init.py:init():1101] starting run threads in backend
2025-05-08 17:10:55,998 INFO    MainThread:48740 [wandb_run.py:_console_start():2566] atexit reg
2025-05-08 17:10:56,000 INFO    MainThread:48740 [wandb_run.py:_redirect():2414] redirect: wrap_raw
2025-05-08 17:10:56,000 INFO    MainThread:48740 [wandb_run.py:_redirect():2483] Wrapping output streams.
2025-05-08 17:10:56,000 INFO    MainThread:48740 [wandb_run.py:_redirect():2506] Redirects installed.
2025-05-08 17:10:56,003 INFO    MainThread:48740 [wandb_init.py:init():1147] run started, returning control to user process
2025-05-08 17:15:55,686 WARNING MsgRouterThr:48740 [router.py:message_loop():63] [no run ID] message_loop has been closed
Traceback (most recent call last):
  File "/opt/miniconda3/envs/lpn_py310/lib/python3.10/site-packages/wandb/sdk/interface/router_sock.py", line 27, in _read_message
    return self._sock_client.read_server_response(timeout=1)
  File "/opt/miniconda3/envs/lpn_py310/lib/python3.10/site-packages/wandb/sdk/lib/sock_client.py", line 235, in read_server_response
    data = self._read_packet_bytes(timeout=timeout)
  File "/opt/miniconda3/envs/lpn_py310/lib/python3.10/site-packages/wandb/sdk/lib/sock_client.py", line 220, in _read_packet_bytes
    raise SockClientClosedError
wandb.sdk.lib.sock_client.SockClientClosedError

The above exception was the direct cause of the following exception:

Traceback (most recent call last):
  File "/opt/miniconda3/envs/lpn_py310/lib/python3.10/site-packages/wandb/sdk/interface/router.py", line 56, in message_loop
    msg = self._read_message()
  File "/opt/miniconda3/envs/lpn_py310/lib/python3.10/site-packages/wandb/sdk/interface/router_sock.py", line 29, in _read_message
    raise MessageRouterClosedError from e
wandb.sdk.interface.router.MessageRouterClosedError
2025-05-08 17:15:55,913 INFO    MsgRouterThr:48740 [mailbox.py:close():129] [no run ID] Closing mailbox, abandoning 3 handles.
2025-05-08 17:15:56,851 INFO    MainThread:48740 [wandb_init.py:_post_run_cell_hook():613] [no run ID] resuming backend
2025-05-08 17:26:40,792 INFO    MainThread:48740 [jupyter.py:save_ipynb():401] [no run ID] not saving jupyter notebook
2025-05-08 17:26:40,800 INFO    MainThread:48740 [wandb_init.py:_pre_run_cell_hook():602] [no run ID] pausing backend
2025-05-08 17:26:40,845 ERROR   MainThread:48740 [redirect.py:_on_write():664] [no run ID] error in stdout callback
Traceback (most recent call last):
  File "/opt/miniconda3/envs/lpn_py310/lib/python3.10/site-packages/IPython/core/events.py", line 82, in trigger
    func(*args, **kwargs)
  File "/opt/miniconda3/envs/lpn_py310/lib/python3.10/site-packages/wandb/sdk/wandb_init.py", line 603, in _pre_run_cell_hook
    self.backend.interface.publish_pause()
  File "/opt/miniconda3/envs/lpn_py310/lib/python3.10/site-packages/wandb/sdk/interface/interface.py", line 771, in publish_pause
    self._publish_pause(pause)
  File "/opt/miniconda3/envs/lpn_py310/lib/python3.10/site-packages/wandb/sdk/interface/interface_shared.py", line 289, in _publish_pause
    self._publish(rec)
  File "/opt/miniconda3/envs/lpn_py310/lib/python3.10/site-packages/wandb/sdk/interface/interface_sock.py", line 39, in _publish
    self._sock_client.send_record_publish(record)
  File "/opt/miniconda3/envs/lpn_py310/lib/python3.10/site-packages/wandb/sdk/lib/sock_client.py", line 174, in send_record_publish
    self.send_server_request(server_req)
  File "/opt/miniconda3/envs/lpn_py310/lib/python3.10/site-packages/wandb/sdk/lib/sock_client.py", line 154, in send_server_request
    self._send_message(msg)
  File "/opt/miniconda3/envs/lpn_py310/lib/python3.10/site-packages/wandb/sdk/lib/sock_client.py", line 151, in _send_message
    self._sendall_with_error_handle(header + data)
  File "/opt/miniconda3/envs/lpn_py310/lib/python3.10/site-packages/wandb/sdk/lib/sock_client.py", line 130, in _sendall_with_error_handle
    sent = self._sock.send(data)
BrokenPipeError: [Errno 32] Broken pipe

During handling of the above exception, another exception occurred:

Traceback (most recent call last):
  File "/opt/miniconda3/envs/lpn_py310/lib/python3.10/site-packages/wandb/sdk/lib/redirect.py", line 662, in _on_write
    cb(written_data)
  File "/opt/miniconda3/envs/lpn_py310/lib/python3.10/site-packages/wandb/sdk/wandb_run.py", line 2487, in <lambda>
    lambda data: self._console_raw_callback("stdout", data),
  File "/opt/miniconda3/envs/lpn_py310/lib/python3.10/site-packages/wandb/sdk/wandb_run.py", line 406, in wrapper
    return func(self, *args, **kwargs)
  File "/opt/miniconda3/envs/lpn_py310/lib/python3.10/site-packages/wandb/sdk/wandb_run.py", line 464, in wrapper_fn
    return func(self, *args, **kwargs)
  File "/opt/miniconda3/envs/lpn_py310/lib/python3.10/site-packages/wandb/sdk/wandb_run.py", line 1632, in _console_raw_callback
    self._backend.interface.publish_output_raw(name, data)
  File "/opt/miniconda3/envs/lpn_py310/lib/python3.10/site-packages/wandb/sdk/interface/interface.py", line 763, in publish_output_raw
    self._publish_output_raw(o)
  File "/opt/miniconda3/envs/lpn_py310/lib/python3.10/site-packages/wandb/sdk/interface/interface_shared.py", line 38, in _publish_output_raw
    self._publish(rec)
  File "/opt/miniconda3/envs/lpn_py310/lib/python3.10/site-packages/wandb/sdk/interface/interface_sock.py", line 39, in _publish
    self._sock_client.send_record_publish(record)
  File "/opt/miniconda3/envs/lpn_py310/lib/python3.10/site-packages/wandb/sdk/lib/sock_client.py", line 174, in send_record_publish
    self.send_server_request(server_req)
  File "/opt/miniconda3/envs/lpn_py310/lib/python3.10/site-packages/wandb/sdk/lib/sock_client.py", line 154, in send_server_request
    self._send_message(msg)
  File "/opt/miniconda3/envs/lpn_py310/lib/python3.10/site-packages/wandb/sdk/lib/sock_client.py", line 151, in _send_message
    self._sendall_with_error_handle(header + data)
  File "/opt/miniconda3/envs/lpn_py310/lib/python3.10/site-packages/wandb/sdk/lib/sock_client.py", line 130, in _sendall_with_error_handle
    sent = self._sock.send(data)
BrokenPipeError: [Errno 32] Broken pipe
2025-05-08 17:26:40,865 ERROR   MainThread:48740 [redirect.py:_on_write():664] [no run ID] error in stdout callback
Traceback (most recent call last):
  File "/opt/miniconda3/envs/lpn_py310/lib/python3.10/site-packages/IPython/core/events.py", line 82, in trigger
    func(*args, **kwargs)
  File "/opt/miniconda3/envs/lpn_py310/lib/python3.10/site-packages/wandb/sdk/wandb_init.py", line 603, in _pre_run_cell_hook
    self.backend.interface.publish_pause()
  File "/opt/miniconda3/envs/lpn_py310/lib/python3.10/site-packages/wandb/sdk/interface/interface.py", line 771, in publish_pause
    self._publish_pause(pause)
  File "/opt/miniconda3/envs/lpn_py310/lib/python3.10/site-packages/wandb/sdk/interface/interface_shared.py", line 289, in _publish_pause
    self._publish(rec)
  File "/opt/miniconda3/envs/lpn_py310/lib/python3.10/site-packages/wandb/sdk/interface/interface_sock.py", line 39, in _publish
    self._sock_client.send_record_publish(record)
  File "/opt/miniconda3/envs/lpn_py310/lib/python3.10/site-packages/wandb/sdk/lib/sock_client.py", line 174, in send_record_publish
    self.send_server_request(server_req)
  File "/opt/miniconda3/envs/lpn_py310/lib/python3.10/site-packages/wandb/sdk/lib/sock_client.py", line 154, in send_server_request
    self._send_message(msg)
  File "/opt/miniconda3/envs/lpn_py310/lib/python3.10/site-packages/wandb/sdk/lib/sock_client.py", line 151, in _send_message
    self._sendall_with_error_handle(header + data)
  File "/opt/miniconda3/envs/lpn_py310/lib/python3.10/site-packages/wandb/sdk/lib/sock_client.py", line 130, in _sendall_with_error_handle
    sent = self._sock.send(data)
BrokenPipeError: [Errno 32] Broken pipe

During handling of the above exception, another exception occurred:

Traceback (most recent call last):
  File "/opt/miniconda3/envs/lpn_py310/lib/python3.10/site-packages/wandb/sdk/lib/redirect.py", line 662, in _on_write
    cb(written_data)
  File "/opt/miniconda3/envs/lpn_py310/lib/python3.10/site-packages/wandb/sdk/wandb_run.py", line 2487, in <lambda>
    lambda data: self._console_raw_callback("stdout", data),
  File "/opt/miniconda3/envs/lpn_py310/lib/python3.10/site-packages/wandb/sdk/wandb_run.py", line 406, in wrapper
    return func(self, *args, **kwargs)
  File "/opt/miniconda3/envs/lpn_py310/lib/python3.10/site-packages/wandb/sdk/wandb_run.py", line 464, in wrapper_fn
    return func(self, *args, **kwargs)
  File "/opt/miniconda3/envs/lpn_py310/lib/python3.10/site-packages/wandb/sdk/wandb_run.py", line 1632, in _console_raw_callback
    self._backend.interface.publish_output_raw(name, data)
  File "/opt/miniconda3/envs/lpn_py310/lib/python3.10/site-packages/wandb/sdk/interface/interface.py", line 763, in publish_output_raw
    self._publish_output_raw(o)
  File "/opt/miniconda3/envs/lpn_py310/lib/python3.10/site-packages/wandb/sdk/interface/interface_shared.py", line 38, in _publish_output_raw
    self._publish(rec)
  File "/opt/miniconda3/envs/lpn_py310/lib/python3.10/site-packages/wandb/sdk/interface/interface_sock.py", line 39, in _publish
    self._sock_client.send_record_publish(record)
  File "/opt/miniconda3/envs/lpn_py310/lib/python3.10/site-packages/wandb/sdk/lib/sock_client.py", line 174, in send_record_publish
    self.send_server_request(server_req)
  File "/opt/miniconda3/envs/lpn_py310/lib/python3.10/site-packages/wandb/sdk/lib/sock_client.py", line 154, in send_server_request
    self._send_message(msg)
  File "/opt/miniconda3/envs/lpn_py310/lib/python3.10/site-packages/wandb/sdk/lib/sock_client.py", line 151, in _send_message
    self._sendall_with_error_handle(header + data)
  File "/opt/miniconda3/envs/lpn_py310/lib/python3.10/site-packages/wandb/sdk/lib/sock_client.py", line 130, in _sendall_with_error_handle
    sent = self._sock.send(data)
BrokenPipeError: [Errno 32] Broken pipe
2025-05-08 17:26:41,356 INFO    MainThread:48740 [wandb_init.py:_post_run_cell_hook():613] [no run ID] resuming backend
2025-05-08 17:26:41,357 ERROR   MainThread:48740 [redirect.py:_on_write():664] [no run ID] error in stdout callback
Traceback (most recent call last):
  File "/opt/miniconda3/envs/lpn_py310/lib/python3.10/site-packages/IPython/core/events.py", line 82, in trigger
    func(*args, **kwargs)
  File "/opt/miniconda3/envs/lpn_py310/lib/python3.10/site-packages/wandb/sdk/wandb_init.py", line 614, in _post_run_cell_hook
    self.backend.interface.publish_resume()
  File "/opt/miniconda3/envs/lpn_py310/lib/python3.10/site-packages/wandb/sdk/interface/interface.py", line 779, in publish_resume
    self._publish_resume(resume)
  File "/opt/miniconda3/envs/lpn_py310/lib/python3.10/site-packages/wandb/sdk/interface/interface_shared.py", line 293, in _publish_resume
    self._publish(rec)
  File "/opt/miniconda3/envs/lpn_py310/lib/python3.10/site-packages/wandb/sdk/interface/interface_sock.py", line 39, in _publish
    self._sock_client.send_record_publish(record)
  File "/opt/miniconda3/envs/lpn_py310/lib/python3.10/site-packages/wandb/sdk/lib/sock_client.py", line 174, in send_record_publish
    self.send_server_request(server_req)
  File "/opt/miniconda3/envs/lpn_py310/lib/python3.10/site-packages/wandb/sdk/lib/sock_client.py", line 154, in send_server_request
    self._send_message(msg)
  File "/opt/miniconda3/envs/lpn_py310/lib/python3.10/site-packages/wandb/sdk/lib/sock_client.py", line 151, in _send_message
    self._sendall_with_error_handle(header + data)
  File "/opt/miniconda3/envs/lpn_py310/lib/python3.10/site-packages/wandb/sdk/lib/sock_client.py", line 130, in _sendall_with_error_handle
    sent = self._sock.send(data)
BrokenPipeError: [Errno 32] Broken pipe

During handling of the above exception, another exception occurred:

Traceback (most recent call last):
  File "/opt/miniconda3/envs/lpn_py310/lib/python3.10/site-packages/wandb/sdk/lib/redirect.py", line 662, in _on_write
    cb(written_data)
  File "/opt/miniconda3/envs/lpn_py310/lib/python3.10/site-packages/wandb/sdk/wandb_run.py", line 2487, in <lambda>
    lambda data: self._console_raw_callback("stdout", data),
  File "/opt/miniconda3/envs/lpn_py310/lib/python3.10/site-packages/wandb/sdk/wandb_run.py", line 406, in wrapper
    return func(self, *args, **kwargs)
  File "/opt/miniconda3/envs/lpn_py310/lib/python3.10/site-packages/wandb/sdk/wandb_run.py", line 464, in wrapper_fn
    return func(self, *args, **kwargs)
  File "/opt/miniconda3/envs/lpn_py310/lib/python3.10/site-packages/wandb/sdk/wandb_run.py", line 1632, in _console_raw_callback
    self._backend.interface.publish_output_raw(name, data)
  File "/opt/miniconda3/envs/lpn_py310/lib/python3.10/site-packages/wandb/sdk/interface/interface.py", line 763, in publish_output_raw
    self._publish_output_raw(o)
  File "/opt/miniconda3/envs/lpn_py310/lib/python3.10/site-packages/wandb/sdk/interface/interface_shared.py", line 38, in _publish_output_raw
    self._publish(rec)
  File "/opt/miniconda3/envs/lpn_py310/lib/python3.10/site-packages/wandb/sdk/interface/interface_sock.py", line 39, in _publish
    self._sock_client.send_record_publish(record)
  File "/opt/miniconda3/envs/lpn_py310/lib/python3.10/site-packages/wandb/sdk/lib/sock_client.py", line 174, in send_record_publish
    self.send_server_request(server_req)
  File "/opt/miniconda3/envs/lpn_py310/lib/python3.10/site-packages/wandb/sdk/lib/sock_client.py", line 154, in send_server_request
    self._send_message(msg)
  File "/opt/miniconda3/envs/lpn_py310/lib/python3.10/site-packages/wandb/sdk/lib/sock_client.py", line 151, in _send_message
    self._sendall_with_error_handle(header + data)
  File "/opt/miniconda3/envs/lpn_py310/lib/python3.10/site-packages/wandb/sdk/lib/sock_client.py", line 130, in _sendall_with_error_handle
    sent = self._sock.send(data)
BrokenPipeError: [Errno 32] Broken pipe
2025-05-08 17:26:41,358 ERROR   MainThread:48740 [redirect.py:_on_write():664] [no run ID] error in stdout callback
Traceback (most recent call last):
  File "/opt/miniconda3/envs/lpn_py310/lib/python3.10/site-packages/IPython/core/events.py", line 82, in trigger
    func(*args, **kwargs)
  File "/opt/miniconda3/envs/lpn_py310/lib/python3.10/site-packages/wandb/sdk/wandb_init.py", line 614, in _post_run_cell_hook
    self.backend.interface.publish_resume()
  File "/opt/miniconda3/envs/lpn_py310/lib/python3.10/site-packages/wandb/sdk/interface/interface.py", line 779, in publish_resume
    self._publish_resume(resume)
  File "/opt/miniconda3/envs/lpn_py310/lib/python3.10/site-packages/wandb/sdk/interface/interface_shared.py", line 293, in _publish_resume
    self._publish(rec)
  File "/opt/miniconda3/envs/lpn_py310/lib/python3.10/site-packages/wandb/sdk/interface/interface_sock.py", line 39, in _publish
    self._sock_client.send_record_publish(record)
  File "/opt/miniconda3/envs/lpn_py310/lib/python3.10/site-packages/wandb/sdk/lib/sock_client.py", line 174, in send_record_publish
    self.send_server_request(server_req)
  File "/opt/miniconda3/envs/lpn_py310/lib/python3.10/site-packages/wandb/sdk/lib/sock_client.py", line 154, in send_server_request
    self._send_message(msg)
  File "/opt/miniconda3/envs/lpn_py310/lib/python3.10/site-packages/wandb/sdk/lib/sock_client.py", line 151, in _send_message
    self._sendall_with_error_handle(header + data)
  File "/opt/miniconda3/envs/lpn_py310/lib/python3.10/site-packages/wandb/sdk/lib/sock_client.py", line 130, in _sendall_with_error_handle
    sent = self._sock.send(data)
BrokenPipeError: [Errno 32] Broken pipe

During handling of the above exception, another exception occurred:

Traceback (most recent call last):
  File "/opt/miniconda3/envs/lpn_py310/lib/python3.10/site-packages/wandb/sdk/lib/redirect.py", line 662, in _on_write
    cb(written_data)
  File "/opt/miniconda3/envs/lpn_py310/lib/python3.10/site-packages/wandb/sdk/wandb_run.py", line 2487, in <lambda>
    lambda data: self._console_raw_callback("stdout", data),
  File "/opt/miniconda3/envs/lpn_py310/lib/python3.10/site-packages/wandb/sdk/wandb_run.py", line 406, in wrapper
    return func(self, *args, **kwargs)
  File "/opt/miniconda3/envs/lpn_py310/lib/python3.10/site-packages/wandb/sdk/wandb_run.py", line 464, in wrapper_fn
    return func(self, *args, **kwargs)
  File "/opt/miniconda3/envs/lpn_py310/lib/python3.10/site-packages/wandb/sdk/wandb_run.py", line 1632, in _console_raw_callback
    self._backend.interface.publish_output_raw(name, data)
  File "/opt/miniconda3/envs/lpn_py310/lib/python3.10/site-packages/wandb/sdk/interface/interface.py", line 763, in publish_output_raw
    self._publish_output_raw(o)
  File "/opt/miniconda3/envs/lpn_py310/lib/python3.10/site-packages/wandb/sdk/interface/interface_shared.py", line 38, in _publish_output_raw
    self._publish(rec)
  File "/opt/miniconda3/envs/lpn_py310/lib/python3.10/site-packages/wandb/sdk/interface/interface_sock.py", line 39, in _publish
    self._sock_client.send_record_publish(record)
  File "/opt/miniconda3/envs/lpn_py310/lib/python3.10/site-packages/wandb/sdk/lib/sock_client.py", line 174, in send_record_publish
    self.send_server_request(server_req)
  File "/opt/miniconda3/envs/lpn_py310/lib/python3.10/site-packages/wandb/sdk/lib/sock_client.py", line 154, in send_server_request
    self._send_message(msg)
  File "/opt/miniconda3/envs/lpn_py310/lib/python3.10/site-packages/wandb/sdk/lib/sock_client.py", line 151, in _send_message
    self._sendall_with_error_handle(header + data)
  File "/opt/miniconda3/envs/lpn_py310/lib/python3.10/site-packages/wandb/sdk/lib/sock_client.py", line 130, in _sendall_with_error_handle
    sent = self._sock.send(data)
BrokenPipeError: [Errno 32] Broken pipe
2025-05-08 17:26:41,506 INFO    MainThread:48740 [jupyter.py:save_ipynb():401] [no run ID] not saving jupyter notebook
2025-05-08 17:26:41,506 INFO    MainThread:48740 [wandb_init.py:_pre_run_cell_hook():602] [no run ID] pausing backend
2025-05-08 17:26:41,507 ERROR   MainThread:48740 [redirect.py:_on_write():664] [no run ID] error in stdout callback
Traceback (most recent call last):
  File "/opt/miniconda3/envs/lpn_py310/lib/python3.10/site-packages/IPython/core/events.py", line 82, in trigger
    func(*args, **kwargs)
  File "/opt/miniconda3/envs/lpn_py310/lib/python3.10/site-packages/wandb/sdk/wandb_init.py", line 603, in _pre_run_cell_hook
    self.backend.interface.publish_pause()
  File "/opt/miniconda3/envs/lpn_py310/lib/python3.10/site-packages/wandb/sdk/interface/interface.py", line 771, in publish_pause
    self._publish_pause(pause)
  File "/opt/miniconda3/envs/lpn_py310/lib/python3.10/site-packages/wandb/sdk/interface/interface_shared.py", line 289, in _publish_pause
    self._publish(rec)
  File "/opt/miniconda3/envs/lpn_py310/lib/python3.10/site-packages/wandb/sdk/interface/interface_sock.py", line 39, in _publish
    self._sock_client.send_record_publish(record)
  File "/opt/miniconda3/envs/lpn_py310/lib/python3.10/site-packages/wandb/sdk/lib/sock_client.py", line 174, in send_record_publish
    self.send_server_request(server_req)
  File "/opt/miniconda3/envs/lpn_py310/lib/python3.10/site-packages/wandb/sdk/lib/sock_client.py", line 154, in send_server_request
    self._send_message(msg)
  File "/opt/miniconda3/envs/lpn_py310/lib/python3.10/site-packages/wandb/sdk/lib/sock_client.py", line 151, in _send_message
    self._sendall_with_error_handle(header + data)
  File "/opt/miniconda3/envs/lpn_py310/lib/python3.10/site-packages/wandb/sdk/lib/sock_client.py", line 130, in _sendall_with_error_handle
    sent = self._sock.send(data)
BrokenPipeError: [Errno 32] Broken pipe

During handling of the above exception, another exception occurred:

Traceback (most recent call last):
  File "/opt/miniconda3/envs/lpn_py310/lib/python3.10/site-packages/wandb/sdk/lib/redirect.py", line 662, in _on_write
    cb(written_data)
  File "/opt/miniconda3/envs/lpn_py310/lib/python3.10/site-packages/wandb/sdk/wandb_run.py", line 2487, in <lambda>
    lambda data: self._console_raw_callback("stdout", data),
  File "/opt/miniconda3/envs/lpn_py310/lib/python3.10/site-packages/wandb/sdk/wandb_run.py", line 406, in wrapper
    return func(self, *args, **kwargs)
  File "/opt/miniconda3/envs/lpn_py310/lib/python3.10/site-packages/wandb/sdk/wandb_run.py", line 464, in wrapper_fn
    return func(self, *args, **kwargs)
  File "/opt/miniconda3/envs/lpn_py310/lib/python3.10/site-packages/wandb/sdk/wandb_run.py", line 1632, in _console_raw_callback
    self._backend.interface.publish_output_raw(name, data)
  File "/opt/miniconda3/envs/lpn_py310/lib/python3.10/site-packages/wandb/sdk/interface/interface.py", line 763, in publish_output_raw
    self._publish_output_raw(o)
  File "/opt/miniconda3/envs/lpn_py310/lib/python3.10/site-packages/wandb/sdk/interface/interface_shared.py", line 38, in _publish_output_raw
    self._publish(rec)
  File "/opt/miniconda3/envs/lpn_py310/lib/python3.10/site-packages/wandb/sdk/interface/interface_sock.py", line 39, in _publish
    self._sock_client.send_record_publish(record)
  File "/opt/miniconda3/envs/lpn_py310/lib/python3.10/site-packages/wandb/sdk/lib/sock_client.py", line 174, in send_record_publish
    self.send_server_request(server_req)
  File "/opt/miniconda3/envs/lpn_py310/lib/python3.10/site-packages/wandb/sdk/lib/sock_client.py", line 154, in send_server_request
    self._send_message(msg)
  File "/opt/miniconda3/envs/lpn_py310/lib/python3.10/site-packages/wandb/sdk/lib/sock_client.py", line 151, in _send_message
    self._sendall_with_error_handle(header + data)
  File "/opt/miniconda3/envs/lpn_py310/lib/python3.10/site-packages/wandb/sdk/lib/sock_client.py", line 130, in _sendall_with_error_handle
    sent = self._sock.send(data)
BrokenPipeError: [Errno 32] Broken pipe
2025-05-08 17:26:41,509 ERROR   MainThread:48740 [redirect.py:_on_write():664] [no run ID] error in stdout callback
Traceback (most recent call last):
  File "/opt/miniconda3/envs/lpn_py310/lib/python3.10/site-packages/IPython/core/events.py", line 82, in trigger
    func(*args, **kwargs)
  File "/opt/miniconda3/envs/lpn_py310/lib/python3.10/site-packages/wandb/sdk/wandb_init.py", line 603, in _pre_run_cell_hook
    self.backend.interface.publish_pause()
  File "/opt/miniconda3/envs/lpn_py310/lib/python3.10/site-packages/wandb/sdk/interface/interface.py", line 771, in publish_pause
    self._publish_pause(pause)
  File "/opt/miniconda3/envs/lpn_py310/lib/python3.10/site-packages/wandb/sdk/interface/interface_shared.py", line 289, in _publish_pause
    self._publish(rec)
  File "/opt/miniconda3/envs/lpn_py310/lib/python3.10/site-packages/wandb/sdk/interface/interface_sock.py", line 39, in _publish
    self._sock_client.send_record_publish(record)
  File "/opt/miniconda3/envs/lpn_py310/lib/python3.10/site-packages/wandb/sdk/lib/sock_client.py", line 174, in send_record_publish
    self.send_server_request(server_req)
  File "/opt/miniconda3/envs/lpn_py310/lib/python3.10/site-packages/wandb/sdk/lib/sock_client.py", line 154, in send_server_request
    self._send_message(msg)
  File "/opt/miniconda3/envs/lpn_py310/lib/python3.10/site-packages/wandb/sdk/lib/sock_client.py", line 151, in _send_message
    self._sendall_with_error_handle(header + data)
  File "/opt/miniconda3/envs/lpn_py310/lib/python3.10/site-packages/wandb/sdk/lib/sock_client.py", line 130, in _sendall_with_error_handle
    sent = self._sock.send(data)
BrokenPipeError: [Errno 32] Broken pipe

During handling of the above exception, another exception occurred:

Traceback (most recent call last):
  File "/opt/miniconda3/envs/lpn_py310/lib/python3.10/site-packages/wandb/sdk/lib/redirect.py", line 662, in _on_write
    cb(written_data)
  File "/opt/miniconda3/envs/lpn_py310/lib/python3.10/site-packages/wandb/sdk/wandb_run.py", line 2487, in <lambda>
    lambda data: self._console_raw_callback("stdout", data),
  File "/opt/miniconda3/envs/lpn_py310/lib/python3.10/site-packages/wandb/sdk/wandb_run.py", line 406, in wrapper
    return func(self, *args, **kwargs)
  File "/opt/miniconda3/envs/lpn_py310/lib/python3.10/site-packages/wandb/sdk/wandb_run.py", line 464, in wrapper_fn
    return func(self, *args, **kwargs)
  File "/opt/miniconda3/envs/lpn_py310/lib/python3.10/site-packages/wandb/sdk/wandb_run.py", line 1632, in _console_raw_callback
    self._backend.interface.publish_output_raw(name, data)
  File "/opt/miniconda3/envs/lpn_py310/lib/python3.10/site-packages/wandb/sdk/interface/interface.py", line 763, in publish_output_raw
    self._publish_output_raw(o)
  File "/opt/miniconda3/envs/lpn_py310/lib/python3.10/site-packages/wandb/sdk/interface/interface_shared.py", line 38, in _publish_output_raw
    self._publish(rec)
  File "/opt/miniconda3/envs/lpn_py310/lib/python3.10/site-packages/wandb/sdk/interface/interface_sock.py", line 39, in _publish
    self._sock_client.send_record_publish(record)
  File "/opt/miniconda3/envs/lpn_py310/lib/python3.10/site-packages/wandb/sdk/lib/sock_client.py", line 174, in send_record_publish
    self.send_server_request(server_req)
  File "/opt/miniconda3/envs/lpn_py310/lib/python3.10/site-packages/wandb/sdk/lib/sock_client.py", line 154, in send_server_request
    self._send_message(msg)
  File "/opt/miniconda3/envs/lpn_py310/lib/python3.10/site-packages/wandb/sdk/lib/sock_client.py", line 151, in _send_message
    self._sendall_with_error_handle(header + data)
  File "/opt/miniconda3/envs/lpn_py310/lib/python3.10/site-packages/wandb/sdk/lib/sock_client.py", line 130, in _sendall_with_error_handle
    sent = self._sock.send(data)
BrokenPipeError: [Errno 32] Broken pipe
2025-05-08 17:26:41,582 INFO    MainThread:48740 [wandb_init.py:_post_run_cell_hook():613] [no run ID] resuming backend
2025-05-08 17:26:41,583 ERROR   MainThread:48740 [redirect.py:_on_write():664] [no run ID] error in stdout callback
Traceback (most recent call last):
  File "/opt/miniconda3/envs/lpn_py310/lib/python3.10/site-packages/IPython/core/events.py", line 82, in trigger
    func(*args, **kwargs)
  File "/opt/miniconda3/envs/lpn_py310/lib/python3.10/site-packages/wandb/sdk/wandb_init.py", line 614, in _post_run_cell_hook
    self.backend.interface.publish_resume()
  File "/opt/miniconda3/envs/lpn_py310/lib/python3.10/site-packages/wandb/sdk/interface/interface.py", line 779, in publish_resume
    self._publish_resume(resume)
  File "/opt/miniconda3/envs/lpn_py310/lib/python3.10/site-packages/wandb/sdk/interface/interface_shared.py", line 293, in _publish_resume
    self._publish(rec)
  File "/opt/miniconda3/envs/lpn_py310/lib/python3.10/site-packages/wandb/sdk/interface/interface_sock.py", line 39, in _publish
    self._sock_client.send_record_publish(record)
  File "/opt/miniconda3/envs/lpn_py310/lib/python3.10/site-packages/wandb/sdk/lib/sock_client.py", line 174, in send_record_publish
    self.send_server_request(server_req)
  File "/opt/miniconda3/envs/lpn_py310/lib/python3.10/site-packages/wandb/sdk/lib/sock_client.py", line 154, in send_server_request
    self._send_message(msg)
  File "/opt/miniconda3/envs/lpn_py310/lib/python3.10/site-packages/wandb/sdk/lib/sock_client.py", line 151, in _send_message
    self._sendall_with_error_handle(header + data)
  File "/opt/miniconda3/envs/lpn_py310/lib/python3.10/site-packages/wandb/sdk/lib/sock_client.py", line 130, in _sendall_with_error_handle
    sent = self._sock.send(data)
BrokenPipeError: [Errno 32] Broken pipe

During handling of the above exception, another exception occurred:

Traceback (most recent call last):
  File "/opt/miniconda3/envs/lpn_py310/lib/python3.10/site-packages/wandb/sdk/lib/redirect.py", line 662, in _on_write
    cb(written_data)
  File "/opt/miniconda3/envs/lpn_py310/lib/python3.10/site-packages/wandb/sdk/wandb_run.py", line 2487, in <lambda>
    lambda data: self._console_raw_callback("stdout", data),
  File "/opt/miniconda3/envs/lpn_py310/lib/python3.10/site-packages/wandb/sdk/wandb_run.py", line 406, in wrapper
    return func(self, *args, **kwargs)
  File "/opt/miniconda3/envs/lpn_py310/lib/python3.10/site-packages/wandb/sdk/wandb_run.py", line 464, in wrapper_fn
    return func(self, *args, **kwargs)
  File "/opt/miniconda3/envs/lpn_py310/lib/python3.10/site-packages/wandb/sdk/wandb_run.py", line 1632, in _console_raw_callback
    self._backend.interface.publish_output_raw(name, data)
  File "/opt/miniconda3/envs/lpn_py310/lib/python3.10/site-packages/wandb/sdk/interface/interface.py", line 763, in publish_output_raw
    self._publish_output_raw(o)
  File "/opt/miniconda3/envs/lpn_py310/lib/python3.10/site-packages/wandb/sdk/interface/interface_shared.py", line 38, in _publish_output_raw
    self._publish(rec)
  File "/opt/miniconda3/envs/lpn_py310/lib/python3.10/site-packages/wandb/sdk/interface/interface_sock.py", line 39, in _publish
    self._sock_client.send_record_publish(record)
  File "/opt/miniconda3/envs/lpn_py310/lib/python3.10/site-packages/wandb/sdk/lib/sock_client.py", line 174, in send_record_publish
    self.send_server_request(server_req)
  File "/opt/miniconda3/envs/lpn_py310/lib/python3.10/site-packages/wandb/sdk/lib/sock_client.py", line 154, in send_server_request
    self._send_message(msg)
  File "/opt/miniconda3/envs/lpn_py310/lib/python3.10/site-packages/wandb/sdk/lib/sock_client.py", line 151, in _send_message
    self._sendall_with_error_handle(header + data)
  File "/opt/miniconda3/envs/lpn_py310/lib/python3.10/site-packages/wandb/sdk/lib/sock_client.py", line 130, in _sendall_with_error_handle
    sent = self._sock.send(data)
BrokenPipeError: [Errno 32] Broken pipe
2025-05-08 17:26:41,585 ERROR   MainThread:48740 [redirect.py:_on_write():664] [no run ID] error in stdout callback
Traceback (most recent call last):
  File "/opt/miniconda3/envs/lpn_py310/lib/python3.10/site-packages/IPython/core/events.py", line 82, in trigger
    func(*args, **kwargs)
  File "/opt/miniconda3/envs/lpn_py310/lib/python3.10/site-packages/wandb/sdk/wandb_init.py", line 614, in _post_run_cell_hook
    self.backend.interface.publish_resume()
  File "/opt/miniconda3/envs/lpn_py310/lib/python3.10/site-packages/wandb/sdk/interface/interface.py", line 779, in publish_resume
    self._publish_resume(resume)
  File "/opt/miniconda3/envs/lpn_py310/lib/python3.10/site-packages/wandb/sdk/interface/interface_shared.py", line 293, in _publish_resume
    self._publish(rec)
  File "/opt/miniconda3/envs/lpn_py310/lib/python3.10/site-packages/wandb/sdk/interface/interface_sock.py", line 39, in _publish
    self._sock_client.send_record_publish(record)
  File "/opt/miniconda3/envs/lpn_py310/lib/python3.10/site-packages/wandb/sdk/lib/sock_client.py", line 174, in send_record_publish
    self.send_server_request(server_req)
  File "/opt/miniconda3/envs/lpn_py310/lib/python3.10/site-packages/wandb/sdk/lib/sock_client.py", line 154, in send_server_request
    self._send_message(msg)
  File "/opt/miniconda3/envs/lpn_py310/lib/python3.10/site-packages/wandb/sdk/lib/sock_client.py", line 151, in _send_message
    self._sendall_with_error_handle(header + data)
  File "/opt/miniconda3/envs/lpn_py310/lib/python3.10/site-packages/wandb/sdk/lib/sock_client.py", line 130, in _sendall_with_error_handle
    sent = self._sock.send(data)
BrokenPipeError: [Errno 32] Broken pipe

During handling of the above exception, another exception occurred:

Traceback (most recent call last):
  File "/opt/miniconda3/envs/lpn_py310/lib/python3.10/site-packages/wandb/sdk/lib/redirect.py", line 662, in _on_write
    cb(written_data)
  File "/opt/miniconda3/envs/lpn_py310/lib/python3.10/site-packages/wandb/sdk/wandb_run.py", line 2487, in <lambda>
    lambda data: self._console_raw_callback("stdout", data),
  File "/opt/miniconda3/envs/lpn_py310/lib/python3.10/site-packages/wandb/sdk/wandb_run.py", line 406, in wrapper
    return func(self, *args, **kwargs)
  File "/opt/miniconda3/envs/lpn_py310/lib/python3.10/site-packages/wandb/sdk/wandb_run.py", line 464, in wrapper_fn
    return func(self, *args, **kwargs)
  File "/opt/miniconda3/envs/lpn_py310/lib/python3.10/site-packages/wandb/sdk/wandb_run.py", line 1632, in _console_raw_callback
    self._backend.interface.publish_output_raw(name, data)
  File "/opt/miniconda3/envs/lpn_py310/lib/python3.10/site-packages/wandb/sdk/interface/interface.py", line 763, in publish_output_raw
    self._publish_output_raw(o)
  File "/opt/miniconda3/envs/lpn_py310/lib/python3.10/site-packages/wandb/sdk/interface/interface_shared.py", line 38, in _publish_output_raw
    self._publish(rec)
  File "/opt/miniconda3/envs/lpn_py310/lib/python3.10/site-packages/wandb/sdk/interface/interface_sock.py", line 39, in _publish
    self._sock_client.send_record_publish(record)
  File "/opt/miniconda3/envs/lpn_py310/lib/python3.10/site-packages/wandb/sdk/lib/sock_client.py", line 174, in send_record_publish
    self.send_server_request(server_req)
  File "/opt/miniconda3/envs/lpn_py310/lib/python3.10/site-packages/wandb/sdk/lib/sock_client.py", line 154, in send_server_request
    self._send_message(msg)
  File "/opt/miniconda3/envs/lpn_py310/lib/python3.10/site-packages/wandb/sdk/lib/sock_client.py", line 151, in _send_message
    self._sendall_with_error_handle(header + data)
  File "/opt/miniconda3/envs/lpn_py310/lib/python3.10/site-packages/wandb/sdk/lib/sock_client.py", line 130, in _sendall_with_error_handle
    sent = self._sock.send(data)
BrokenPipeError: [Errno 32] Broken pipe
2025-05-08 17:26:41,670 INFO    MainThread:48740 [jupyter.py:save_ipynb():401] [no run ID] not saving jupyter notebook
2025-05-08 17:26:41,670 INFO    MainThread:48740 [wandb_init.py:_pre_run_cell_hook():602] [no run ID] pausing backend
2025-05-08 17:26:41,673 ERROR   MainThread:48740 [redirect.py:_on_write():664] [no run ID] error in stdout callback
Traceback (most recent call last):
  File "/opt/miniconda3/envs/lpn_py310/lib/python3.10/site-packages/IPython/core/events.py", line 82, in trigger
    func(*args, **kwargs)
  File "/opt/miniconda3/envs/lpn_py310/lib/python3.10/site-packages/wandb/sdk/wandb_init.py", line 603, in _pre_run_cell_hook
    self.backend.interface.publish_pause()
  File "/opt/miniconda3/envs/lpn_py310/lib/python3.10/site-packages/wandb/sdk/interface/interface.py", line 771, in publish_pause
    self._publish_pause(pause)
  File "/opt/miniconda3/envs/lpn_py310/lib/python3.10/site-packages/wandb/sdk/interface/interface_shared.py", line 289, in _publish_pause
    self._publish(rec)
  File "/opt/miniconda3/envs/lpn_py310/lib/python3.10/site-packages/wandb/sdk/interface/interface_sock.py", line 39, in _publish
    self._sock_client.send_record_publish(record)
  File "/opt/miniconda3/envs/lpn_py310/lib/python3.10/site-packages/wandb/sdk/lib/sock_client.py", line 174, in send_record_publish
    self.send_server_request(server_req)
  File "/opt/miniconda3/envs/lpn_py310/lib/python3.10/site-packages/wandb/sdk/lib/sock_client.py", line 154, in send_server_request
    self._send_message(msg)
  File "/opt/miniconda3/envs/lpn_py310/lib/python3.10/site-packages/wandb/sdk/lib/sock_client.py", line 151, in _send_message
    self._sendall_with_error_handle(header + data)
  File "/opt/miniconda3/envs/lpn_py310/lib/python3.10/site-packages/wandb/sdk/lib/sock_client.py", line 130, in _sendall_with_error_handle
    sent = self._sock.send(data)
BrokenPipeError: [Errno 32] Broken pipe

During handling of the above exception, another exception occurred:

Traceback (most recent call last):
  File "/opt/miniconda3/envs/lpn_py310/lib/python3.10/site-packages/wandb/sdk/lib/redirect.py", line 662, in _on_write
    cb(written_data)
  File "/opt/miniconda3/envs/lpn_py310/lib/python3.10/site-packages/wandb/sdk/wandb_run.py", line 2487, in <lambda>
    lambda data: self._console_raw_callback("stdout", data),
  File "/opt/miniconda3/envs/lpn_py310/lib/python3.10/site-packages/wandb/sdk/wandb_run.py", line 406, in wrapper
    return func(self, *args, **kwargs)
  File "/opt/miniconda3/envs/lpn_py310/lib/python3.10/site-packages/wandb/sdk/wandb_run.py", line 464, in wrapper_fn
    return func(self, *args, **kwargs)
  File "/opt/miniconda3/envs/lpn_py310/lib/python3.10/site-packages/wandb/sdk/wandb_run.py", line 1632, in _console_raw_callback
    self._backend.interface.publish_output_raw(name, data)
  File "/opt/miniconda3/envs/lpn_py310/lib/python3.10/site-packages/wandb/sdk/interface/interface.py", line 763, in publish_output_raw
    self._publish_output_raw(o)
  File "/opt/miniconda3/envs/lpn_py310/lib/python3.10/site-packages/wandb/sdk/interface/interface_shared.py", line 38, in _publish_output_raw
    self._publish(rec)
  File "/opt/miniconda3/envs/lpn_py310/lib/python3.10/site-packages/wandb/sdk/interface/interface_sock.py", line 39, in _publish
    self._sock_client.send_record_publish(record)
  File "/opt/miniconda3/envs/lpn_py310/lib/python3.10/site-packages/wandb/sdk/lib/sock_client.py", line 174, in send_record_publish
    self.send_server_request(server_req)
  File "/opt/miniconda3/envs/lpn_py310/lib/python3.10/site-packages/wandb/sdk/lib/sock_client.py", line 154, in send_server_request
    self._send_message(msg)
  File "/opt/miniconda3/envs/lpn_py310/lib/python3.10/site-packages/wandb/sdk/lib/sock_client.py", line 151, in _send_message
    self._sendall_with_error_handle(header + data)
  File "/opt/miniconda3/envs/lpn_py310/lib/python3.10/site-packages/wandb/sdk/lib/sock_client.py", line 130, in _sendall_with_error_handle
    sent = self._sock.send(data)
BrokenPipeError: [Errno 32] Broken pipe
2025-05-08 17:26:41,675 ERROR   MainThread:48740 [redirect.py:_on_write():664] [no run ID] error in stdout callback
Traceback (most recent call last):
  File "/opt/miniconda3/envs/lpn_py310/lib/python3.10/site-packages/IPython/core/events.py", line 82, in trigger
    func(*args, **kwargs)
  File "/opt/miniconda3/envs/lpn_py310/lib/python3.10/site-packages/wandb/sdk/wandb_init.py", line 603, in _pre_run_cell_hook
    self.backend.interface.publish_pause()
  File "/opt/miniconda3/envs/lpn_py310/lib/python3.10/site-packages/wandb/sdk/interface/interface.py", line 771, in publish_pause
    self._publish_pause(pause)
  File "/opt/miniconda3/envs/lpn_py310/lib/python3.10/site-packages/wandb/sdk/interface/interface_shared.py", line 289, in _publish_pause
    self._publish(rec)
  File "/opt/miniconda3/envs/lpn_py310/lib/python3.10/site-packages/wandb/sdk/interface/interface_sock.py", line 39, in _publish
    self._sock_client.send_record_publish(record)
  File "/opt/miniconda3/envs/lpn_py310/lib/python3.10/site-packages/wandb/sdk/lib/sock_client.py", line 174, in send_record_publish
    self.send_server_request(server_req)
  File "/opt/miniconda3/envs/lpn_py310/lib/python3.10/site-packages/wandb/sdk/lib/sock_client.py", line 154, in send_server_request
    self._send_message(msg)
  File "/opt/miniconda3/envs/lpn_py310/lib/python3.10/site-packages/wandb/sdk/lib/sock_client.py", line 151, in _send_message
    self._sendall_with_error_handle(header + data)
  File "/opt/miniconda3/envs/lpn_py310/lib/python3.10/site-packages/wandb/sdk/lib/sock_client.py", line 130, in _sendall_with_error_handle
    sent = self._sock.send(data)
BrokenPipeError: [Errno 32] Broken pipe

During handling of the above exception, another exception occurred:

Traceback (most recent call last):
  File "/opt/miniconda3/envs/lpn_py310/lib/python3.10/site-packages/wandb/sdk/lib/redirect.py", line 662, in _on_write
    cb(written_data)
  File "/opt/miniconda3/envs/lpn_py310/lib/python3.10/site-packages/wandb/sdk/wandb_run.py", line 2487, in <lambda>
    lambda data: self._console_raw_callback("stdout", data),
  File "/opt/miniconda3/envs/lpn_py310/lib/python3.10/site-packages/wandb/sdk/wandb_run.py", line 406, in wrapper
    return func(self, *args, **kwargs)
  File "/opt/miniconda3/envs/lpn_py310/lib/python3.10/site-packages/wandb/sdk/wandb_run.py", line 464, in wrapper_fn
    return func(self, *args, **kwargs)
  File "/opt/miniconda3/envs/lpn_py310/lib/python3.10/site-packages/wandb/sdk/wandb_run.py", line 1632, in _console_raw_callback
    self._backend.interface.publish_output_raw(name, data)
  File "/opt/miniconda3/envs/lpn_py310/lib/python3.10/site-packages/wandb/sdk/interface/interface.py", line 763, in publish_output_raw
    self._publish_output_raw(o)
  File "/opt/miniconda3/envs/lpn_py310/lib/python3.10/site-packages/wandb/sdk/interface/interface_shared.py", line 38, in _publish_output_raw
    self._publish(rec)
  File "/opt/miniconda3/envs/lpn_py310/lib/python3.10/site-packages/wandb/sdk/interface/interface_sock.py", line 39, in _publish
    self._sock_client.send_record_publish(record)
  File "/opt/miniconda3/envs/lpn_py310/lib/python3.10/site-packages/wandb/sdk/lib/sock_client.py", line 174, in send_record_publish
    self.send_server_request(server_req)
  File "/opt/miniconda3/envs/lpn_py310/lib/python3.10/site-packages/wandb/sdk/lib/sock_client.py", line 154, in send_server_request
    self._send_message(msg)
  File "/opt/miniconda3/envs/lpn_py310/lib/python3.10/site-packages/wandb/sdk/lib/sock_client.py", line 151, in _send_message
    self._sendall_with_error_handle(header + data)
  File "/opt/miniconda3/envs/lpn_py310/lib/python3.10/site-packages/wandb/sdk/lib/sock_client.py", line 130, in _sendall_with_error_handle
    sent = self._sock.send(data)
BrokenPipeError: [Errno 32] Broken pipe
2025-05-08 17:26:41,804 INFO    MainThread:48740 [wandb_init.py:_post_run_cell_hook():613] [no run ID] resuming backend
2025-05-08 17:26:41,805 ERROR   MainThread:48740 [redirect.py:_on_write():664] [no run ID] error in stdout callback
Traceback (most recent call last):
  File "/opt/miniconda3/envs/lpn_py310/lib/python3.10/site-packages/IPython/core/events.py", line 82, in trigger
    func(*args, **kwargs)
  File "/opt/miniconda3/envs/lpn_py310/lib/python3.10/site-packages/wandb/sdk/wandb_init.py", line 614, in _post_run_cell_hook
    self.backend.interface.publish_resume()
  File "/opt/miniconda3/envs/lpn_py310/lib/python3.10/site-packages/wandb/sdk/interface/interface.py", line 779, in publish_resume
    self._publish_resume(resume)
  File "/opt/miniconda3/envs/lpn_py310/lib/python3.10/site-packages/wandb/sdk/interface/interface_shared.py", line 293, in _publish_resume
    self._publish(rec)
  File "/opt/miniconda3/envs/lpn_py310/lib/python3.10/site-packages/wandb/sdk/interface/interface_sock.py", line 39, in _publish
    self._sock_client.send_record_publish(record)
  File "/opt/miniconda3/envs/lpn_py310/lib/python3.10/site-packages/wandb/sdk/lib/sock_client.py", line 174, in send_record_publish
    self.send_server_request(server_req)
  File "/opt/miniconda3/envs/lpn_py310/lib/python3.10/site-packages/wandb/sdk/lib/sock_client.py", line 154, in send_server_request
    self._send_message(msg)
  File "/opt/miniconda3/envs/lpn_py310/lib/python3.10/site-packages/wandb/sdk/lib/sock_client.py", line 151, in _send_message
    self._sendall_with_error_handle(header + data)
  File "/opt/miniconda3/envs/lpn_py310/lib/python3.10/site-packages/wandb/sdk/lib/sock_client.py", line 130, in _sendall_with_error_handle
    sent = self._sock.send(data)
BrokenPipeError: [Errno 32] Broken pipe

During handling of the above exception, another exception occurred:

Traceback (most recent call last):
  File "/opt/miniconda3/envs/lpn_py310/lib/python3.10/site-packages/wandb/sdk/lib/redirect.py", line 662, in _on_write
    cb(written_data)
  File "/opt/miniconda3/envs/lpn_py310/lib/python3.10/site-packages/wandb/sdk/wandb_run.py", line 2487, in <lambda>
    lambda data: self._console_raw_callback("stdout", data),
  File "/opt/miniconda3/envs/lpn_py310/lib/python3.10/site-packages/wandb/sdk/wandb_run.py", line 406, in wrapper
    return func(self, *args, **kwargs)
  File "/opt/miniconda3/envs/lpn_py310/lib/python3.10/site-packages/wandb/sdk/wandb_run.py", line 464, in wrapper_fn
    return func(self, *args, **kwargs)
  File "/opt/miniconda3/envs/lpn_py310/lib/python3.10/site-packages/wandb/sdk/wandb_run.py", line 1632, in _console_raw_callback
    self._backend.interface.publish_output_raw(name, data)
  File "/opt/miniconda3/envs/lpn_py310/lib/python3.10/site-packages/wandb/sdk/interface/interface.py", line 763, in publish_output_raw
    self._publish_output_raw(o)
  File "/opt/miniconda3/envs/lpn_py310/lib/python3.10/site-packages/wandb/sdk/interface/interface_shared.py", line 38, in _publish_output_raw
    self._publish(rec)
  File "/opt/miniconda3/envs/lpn_py310/lib/python3.10/site-packages/wandb/sdk/interface/interface_sock.py", line 39, in _publish
    self._sock_client.send_record_publish(record)
  File "/opt/miniconda3/envs/lpn_py310/lib/python3.10/site-packages/wandb/sdk/lib/sock_client.py", line 174, in send_record_publish
    self.send_server_request(server_req)
  File "/opt/miniconda3/envs/lpn_py310/lib/python3.10/site-packages/wandb/sdk/lib/sock_client.py", line 154, in send_server_request
    self._send_message(msg)
  File "/opt/miniconda3/envs/lpn_py310/lib/python3.10/site-packages/wandb/sdk/lib/sock_client.py", line 151, in _send_message
    self._sendall_with_error_handle(header + data)
  File "/opt/miniconda3/envs/lpn_py310/lib/python3.10/site-packages/wandb/sdk/lib/sock_client.py", line 130, in _sendall_with_error_handle
    sent = self._sock.send(data)
BrokenPipeError: [Errno 32] Broken pipe
2025-05-08 17:26:41,807 ERROR   MainThread:48740 [redirect.py:_on_write():664] [no run ID] error in stdout callback
Traceback (most recent call last):
  File "/opt/miniconda3/envs/lpn_py310/lib/python3.10/site-packages/IPython/core/events.py", line 82, in trigger
    func(*args, **kwargs)
  File "/opt/miniconda3/envs/lpn_py310/lib/python3.10/site-packages/wandb/sdk/wandb_init.py", line 614, in _post_run_cell_hook
    self.backend.interface.publish_resume()
  File "/opt/miniconda3/envs/lpn_py310/lib/python3.10/site-packages/wandb/sdk/interface/interface.py", line 779, in publish_resume
    self._publish_resume(resume)
  File "/opt/miniconda3/envs/lpn_py310/lib/python3.10/site-packages/wandb/sdk/interface/interface_shared.py", line 293, in _publish_resume
    self._publish(rec)
  File "/opt/miniconda3/envs/lpn_py310/lib/python3.10/site-packages/wandb/sdk/interface/interface_sock.py", line 39, in _publish
    self._sock_client.send_record_publish(record)
  File "/opt/miniconda3/envs/lpn_py310/lib/python3.10/site-packages/wandb/sdk/lib/sock_client.py", line 174, in send_record_publish
    self.send_server_request(server_req)
  File "/opt/miniconda3/envs/lpn_py310/lib/python3.10/site-packages/wandb/sdk/lib/sock_client.py", line 154, in send_server_request
    self._send_message(msg)
  File "/opt/miniconda3/envs/lpn_py310/lib/python3.10/site-packages/wandb/sdk/lib/sock_client.py", line 151, in _send_message
    self._sendall_with_error_handle(header + data)
  File "/opt/miniconda3/envs/lpn_py310/lib/python3.10/site-packages/wandb/sdk/lib/sock_client.py", line 130, in _sendall_with_error_handle
    sent = self._sock.send(data)
BrokenPipeError: [Errno 32] Broken pipe

During handling of the above exception, another exception occurred:

Traceback (most recent call last):
  File "/opt/miniconda3/envs/lpn_py310/lib/python3.10/site-packages/wandb/sdk/lib/redirect.py", line 662, in _on_write
    cb(written_data)
  File "/opt/miniconda3/envs/lpn_py310/lib/python3.10/site-packages/wandb/sdk/wandb_run.py", line 2487, in <lambda>
    lambda data: self._console_raw_callback("stdout", data),
  File "/opt/miniconda3/envs/lpn_py310/lib/python3.10/site-packages/wandb/sdk/wandb_run.py", line 406, in wrapper
    return func(self, *args, **kwargs)
  File "/opt/miniconda3/envs/lpn_py310/lib/python3.10/site-packages/wandb/sdk/wandb_run.py", line 464, in wrapper_fn
    return func(self, *args, **kwargs)
  File "/opt/miniconda3/envs/lpn_py310/lib/python3.10/site-packages/wandb/sdk/wandb_run.py", line 1632, in _console_raw_callback
    self._backend.interface.publish_output_raw(name, data)
  File "/opt/miniconda3/envs/lpn_py310/lib/python3.10/site-packages/wandb/sdk/interface/interface.py", line 763, in publish_output_raw
    self._publish_output_raw(o)
  File "/opt/miniconda3/envs/lpn_py310/lib/python3.10/site-packages/wandb/sdk/interface/interface_shared.py", line 38, in _publish_output_raw
    self._publish(rec)
  File "/opt/miniconda3/envs/lpn_py310/lib/python3.10/site-packages/wandb/sdk/interface/interface_sock.py", line 39, in _publish
    self._sock_client.send_record_publish(record)
  File "/opt/miniconda3/envs/lpn_py310/lib/python3.10/site-packages/wandb/sdk/lib/sock_client.py", line 174, in send_record_publish
    self.send_server_request(server_req)
  File "/opt/miniconda3/envs/lpn_py310/lib/python3.10/site-packages/wandb/sdk/lib/sock_client.py", line 154, in send_server_request
    self._send_message(msg)
  File "/opt/miniconda3/envs/lpn_py310/lib/python3.10/site-packages/wandb/sdk/lib/sock_client.py", line 151, in _send_message
    self._sendall_with_error_handle(header + data)
  File "/opt/miniconda3/envs/lpn_py310/lib/python3.10/site-packages/wandb/sdk/lib/sock_client.py", line 130, in _sendall_with_error_handle
    sent = self._sock.send(data)
BrokenPipeError: [Errno 32] Broken pipe
2025-05-08 17:26:41,963 INFO    MainThread:48740 [jupyter.py:save_ipynb():401] [no run ID] not saving jupyter notebook
2025-05-08 17:26:41,963 INFO    MainThread:48740 [wandb_init.py:_pre_run_cell_hook():602] [no run ID] pausing backend
2025-05-08 17:26:41,964 ERROR   MainThread:48740 [redirect.py:_on_write():664] [no run ID] error in stdout callback
Traceback (most recent call last):
  File "/opt/miniconda3/envs/lpn_py310/lib/python3.10/site-packages/IPython/core/events.py", line 82, in trigger
    func(*args, **kwargs)
  File "/opt/miniconda3/envs/lpn_py310/lib/python3.10/site-packages/wandb/sdk/wandb_init.py", line 603, in _pre_run_cell_hook
    self.backend.interface.publish_pause()
  File "/opt/miniconda3/envs/lpn_py310/lib/python3.10/site-packages/wandb/sdk/interface/interface.py", line 771, in publish_pause
    self._publish_pause(pause)
  File "/opt/miniconda3/envs/lpn_py310/lib/python3.10/site-packages/wandb/sdk/interface/interface_shared.py", line 289, in _publish_pause
    self._publish(rec)
  File "/opt/miniconda3/envs/lpn_py310/lib/python3.10/site-packages/wandb/sdk/interface/interface_sock.py", line 39, in _publish
    self._sock_client.send_record_publish(record)
  File "/opt/miniconda3/envs/lpn_py310/lib/python3.10/site-packages/wandb/sdk/lib/sock_client.py", line 174, in send_record_publish
    self.send_server_request(server_req)
  File "/opt/miniconda3/envs/lpn_py310/lib/python3.10/site-packages/wandb/sdk/lib/sock_client.py", line 154, in send_server_request
    self._send_message(msg)
  File "/opt/miniconda3/envs/lpn_py310/lib/python3.10/site-packages/wandb/sdk/lib/sock_client.py", line 151, in _send_message
    self._sendall_with_error_handle(header + data)
  File "/opt/miniconda3/envs/lpn_py310/lib/python3.10/site-packages/wandb/sdk/lib/sock_client.py", line 130, in _sendall_with_error_handle
    sent = self._sock.send(data)
BrokenPipeError: [Errno 32] Broken pipe

During handling of the above exception, another exception occurred:

Traceback (most recent call last):
  File "/opt/miniconda3/envs/lpn_py310/lib/python3.10/site-packages/wandb/sdk/lib/redirect.py", line 662, in _on_write
    cb(written_data)
  File "/opt/miniconda3/envs/lpn_py310/lib/python3.10/site-packages/wandb/sdk/wandb_run.py", line 2487, in <lambda>
    lambda data: self._console_raw_callback("stdout", data),
  File "/opt/miniconda3/envs/lpn_py310/lib/python3.10/site-packages/wandb/sdk/wandb_run.py", line 406, in wrapper
    return func(self, *args, **kwargs)
  File "/opt/miniconda3/envs/lpn_py310/lib/python3.10/site-packages/wandb/sdk/wandb_run.py", line 464, in wrapper_fn
    return func(self, *args, **kwargs)
  File "/opt/miniconda3/envs/lpn_py310/lib/python3.10/site-packages/wandb/sdk/wandb_run.py", line 1632, in _console_raw_callback
    self._backend.interface.publish_output_raw(name, data)
  File "/opt/miniconda3/envs/lpn_py310/lib/python3.10/site-packages/wandb/sdk/interface/interface.py", line 763, in publish_output_raw
    self._publish_output_raw(o)
  File "/opt/miniconda3/envs/lpn_py310/lib/python3.10/site-packages/wandb/sdk/interface/interface_shared.py", line 38, in _publish_output_raw
    self._publish(rec)
  File "/opt/miniconda3/envs/lpn_py310/lib/python3.10/site-packages/wandb/sdk/interface/interface_sock.py", line 39, in _publish
    self._sock_client.send_record_publish(record)
  File "/opt/miniconda3/envs/lpn_py310/lib/python3.10/site-packages/wandb/sdk/lib/sock_client.py", line 174, in send_record_publish
    self.send_server_request(server_req)
  File "/opt/miniconda3/envs/lpn_py310/lib/python3.10/site-packages/wandb/sdk/lib/sock_client.py", line 154, in send_server_request
    self._send_message(msg)
  File "/opt/miniconda3/envs/lpn_py310/lib/python3.10/site-packages/wandb/sdk/lib/sock_client.py", line 151, in _send_message
    self._sendall_with_error_handle(header + data)
  File "/opt/miniconda3/envs/lpn_py310/lib/python3.10/site-packages/wandb/sdk/lib/sock_client.py", line 130, in _sendall_with_error_handle
    sent = self._sock.send(data)
BrokenPipeError: [Errno 32] Broken pipe
2025-05-08 17:26:41,966 ERROR   MainThread:48740 [redirect.py:_on_write():664] [no run ID] error in stdout callback
Traceback (most recent call last):
  File "/opt/miniconda3/envs/lpn_py310/lib/python3.10/site-packages/IPython/core/events.py", line 82, in trigger
    func(*args, **kwargs)
  File "/opt/miniconda3/envs/lpn_py310/lib/python3.10/site-packages/wandb/sdk/wandb_init.py", line 603, in _pre_run_cell_hook
    self.backend.interface.publish_pause()
  File "/opt/miniconda3/envs/lpn_py310/lib/python3.10/site-packages/wandb/sdk/interface/interface.py", line 771, in publish_pause
    self._publish_pause(pause)
  File "/opt/miniconda3/envs/lpn_py310/lib/python3.10/site-packages/wandb/sdk/interface/interface_shared.py", line 289, in _publish_pause
    self._publish(rec)
  File "/opt/miniconda3/envs/lpn_py310/lib/python3.10/site-packages/wandb/sdk/interface/interface_sock.py", line 39, in _publish
    self._sock_client.send_record_publish(record)
  File "/opt/miniconda3/envs/lpn_py310/lib/python3.10/site-packages/wandb/sdk/lib/sock_client.py", line 174, in send_record_publish
    self.send_server_request(server_req)
  File "/opt/miniconda3/envs/lpn_py310/lib/python3.10/site-packages/wandb/sdk/lib/sock_client.py", line 154, in send_server_request
    self._send_message(msg)
  File "/opt/miniconda3/envs/lpn_py310/lib/python3.10/site-packages/wandb/sdk/lib/sock_client.py", line 151, in _send_message
    self._sendall_with_error_handle(header + data)
  File "/opt/miniconda3/envs/lpn_py310/lib/python3.10/site-packages/wandb/sdk/lib/sock_client.py", line 130, in _sendall_with_error_handle
    sent = self._sock.send(data)
BrokenPipeError: [Errno 32] Broken pipe

During handling of the above exception, another exception occurred:

Traceback (most recent call last):
  File "/opt/miniconda3/envs/lpn_py310/lib/python3.10/site-packages/wandb/sdk/lib/redirect.py", line 662, in _on_write
    cb(written_data)
  File "/opt/miniconda3/envs/lpn_py310/lib/python3.10/site-packages/wandb/sdk/wandb_run.py", line 2487, in <lambda>
    lambda data: self._console_raw_callback("stdout", data),
  File "/opt/miniconda3/envs/lpn_py310/lib/python3.10/site-packages/wandb/sdk/wandb_run.py", line 406, in wrapper
    return func(self, *args, **kwargs)
  File "/opt/miniconda3/envs/lpn_py310/lib/python3.10/site-packages/wandb/sdk/wandb_run.py", line 464, in wrapper_fn
    return func(self, *args, **kwargs)
  File "/opt/miniconda3/envs/lpn_py310/lib/python3.10/site-packages/wandb/sdk/wandb_run.py", line 1632, in _console_raw_callback
    self._backend.interface.publish_output_raw(name, data)
  File "/opt/miniconda3/envs/lpn_py310/lib/python3.10/site-packages/wandb/sdk/interface/interface.py", line 763, in publish_output_raw
    self._publish_output_raw(o)
  File "/opt/miniconda3/envs/lpn_py310/lib/python3.10/site-packages/wandb/sdk/interface/interface_shared.py", line 38, in _publish_output_raw
    self._publish(rec)
  File "/opt/miniconda3/envs/lpn_py310/lib/python3.10/site-packages/wandb/sdk/interface/interface_sock.py", line 39, in _publish
    self._sock_client.send_record_publish(record)
  File "/opt/miniconda3/envs/lpn_py310/lib/python3.10/site-packages/wandb/sdk/lib/sock_client.py", line 174, in send_record_publish
    self.send_server_request(server_req)
  File "/opt/miniconda3/envs/lpn_py310/lib/python3.10/site-packages/wandb/sdk/lib/sock_client.py", line 154, in send_server_request
    self._send_message(msg)
  File "/opt/miniconda3/envs/lpn_py310/lib/python3.10/site-packages/wandb/sdk/lib/sock_client.py", line 151, in _send_message
    self._sendall_with_error_handle(header + data)
  File "/opt/miniconda3/envs/lpn_py310/lib/python3.10/site-packages/wandb/sdk/lib/sock_client.py", line 130, in _sendall_with_error_handle
    sent = self._sock.send(data)
BrokenPipeError: [Errno 32] Broken pipe
2025-05-08 17:26:42,049 INFO    MainThread:48740 [wandb_init.py:_post_run_cell_hook():613] [no run ID] resuming backend
2025-05-08 17:26:42,051 ERROR   MainThread:48740 [redirect.py:_on_write():664] [no run ID] error in stdout callback
Traceback (most recent call last):
  File "/opt/miniconda3/envs/lpn_py310/lib/python3.10/site-packages/IPython/core/events.py", line 82, in trigger
    func(*args, **kwargs)
  File "/opt/miniconda3/envs/lpn_py310/lib/python3.10/site-packages/wandb/sdk/wandb_init.py", line 614, in _post_run_cell_hook
    self.backend.interface.publish_resume()
  File "/opt/miniconda3/envs/lpn_py310/lib/python3.10/site-packages/wandb/sdk/interface/interface.py", line 779, in publish_resume
    self._publish_resume(resume)
  File "/opt/miniconda3/envs/lpn_py310/lib/python3.10/site-packages/wandb/sdk/interface/interface_shared.py", line 293, in _publish_resume
    self._publish(rec)
  File "/opt/miniconda3/envs/lpn_py310/lib/python3.10/site-packages/wandb/sdk/interface/interface_sock.py", line 39, in _publish
    self._sock_client.send_record_publish(record)
  File "/opt/miniconda3/envs/lpn_py310/lib/python3.10/site-packages/wandb/sdk/lib/sock_client.py", line 174, in send_record_publish
    self.send_server_request(server_req)
  File "/opt/miniconda3/envs/lpn_py310/lib/python3.10/site-packages/wandb/sdk/lib/sock_client.py", line 154, in send_server_request
    self._send_message(msg)
  File "/opt/miniconda3/envs/lpn_py310/lib/python3.10/site-packages/wandb/sdk/lib/sock_client.py", line 151, in _send_message
    self._sendall_with_error_handle(header + data)
  File "/opt/miniconda3/envs/lpn_py310/lib/python3.10/site-packages/wandb/sdk/lib/sock_client.py", line 130, in _sendall_with_error_handle
    sent = self._sock.send(data)
BrokenPipeError: [Errno 32] Broken pipe

During handling of the above exception, another exception occurred:

Traceback (most recent call last):
  File "/opt/miniconda3/envs/lpn_py310/lib/python3.10/site-packages/wandb/sdk/lib/redirect.py", line 662, in _on_write
    cb(written_data)
  File "/opt/miniconda3/envs/lpn_py310/lib/python3.10/site-packages/wandb/sdk/wandb_run.py", line 2487, in <lambda>
    lambda data: self._console_raw_callback("stdout", data),
  File "/opt/miniconda3/envs/lpn_py310/lib/python3.10/site-packages/wandb/sdk/wandb_run.py", line 406, in wrapper
    return func(self, *args, **kwargs)
  File "/opt/miniconda3/envs/lpn_py310/lib/python3.10/site-packages/wandb/sdk/wandb_run.py", line 464, in wrapper_fn
    return func(self, *args, **kwargs)
  File "/opt/miniconda3/envs/lpn_py310/lib/python3.10/site-packages/wandb/sdk/wandb_run.py", line 1632, in _console_raw_callback
    self._backend.interface.publish_output_raw(name, data)
  File "/opt/miniconda3/envs/lpn_py310/lib/python3.10/site-packages/wandb/sdk/interface/interface.py", line 763, in publish_output_raw
    self._publish_output_raw(o)
  File "/opt/miniconda3/envs/lpn_py310/lib/python3.10/site-packages/wandb/sdk/interface/interface_shared.py", line 38, in _publish_output_raw
    self._publish(rec)
  File "/opt/miniconda3/envs/lpn_py310/lib/python3.10/site-packages/wandb/sdk/interface/interface_sock.py", line 39, in _publish
    self._sock_client.send_record_publish(record)
  File "/opt/miniconda3/envs/lpn_py310/lib/python3.10/site-packages/wandb/sdk/lib/sock_client.py", line 174, in send_record_publish
    self.send_server_request(server_req)
  File "/opt/miniconda3/envs/lpn_py310/lib/python3.10/site-packages/wandb/sdk/lib/sock_client.py", line 154, in send_server_request
    self._send_message(msg)
  File "/opt/miniconda3/envs/lpn_py310/lib/python3.10/site-packages/wandb/sdk/lib/sock_client.py", line 151, in _send_message
    self._sendall_with_error_handle(header + data)
  File "/opt/miniconda3/envs/lpn_py310/lib/python3.10/site-packages/wandb/sdk/lib/sock_client.py", line 130, in _sendall_with_error_handle
    sent = self._sock.send(data)
BrokenPipeError: [Errno 32] Broken pipe
2025-05-08 17:26:42,052 ERROR   MainThread:48740 [redirect.py:_on_write():664] [no run ID] error in stdout callback
Traceback (most recent call last):
  File "/opt/miniconda3/envs/lpn_py310/lib/python3.10/site-packages/IPython/core/events.py", line 82, in trigger
    func(*args, **kwargs)
  File "/opt/miniconda3/envs/lpn_py310/lib/python3.10/site-packages/wandb/sdk/wandb_init.py", line 614, in _post_run_cell_hook
    self.backend.interface.publish_resume()
  File "/opt/miniconda3/envs/lpn_py310/lib/python3.10/site-packages/wandb/sdk/interface/interface.py", line 779, in publish_resume
    self._publish_resume(resume)
  File "/opt/miniconda3/envs/lpn_py310/lib/python3.10/site-packages/wandb/sdk/interface/interface_shared.py", line 293, in _publish_resume
    self._publish(rec)
  File "/opt/miniconda3/envs/lpn_py310/lib/python3.10/site-packages/wandb/sdk/interface/interface_sock.py", line 39, in _publish
    self._sock_client.send_record_publish(record)
  File "/opt/miniconda3/envs/lpn_py310/lib/python3.10/site-packages/wandb/sdk/lib/sock_client.py", line 174, in send_record_publish
    self.send_server_request(server_req)
  File "/opt/miniconda3/envs/lpn_py310/lib/python3.10/site-packages/wandb/sdk/lib/sock_client.py", line 154, in send_server_request
    self._send_message(msg)
  File "/opt/miniconda3/envs/lpn_py310/lib/python3.10/site-packages/wandb/sdk/lib/sock_client.py", line 151, in _send_message
    self._sendall_with_error_handle(header + data)
  File "/opt/miniconda3/envs/lpn_py310/lib/python3.10/site-packages/wandb/sdk/lib/sock_client.py", line 130, in _sendall_with_error_handle
    sent = self._sock.send(data)
BrokenPipeError: [Errno 32] Broken pipe

During handling of the above exception, another exception occurred:

Traceback (most recent call last):
  File "/opt/miniconda3/envs/lpn_py310/lib/python3.10/site-packages/wandb/sdk/lib/redirect.py", line 662, in _on_write
    cb(written_data)
  File "/opt/miniconda3/envs/lpn_py310/lib/python3.10/site-packages/wandb/sdk/wandb_run.py", line 2487, in <lambda>
    lambda data: self._console_raw_callback("stdout", data),
  File "/opt/miniconda3/envs/lpn_py310/lib/python3.10/site-packages/wandb/sdk/wandb_run.py", line 406, in wrapper
    return func(self, *args, **kwargs)
  File "/opt/miniconda3/envs/lpn_py310/lib/python3.10/site-packages/wandb/sdk/wandb_run.py", line 464, in wrapper_fn
    return func(self, *args, **kwargs)
  File "/opt/miniconda3/envs/lpn_py310/lib/python3.10/site-packages/wandb/sdk/wandb_run.py", line 1632, in _console_raw_callback
    self._backend.interface.publish_output_raw(name, data)
  File "/opt/miniconda3/envs/lpn_py310/lib/python3.10/site-packages/wandb/sdk/interface/interface.py", line 763, in publish_output_raw
    self._publish_output_raw(o)
  File "/opt/miniconda3/envs/lpn_py310/lib/python3.10/site-packages/wandb/sdk/interface/interface_shared.py", line 38, in _publish_output_raw
    self._publish(rec)
  File "/opt/miniconda3/envs/lpn_py310/lib/python3.10/site-packages/wandb/sdk/interface/interface_sock.py", line 39, in _publish
    self._sock_client.send_record_publish(record)
  File "/opt/miniconda3/envs/lpn_py310/lib/python3.10/site-packages/wandb/sdk/lib/sock_client.py", line 174, in send_record_publish
    self.send_server_request(server_req)
  File "/opt/miniconda3/envs/lpn_py310/lib/python3.10/site-packages/wandb/sdk/lib/sock_client.py", line 154, in send_server_request
    self._send_message(msg)
  File "/opt/miniconda3/envs/lpn_py310/lib/python3.10/site-packages/wandb/sdk/lib/sock_client.py", line 151, in _send_message
    self._sendall_with_error_handle(header + data)
  File "/opt/miniconda3/envs/lpn_py310/lib/python3.10/site-packages/wandb/sdk/lib/sock_client.py", line 130, in _sendall_with_error_handle
    sent = self._sock.send(data)
BrokenPipeError: [Errno 32] Broken pipe
2025-05-08 17:26:42,132 INFO    MainThread:48740 [jupyter.py:save_ipynb():401] [no run ID] not saving jupyter notebook
2025-05-08 17:26:42,132 INFO    MainThread:48740 [wandb_init.py:_pre_run_cell_hook():602] [no run ID] pausing backend
2025-05-08 17:26:42,133 ERROR   MainThread:48740 [redirect.py:_on_write():664] [no run ID] error in stdout callback
Traceback (most recent call last):
  File "/opt/miniconda3/envs/lpn_py310/lib/python3.10/site-packages/IPython/core/events.py", line 82, in trigger
    func(*args, **kwargs)
  File "/opt/miniconda3/envs/lpn_py310/lib/python3.10/site-packages/wandb/sdk/wandb_init.py", line 603, in _pre_run_cell_hook
    self.backend.interface.publish_pause()
  File "/opt/miniconda3/envs/lpn_py310/lib/python3.10/site-packages/wandb/sdk/interface/interface.py", line 771, in publish_pause
    self._publish_pause(pause)
  File "/opt/miniconda3/envs/lpn_py310/lib/python3.10/site-packages/wandb/sdk/interface/interface_shared.py", line 289, in _publish_pause
    self._publish(rec)
  File "/opt/miniconda3/envs/lpn_py310/lib/python3.10/site-packages/wandb/sdk/interface/interface_sock.py", line 39, in _publish
    self._sock_client.send_record_publish(record)
  File "/opt/miniconda3/envs/lpn_py310/lib/python3.10/site-packages/wandb/sdk/lib/sock_client.py", line 174, in send_record_publish
    self.send_server_request(server_req)
  File "/opt/miniconda3/envs/lpn_py310/lib/python3.10/site-packages/wandb/sdk/lib/sock_client.py", line 154, in send_server_request
    self._send_message(msg)
  File "/opt/miniconda3/envs/lpn_py310/lib/python3.10/site-packages/wandb/sdk/lib/sock_client.py", line 151, in _send_message
    self._sendall_with_error_handle(header + data)
  File "/opt/miniconda3/envs/lpn_py310/lib/python3.10/site-packages/wandb/sdk/lib/sock_client.py", line 130, in _sendall_with_error_handle
    sent = self._sock.send(data)
BrokenPipeError: [Errno 32] Broken pipe

During handling of the above exception, another exception occurred:

Traceback (most recent call last):
  File "/opt/miniconda3/envs/lpn_py310/lib/python3.10/site-packages/wandb/sdk/lib/redirect.py", line 662, in _on_write
    cb(written_data)
  File "/opt/miniconda3/envs/lpn_py310/lib/python3.10/site-packages/wandb/sdk/wandb_run.py", line 2487, in <lambda>
    lambda data: self._console_raw_callback("stdout", data),
  File "/opt/miniconda3/envs/lpn_py310/lib/python3.10/site-packages/wandb/sdk/wandb_run.py", line 406, in wrapper
    return func(self, *args, **kwargs)
  File "/opt/miniconda3/envs/lpn_py310/lib/python3.10/site-packages/wandb/sdk/wandb_run.py", line 464, in wrapper_fn
    return func(self, *args, **kwargs)
  File "/opt/miniconda3/envs/lpn_py310/lib/python3.10/site-packages/wandb/sdk/wandb_run.py", line 1632, in _console_raw_callback
    self._backend.interface.publish_output_raw(name, data)
  File "/opt/miniconda3/envs/lpn_py310/lib/python3.10/site-packages/wandb/sdk/interface/interface.py", line 763, in publish_output_raw
    self._publish_output_raw(o)
  File "/opt/miniconda3/envs/lpn_py310/lib/python3.10/site-packages/wandb/sdk/interface/interface_shared.py", line 38, in _publish_output_raw
    self._publish(rec)
  File "/opt/miniconda3/envs/lpn_py310/lib/python3.10/site-packages/wandb/sdk/interface/interface_sock.py", line 39, in _publish
    self._sock_client.send_record_publish(record)
  File "/opt/miniconda3/envs/lpn_py310/lib/python3.10/site-packages/wandb/sdk/lib/sock_client.py", line 174, in send_record_publish
    self.send_server_request(server_req)
  File "/opt/miniconda3/envs/lpn_py310/lib/python3.10/site-packages/wandb/sdk/lib/sock_client.py", line 154, in send_server_request
    self._send_message(msg)
  File "/opt/miniconda3/envs/lpn_py310/lib/python3.10/site-packages/wandb/sdk/lib/sock_client.py", line 151, in _send_message
    self._sendall_with_error_handle(header + data)
  File "/opt/miniconda3/envs/lpn_py310/lib/python3.10/site-packages/wandb/sdk/lib/sock_client.py", line 130, in _sendall_with_error_handle
    sent = self._sock.send(data)
BrokenPipeError: [Errno 32] Broken pipe
2025-05-08 17:26:42,135 ERROR   MainThread:48740 [redirect.py:_on_write():664] [no run ID] error in stdout callback
Traceback (most recent call last):
  File "/opt/miniconda3/envs/lpn_py310/lib/python3.10/site-packages/IPython/core/events.py", line 82, in trigger
    func(*args, **kwargs)
  File "/opt/miniconda3/envs/lpn_py310/lib/python3.10/site-packages/wandb/sdk/wandb_init.py", line 603, in _pre_run_cell_hook
    self.backend.interface.publish_pause()
  File "/opt/miniconda3/envs/lpn_py310/lib/python3.10/site-packages/wandb/sdk/interface/interface.py", line 771, in publish_pause
    self._publish_pause(pause)
  File "/opt/miniconda3/envs/lpn_py310/lib/python3.10/site-packages/wandb/sdk/interface/interface_shared.py", line 289, in _publish_pause
    self._publish(rec)
  File "/opt/miniconda3/envs/lpn_py310/lib/python3.10/site-packages/wandb/sdk/interface/interface_sock.py", line 39, in _publish
    self._sock_client.send_record_publish(record)
  File "/opt/miniconda3/envs/lpn_py310/lib/python3.10/site-packages/wandb/sdk/lib/sock_client.py", line 174, in send_record_publish
    self.send_server_request(server_req)
  File "/opt/miniconda3/envs/lpn_py310/lib/python3.10/site-packages/wandb/sdk/lib/sock_client.py", line 154, in send_server_request
    self._send_message(msg)
  File "/opt/miniconda3/envs/lpn_py310/lib/python3.10/site-packages/wandb/sdk/lib/sock_client.py", line 151, in _send_message
    self._sendall_with_error_handle(header + data)
  File "/opt/miniconda3/envs/lpn_py310/lib/python3.10/site-packages/wandb/sdk/lib/sock_client.py", line 130, in _sendall_with_error_handle
    sent = self._sock.send(data)
BrokenPipeError: [Errno 32] Broken pipe

During handling of the above exception, another exception occurred:

Traceback (most recent call last):
  File "/opt/miniconda3/envs/lpn_py310/lib/python3.10/site-packages/wandb/sdk/lib/redirect.py", line 662, in _on_write
    cb(written_data)
  File "/opt/miniconda3/envs/lpn_py310/lib/python3.10/site-packages/wandb/sdk/wandb_run.py", line 2487, in <lambda>
    lambda data: self._console_raw_callback("stdout", data),
  File "/opt/miniconda3/envs/lpn_py310/lib/python3.10/site-packages/wandb/sdk/wandb_run.py", line 406, in wrapper
    return func(self, *args, **kwargs)
  File "/opt/miniconda3/envs/lpn_py310/lib/python3.10/site-packages/wandb/sdk/wandb_run.py", line 464, in wrapper_fn
    return func(self, *args, **kwargs)
  File "/opt/miniconda3/envs/lpn_py310/lib/python3.10/site-packages/wandb/sdk/wandb_run.py", line 1632, in _console_raw_callback
    self._backend.interface.publish_output_raw(name, data)
  File "/opt/miniconda3/envs/lpn_py310/lib/python3.10/site-packages/wandb/sdk/interface/interface.py", line 763, in publish_output_raw
    self._publish_output_raw(o)
  File "/opt/miniconda3/envs/lpn_py310/lib/python3.10/site-packages/wandb/sdk/interface/interface_shared.py", line 38, in _publish_output_raw
    self._publish(rec)
  File "/opt/miniconda3/envs/lpn_py310/lib/python3.10/site-packages/wandb/sdk/interface/interface_sock.py", line 39, in _publish
    self._sock_client.send_record_publish(record)
  File "/opt/miniconda3/envs/lpn_py310/lib/python3.10/site-packages/wandb/sdk/lib/sock_client.py", line 174, in send_record_publish
    self.send_server_request(server_req)
  File "/opt/miniconda3/envs/lpn_py310/lib/python3.10/site-packages/wandb/sdk/lib/sock_client.py", line 154, in send_server_request
    self._send_message(msg)
  File "/opt/miniconda3/envs/lpn_py310/lib/python3.10/site-packages/wandb/sdk/lib/sock_client.py", line 151, in _send_message
    self._sendall_with_error_handle(header + data)
  File "/opt/miniconda3/envs/lpn_py310/lib/python3.10/site-packages/wandb/sdk/lib/sock_client.py", line 130, in _sendall_with_error_handle
    sent = self._sock.send(data)
BrokenPipeError: [Errno 32] Broken pipe
2025-05-08 17:26:42,241 INFO    MainThread:48740 [wandb_init.py:_post_run_cell_hook():613] [no run ID] resuming backend
2025-05-08 17:26:42,242 ERROR   MainThread:48740 [redirect.py:_on_write():664] [no run ID] error in stdout callback
Traceback (most recent call last):
  File "/opt/miniconda3/envs/lpn_py310/lib/python3.10/site-packages/IPython/core/events.py", line 82, in trigger
    func(*args, **kwargs)
  File "/opt/miniconda3/envs/lpn_py310/lib/python3.10/site-packages/wandb/sdk/wandb_init.py", line 614, in _post_run_cell_hook
    self.backend.interface.publish_resume()
  File "/opt/miniconda3/envs/lpn_py310/lib/python3.10/site-packages/wandb/sdk/interface/interface.py", line 779, in publish_resume
    self._publish_resume(resume)
  File "/opt/miniconda3/envs/lpn_py310/lib/python3.10/site-packages/wandb/sdk/interface/interface_shared.py", line 293, in _publish_resume
    self._publish(rec)
  File "/opt/miniconda3/envs/lpn_py310/lib/python3.10/site-packages/wandb/sdk/interface/interface_sock.py", line 39, in _publish
    self._sock_client.send_record_publish(record)
  File "/opt/miniconda3/envs/lpn_py310/lib/python3.10/site-packages/wandb/sdk/lib/sock_client.py", line 174, in send_record_publish
    self.send_server_request(server_req)
  File "/opt/miniconda3/envs/lpn_py310/lib/python3.10/site-packages/wandb/sdk/lib/sock_client.py", line 154, in send_server_request
    self._send_message(msg)
  File "/opt/miniconda3/envs/lpn_py310/lib/python3.10/site-packages/wandb/sdk/lib/sock_client.py", line 151, in _send_message
    self._sendall_with_error_handle(header + data)
  File "/opt/miniconda3/envs/lpn_py310/lib/python3.10/site-packages/wandb/sdk/lib/sock_client.py", line 130, in _sendall_with_error_handle
    sent = self._sock.send(data)
BrokenPipeError: [Errno 32] Broken pipe

During handling of the above exception, another exception occurred:

Traceback (most recent call last):
  File "/opt/miniconda3/envs/lpn_py310/lib/python3.10/site-packages/wandb/sdk/lib/redirect.py", line 662, in _on_write
    cb(written_data)
  File "/opt/miniconda3/envs/lpn_py310/lib/python3.10/site-packages/wandb/sdk/wandb_run.py", line 2487, in <lambda>
    lambda data: self._console_raw_callback("stdout", data),
  File "/opt/miniconda3/envs/lpn_py310/lib/python3.10/site-packages/wandb/sdk/wandb_run.py", line 406, in wrapper
    return func(self, *args, **kwargs)
  File "/opt/miniconda3/envs/lpn_py310/lib/python3.10/site-packages/wandb/sdk/wandb_run.py", line 464, in wrapper_fn
    return func(self, *args, **kwargs)
  File "/opt/miniconda3/envs/lpn_py310/lib/python3.10/site-packages/wandb/sdk/wandb_run.py", line 1632, in _console_raw_callback
    self._backend.interface.publish_output_raw(name, data)
  File "/opt/miniconda3/envs/lpn_py310/lib/python3.10/site-packages/wandb/sdk/interface/interface.py", line 763, in publish_output_raw
    self._publish_output_raw(o)
  File "/opt/miniconda3/envs/lpn_py310/lib/python3.10/site-packages/wandb/sdk/interface/interface_shared.py", line 38, in _publish_output_raw
    self._publish(rec)
  File "/opt/miniconda3/envs/lpn_py310/lib/python3.10/site-packages/wandb/sdk/interface/interface_sock.py", line 39, in _publish
    self._sock_client.send_record_publish(record)
  File "/opt/miniconda3/envs/lpn_py310/lib/python3.10/site-packages/wandb/sdk/lib/sock_client.py", line 174, in send_record_publish
    self.send_server_request(server_req)
  File "/opt/miniconda3/envs/lpn_py310/lib/python3.10/site-packages/wandb/sdk/lib/sock_client.py", line 154, in send_server_request
    self._send_message(msg)
  File "/opt/miniconda3/envs/lpn_py310/lib/python3.10/site-packages/wandb/sdk/lib/sock_client.py", line 151, in _send_message
    self._sendall_with_error_handle(header + data)
  File "/opt/miniconda3/envs/lpn_py310/lib/python3.10/site-packages/wandb/sdk/lib/sock_client.py", line 130, in _sendall_with_error_handle
    sent = self._sock.send(data)
BrokenPipeError: [Errno 32] Broken pipe
2025-05-08 17:26:42,243 ERROR   MainThread:48740 [redirect.py:_on_write():664] [no run ID] error in stdout callback
Traceback (most recent call last):
  File "/opt/miniconda3/envs/lpn_py310/lib/python3.10/site-packages/IPython/core/events.py", line 82, in trigger
    func(*args, **kwargs)
  File "/opt/miniconda3/envs/lpn_py310/lib/python3.10/site-packages/wandb/sdk/wandb_init.py", line 614, in _post_run_cell_hook
    self.backend.interface.publish_resume()
  File "/opt/miniconda3/envs/lpn_py310/lib/python3.10/site-packages/wandb/sdk/interface/interface.py", line 779, in publish_resume
    self._publish_resume(resume)
  File "/opt/miniconda3/envs/lpn_py310/lib/python3.10/site-packages/wandb/sdk/interface/interface_shared.py", line 293, in _publish_resume
    self._publish(rec)
  File "/opt/miniconda3/envs/lpn_py310/lib/python3.10/site-packages/wandb/sdk/interface/interface_sock.py", line 39, in _publish
    self._sock_client.send_record_publish(record)
  File "/opt/miniconda3/envs/lpn_py310/lib/python3.10/site-packages/wandb/sdk/lib/sock_client.py", line 174, in send_record_publish
    self.send_server_request(server_req)
  File "/opt/miniconda3/envs/lpn_py310/lib/python3.10/site-packages/wandb/sdk/lib/sock_client.py", line 154, in send_server_request
    self._send_message(msg)
  File "/opt/miniconda3/envs/lpn_py310/lib/python3.10/site-packages/wandb/sdk/lib/sock_client.py", line 151, in _send_message
    self._sendall_with_error_handle(header + data)
  File "/opt/miniconda3/envs/lpn_py310/lib/python3.10/site-packages/wandb/sdk/lib/sock_client.py", line 130, in _sendall_with_error_handle
    sent = self._sock.send(data)
BrokenPipeError: [Errno 32] Broken pipe

During handling of the above exception, another exception occurred:

Traceback (most recent call last):
  File "/opt/miniconda3/envs/lpn_py310/lib/python3.10/site-packages/wandb/sdk/lib/redirect.py", line 662, in _on_write
    cb(written_data)
  File "/opt/miniconda3/envs/lpn_py310/lib/python3.10/site-packages/wandb/sdk/wandb_run.py", line 2487, in <lambda>
    lambda data: self._console_raw_callback("stdout", data),
  File "/opt/miniconda3/envs/lpn_py310/lib/python3.10/site-packages/wandb/sdk/wandb_run.py", line 406, in wrapper
    return func(self, *args, **kwargs)
  File "/opt/miniconda3/envs/lpn_py310/lib/python3.10/site-packages/wandb/sdk/wandb_run.py", line 464, in wrapper_fn
    return func(self, *args, **kwargs)
  File "/opt/miniconda3/envs/lpn_py310/lib/python3.10/site-packages/wandb/sdk/wandb_run.py", line 1632, in _console_raw_callback
    self._backend.interface.publish_output_raw(name, data)
  File "/opt/miniconda3/envs/lpn_py310/lib/python3.10/site-packages/wandb/sdk/interface/interface.py", line 763, in publish_output_raw
    self._publish_output_raw(o)
  File "/opt/miniconda3/envs/lpn_py310/lib/python3.10/site-packages/wandb/sdk/interface/interface_shared.py", line 38, in _publish_output_raw
    self._publish(rec)
  File "/opt/miniconda3/envs/lpn_py310/lib/python3.10/site-packages/wandb/sdk/interface/interface_sock.py", line 39, in _publish
    self._sock_client.send_record_publish(record)
  File "/opt/miniconda3/envs/lpn_py310/lib/python3.10/site-packages/wandb/sdk/lib/sock_client.py", line 174, in send_record_publish
    self.send_server_request(server_req)
  File "/opt/miniconda3/envs/lpn_py310/lib/python3.10/site-packages/wandb/sdk/lib/sock_client.py", line 154, in send_server_request
    self._send_message(msg)
  File "/opt/miniconda3/envs/lpn_py310/lib/python3.10/site-packages/wandb/sdk/lib/sock_client.py", line 151, in _send_message
    self._sendall_with_error_handle(header + data)
  File "/opt/miniconda3/envs/lpn_py310/lib/python3.10/site-packages/wandb/sdk/lib/sock_client.py", line 130, in _sendall_with_error_handle
    sent = self._sock.send(data)
BrokenPipeError: [Errno 32] Broken pipe
2025-05-08 17:26:42,362 INFO    MainThread:48740 [jupyter.py:save_ipynb():401] [no run ID] not saving jupyter notebook
2025-05-08 17:26:42,362 INFO    MainThread:48740 [wandb_init.py:_pre_run_cell_hook():602] [no run ID] pausing backend
2025-05-08 17:26:42,364 ERROR   MainThread:48740 [redirect.py:_on_write():664] [no run ID] error in stdout callback
Traceback (most recent call last):
  File "/opt/miniconda3/envs/lpn_py310/lib/python3.10/site-packages/IPython/core/events.py", line 82, in trigger
    func(*args, **kwargs)
  File "/opt/miniconda3/envs/lpn_py310/lib/python3.10/site-packages/wandb/sdk/wandb_init.py", line 603, in _pre_run_cell_hook
    self.backend.interface.publish_pause()
  File "/opt/miniconda3/envs/lpn_py310/lib/python3.10/site-packages/wandb/sdk/interface/interface.py", line 771, in publish_pause
    self._publish_pause(pause)
  File "/opt/miniconda3/envs/lpn_py310/lib/python3.10/site-packages/wandb/sdk/interface/interface_shared.py", line 289, in _publish_pause
    self._publish(rec)
  File "/opt/miniconda3/envs/lpn_py310/lib/python3.10/site-packages/wandb/sdk/interface/interface_sock.py", line 39, in _publish
    self._sock_client.send_record_publish(record)
  File "/opt/miniconda3/envs/lpn_py310/lib/python3.10/site-packages/wandb/sdk/lib/sock_client.py", line 174, in send_record_publish
    self.send_server_request(server_req)
  File "/opt/miniconda3/envs/lpn_py310/lib/python3.10/site-packages/wandb/sdk/lib/sock_client.py", line 154, in send_server_request
    self._send_message(msg)
  File "/opt/miniconda3/envs/lpn_py310/lib/python3.10/site-packages/wandb/sdk/lib/sock_client.py", line 151, in _send_message
    self._sendall_with_error_handle(header + data)
  File "/opt/miniconda3/envs/lpn_py310/lib/python3.10/site-packages/wandb/sdk/lib/sock_client.py", line 130, in _sendall_with_error_handle
    sent = self._sock.send(data)
BrokenPipeError: [Errno 32] Broken pipe

During handling of the above exception, another exception occurred:

Traceback (most recent call last):
  File "/opt/miniconda3/envs/lpn_py310/lib/python3.10/site-packages/wandb/sdk/lib/redirect.py", line 662, in _on_write
    cb(written_data)
  File "/opt/miniconda3/envs/lpn_py310/lib/python3.10/site-packages/wandb/sdk/wandb_run.py", line 2487, in <lambda>
    lambda data: self._console_raw_callback("stdout", data),
  File "/opt/miniconda3/envs/lpn_py310/lib/python3.10/site-packages/wandb/sdk/wandb_run.py", line 406, in wrapper
    return func(self, *args, **kwargs)
  File "/opt/miniconda3/envs/lpn_py310/lib/python3.10/site-packages/wandb/sdk/wandb_run.py", line 464, in wrapper_fn
    return func(self, *args, **kwargs)
  File "/opt/miniconda3/envs/lpn_py310/lib/python3.10/site-packages/wandb/sdk/wandb_run.py", line 1632, in _console_raw_callback
    self._backend.interface.publish_output_raw(name, data)
  File "/opt/miniconda3/envs/lpn_py310/lib/python3.10/site-packages/wandb/sdk/interface/interface.py", line 763, in publish_output_raw
    self._publish_output_raw(o)
  File "/opt/miniconda3/envs/lpn_py310/lib/python3.10/site-packages/wandb/sdk/interface/interface_shared.py", line 38, in _publish_output_raw
    self._publish(rec)
  File "/opt/miniconda3/envs/lpn_py310/lib/python3.10/site-packages/wandb/sdk/interface/interface_sock.py", line 39, in _publish
    self._sock_client.send_record_publish(record)
  File "/opt/miniconda3/envs/lpn_py310/lib/python3.10/site-packages/wandb/sdk/lib/sock_client.py", line 174, in send_record_publish
    self.send_server_request(server_req)
  File "/opt/miniconda3/envs/lpn_py310/lib/python3.10/site-packages/wandb/sdk/lib/sock_client.py", line 154, in send_server_request
    self._send_message(msg)
  File "/opt/miniconda3/envs/lpn_py310/lib/python3.10/site-packages/wandb/sdk/lib/sock_client.py", line 151, in _send_message
    self._sendall_with_error_handle(header + data)
  File "/opt/miniconda3/envs/lpn_py310/lib/python3.10/site-packages/wandb/sdk/lib/sock_client.py", line 130, in _sendall_with_error_handle
    sent = self._sock.send(data)
BrokenPipeError: [Errno 32] Broken pipe
2025-05-08 17:26:42,366 ERROR   MainThread:48740 [redirect.py:_on_write():664] [no run ID] error in stdout callback
Traceback (most recent call last):
  File "/opt/miniconda3/envs/lpn_py310/lib/python3.10/site-packages/IPython/core/events.py", line 82, in trigger
    func(*args, **kwargs)
  File "/opt/miniconda3/envs/lpn_py310/lib/python3.10/site-packages/wandb/sdk/wandb_init.py", line 603, in _pre_run_cell_hook
    self.backend.interface.publish_pause()
  File "/opt/miniconda3/envs/lpn_py310/lib/python3.10/site-packages/wandb/sdk/interface/interface.py", line 771, in publish_pause
    self._publish_pause(pause)
  File "/opt/miniconda3/envs/lpn_py310/lib/python3.10/site-packages/wandb/sdk/interface/interface_shared.py", line 289, in _publish_pause
    self._publish(rec)
  File "/opt/miniconda3/envs/lpn_py310/lib/python3.10/site-packages/wandb/sdk/interface/interface_sock.py", line 39, in _publish
    self._sock_client.send_record_publish(record)
  File "/opt/miniconda3/envs/lpn_py310/lib/python3.10/site-packages/wandb/sdk/lib/sock_client.py", line 174, in send_record_publish
    self.send_server_request(server_req)
  File "/opt/miniconda3/envs/lpn_py310/lib/python3.10/site-packages/wandb/sdk/lib/sock_client.py", line 154, in send_server_request
    self._send_message(msg)
  File "/opt/miniconda3/envs/lpn_py310/lib/python3.10/site-packages/wandb/sdk/lib/sock_client.py", line 151, in _send_message
    self._sendall_with_error_handle(header + data)
  File "/opt/miniconda3/envs/lpn_py310/lib/python3.10/site-packages/wandb/sdk/lib/sock_client.py", line 130, in _sendall_with_error_handle
    sent = self._sock.send(data)
BrokenPipeError: [Errno 32] Broken pipe

During handling of the above exception, another exception occurred:

Traceback (most recent call last):
  File "/opt/miniconda3/envs/lpn_py310/lib/python3.10/site-packages/wandb/sdk/lib/redirect.py", line 662, in _on_write
    cb(written_data)
  File "/opt/miniconda3/envs/lpn_py310/lib/python3.10/site-packages/wandb/sdk/wandb_run.py", line 2487, in <lambda>
    lambda data: self._console_raw_callback("stdout", data),
  File "/opt/miniconda3/envs/lpn_py310/lib/python3.10/site-packages/wandb/sdk/wandb_run.py", line 406, in wrapper
    return func(self, *args, **kwargs)
  File "/opt/miniconda3/envs/lpn_py310/lib/python3.10/site-packages/wandb/sdk/wandb_run.py", line 464, in wrapper_fn
    return func(self, *args, **kwargs)
  File "/opt/miniconda3/envs/lpn_py310/lib/python3.10/site-packages/wandb/sdk/wandb_run.py", line 1632, in _console_raw_callback
    self._backend.interface.publish_output_raw(name, data)
  File "/opt/miniconda3/envs/lpn_py310/lib/python3.10/site-packages/wandb/sdk/interface/interface.py", line 763, in publish_output_raw
    self._publish_output_raw(o)
  File "/opt/miniconda3/envs/lpn_py310/lib/python3.10/site-packages/wandb/sdk/interface/interface_shared.py", line 38, in _publish_output_raw
    self._publish(rec)
  File "/opt/miniconda3/envs/lpn_py310/lib/python3.10/site-packages/wandb/sdk/interface/interface_sock.py", line 39, in _publish
    self._sock_client.send_record_publish(record)
  File "/opt/miniconda3/envs/lpn_py310/lib/python3.10/site-packages/wandb/sdk/lib/sock_client.py", line 174, in send_record_publish
    self.send_server_request(server_req)
  File "/opt/miniconda3/envs/lpn_py310/lib/python3.10/site-packages/wandb/sdk/lib/sock_client.py", line 154, in send_server_request
    self._send_message(msg)
  File "/opt/miniconda3/envs/lpn_py310/lib/python3.10/site-packages/wandb/sdk/lib/sock_client.py", line 151, in _send_message
    self._sendall_with_error_handle(header + data)
  File "/opt/miniconda3/envs/lpn_py310/lib/python3.10/site-packages/wandb/sdk/lib/sock_client.py", line 130, in _sendall_with_error_handle
    sent = self._sock.send(data)
BrokenPipeError: [Errno 32] Broken pipe
2025-05-08 17:26:42,537 INFO    MainThread:48740 [wandb_run.py:_finish():2314] finishing run stephen-marcou-eth-z-rich/deterministic_lpn4sine_cf_maml/5cni9044
2025-05-08 17:26:42,539 ERROR   MainThread:48740 [wandb_init.py:init():1660] [no run ID] error in wandb.init()
Traceback (most recent call last):
  File "/opt/miniconda3/envs/lpn_py310/lib/python3.10/site-packages/wandb/sdk/wandb_init.py", line 1650, in init
    return wi.init(run_settings, run_config, run_printer)
  File "/opt/miniconda3/envs/lpn_py310/lib/python3.10/site-packages/wandb/sdk/wandb_init.py", line 873, in init
    self._wl.finish_all_active_runs()
  File "/opt/miniconda3/envs/lpn_py310/lib/python3.10/site-packages/wandb/sdk/wandb_setup.py", line 150, in finish_all_active_runs
    run.finish()
  File "/opt/miniconda3/envs/lpn_py310/lib/python3.10/site-packages/wandb/sdk/wandb_run.py", line 406, in wrapper
    return func(self, *args, **kwargs)
  File "/opt/miniconda3/envs/lpn_py310/lib/python3.10/site-packages/wandb/sdk/wandb_run.py", line 503, in wrapper
    return func(self, *args, **kwargs)
  File "/opt/miniconda3/envs/lpn_py310/lib/python3.10/site-packages/wandb/sdk/wandb_run.py", line 451, in wrapper
    return func(self, *args, **kwargs)
  File "/opt/miniconda3/envs/lpn_py310/lib/python3.10/site-packages/wandb/sdk/wandb_run.py", line 2302, in finish
    return self._finish(exit_code)
  File "/opt/miniconda3/envs/lpn_py310/lib/python3.10/site-packages/wandb/sdk/wandb_run.py", line 406, in wrapper
    return func(self, *args, **kwargs)
  File "/opt/miniconda3/envs/lpn_py310/lib/python3.10/site-packages/wandb/sdk/wandb_run.py", line 2315, in _finish
    with telemetry.context(run=self) as tel:
  File "/opt/miniconda3/envs/lpn_py310/lib/python3.10/site-packages/wandb/sdk/lib/telemetry.py", line 42, in __exit__
    self._run._telemetry_callback(self._obj)
  File "/opt/miniconda3/envs/lpn_py310/lib/python3.10/site-packages/wandb/sdk/wandb_run.py", line 821, in _telemetry_callback
    self._telemetry_flush()
  File "/opt/miniconda3/envs/lpn_py310/lib/python3.10/site-packages/wandb/sdk/wandb_run.py", line 834, in _telemetry_flush
    self._backend.interface._publish_telemetry(self._telemetry_obj)
  File "/opt/miniconda3/envs/lpn_py310/lib/python3.10/site-packages/wandb/sdk/interface/interface_shared.py", line 60, in _publish_telemetry
    self._publish(rec)
  File "/opt/miniconda3/envs/lpn_py310/lib/python3.10/site-packages/wandb/sdk/interface/interface_sock.py", line 39, in _publish
    self._sock_client.send_record_publish(record)
  File "/opt/miniconda3/envs/lpn_py310/lib/python3.10/site-packages/wandb/sdk/lib/sock_client.py", line 174, in send_record_publish
    self.send_server_request(server_req)
  File "/opt/miniconda3/envs/lpn_py310/lib/python3.10/site-packages/wandb/sdk/lib/sock_client.py", line 154, in send_server_request
    self._send_message(msg)
  File "/opt/miniconda3/envs/lpn_py310/lib/python3.10/site-packages/wandb/sdk/lib/sock_client.py", line 151, in _send_message
    self._sendall_with_error_handle(header + data)
  File "/opt/miniconda3/envs/lpn_py310/lib/python3.10/site-packages/wandb/sdk/lib/sock_client.py", line 130, in _sendall_with_error_handle
    sent = self._sock.send(data)
BrokenPipeError: [Errno 32] Broken pipe
2025-05-08 17:26:44,603 INFO    MainThread:48740 [wandb_init.py:_post_run_cell_hook():613] [no run ID] resuming backend
2025-05-08 17:26:44,605 ERROR   MainThread:48740 [redirect.py:_on_write():664] [no run ID] error in stdout callback
Traceback (most recent call last):
  File "/opt/miniconda3/envs/lpn_py310/lib/python3.10/site-packages/IPython/core/events.py", line 82, in trigger
    func(*args, **kwargs)
  File "/opt/miniconda3/envs/lpn_py310/lib/python3.10/site-packages/wandb/sdk/wandb_init.py", line 614, in _post_run_cell_hook
    self.backend.interface.publish_resume()
  File "/opt/miniconda3/envs/lpn_py310/lib/python3.10/site-packages/wandb/sdk/interface/interface.py", line 779, in publish_resume
    self._publish_resume(resume)
  File "/opt/miniconda3/envs/lpn_py310/lib/python3.10/site-packages/wandb/sdk/interface/interface_shared.py", line 293, in _publish_resume
    self._publish(rec)
  File "/opt/miniconda3/envs/lpn_py310/lib/python3.10/site-packages/wandb/sdk/interface/interface_sock.py", line 39, in _publish
    self._sock_client.send_record_publish(record)
  File "/opt/miniconda3/envs/lpn_py310/lib/python3.10/site-packages/wandb/sdk/lib/sock_client.py", line 174, in send_record_publish
    self.send_server_request(server_req)
  File "/opt/miniconda3/envs/lpn_py310/lib/python3.10/site-packages/wandb/sdk/lib/sock_client.py", line 154, in send_server_request
    self._send_message(msg)
  File "/opt/miniconda3/envs/lpn_py310/lib/python3.10/site-packages/wandb/sdk/lib/sock_client.py", line 151, in _send_message
    self._sendall_with_error_handle(header + data)
  File "/opt/miniconda3/envs/lpn_py310/lib/python3.10/site-packages/wandb/sdk/lib/sock_client.py", line 130, in _sendall_with_error_handle
    sent = self._sock.send(data)
BrokenPipeError: [Errno 32] Broken pipe

During handling of the above exception, another exception occurred:

Traceback (most recent call last):
  File "/opt/miniconda3/envs/lpn_py310/lib/python3.10/site-packages/wandb/sdk/lib/redirect.py", line 662, in _on_write
    cb(written_data)
  File "/opt/miniconda3/envs/lpn_py310/lib/python3.10/site-packages/wandb/sdk/wandb_run.py", line 2487, in <lambda>
    lambda data: self._console_raw_callback("stdout", data),
  File "/opt/miniconda3/envs/lpn_py310/lib/python3.10/site-packages/wandb/sdk/wandb_run.py", line 406, in wrapper
    return func(self, *args, **kwargs)
  File "/opt/miniconda3/envs/lpn_py310/lib/python3.10/site-packages/wandb/sdk/wandb_run.py", line 464, in wrapper_fn
    return func(self, *args, **kwargs)
  File "/opt/miniconda3/envs/lpn_py310/lib/python3.10/site-packages/wandb/sdk/wandb_run.py", line 1632, in _console_raw_callback
    self._backend.interface.publish_output_raw(name, data)
  File "/opt/miniconda3/envs/lpn_py310/lib/python3.10/site-packages/wandb/sdk/interface/interface.py", line 763, in publish_output_raw
    self._publish_output_raw(o)
  File "/opt/miniconda3/envs/lpn_py310/lib/python3.10/site-packages/wandb/sdk/interface/interface_shared.py", line 38, in _publish_output_raw
    self._publish(rec)
  File "/opt/miniconda3/envs/lpn_py310/lib/python3.10/site-packages/wandb/sdk/interface/interface_sock.py", line 39, in _publish
    self._sock_client.send_record_publish(record)
  File "/opt/miniconda3/envs/lpn_py310/lib/python3.10/site-packages/wandb/sdk/lib/sock_client.py", line 174, in send_record_publish
    self.send_server_request(server_req)
  File "/opt/miniconda3/envs/lpn_py310/lib/python3.10/site-packages/wandb/sdk/lib/sock_client.py", line 154, in send_server_request
    self._send_message(msg)
  File "/opt/miniconda3/envs/lpn_py310/lib/python3.10/site-packages/wandb/sdk/lib/sock_client.py", line 151, in _send_message
    self._sendall_with_error_handle(header + data)
  File "/opt/miniconda3/envs/lpn_py310/lib/python3.10/site-packages/wandb/sdk/lib/sock_client.py", line 130, in _sendall_with_error_handle
    sent = self._sock.send(data)
BrokenPipeError: [Errno 32] Broken pipe
2025-05-08 17:26:44,607 ERROR   MainThread:48740 [redirect.py:_on_write():664] [no run ID] error in stdout callback
Traceback (most recent call last):
  File "/opt/miniconda3/envs/lpn_py310/lib/python3.10/site-packages/IPython/core/events.py", line 82, in trigger
    func(*args, **kwargs)
  File "/opt/miniconda3/envs/lpn_py310/lib/python3.10/site-packages/wandb/sdk/wandb_init.py", line 614, in _post_run_cell_hook
    self.backend.interface.publish_resume()
  File "/opt/miniconda3/envs/lpn_py310/lib/python3.10/site-packages/wandb/sdk/interface/interface.py", line 779, in publish_resume
    self._publish_resume(resume)
  File "/opt/miniconda3/envs/lpn_py310/lib/python3.10/site-packages/wandb/sdk/interface/interface_shared.py", line 293, in _publish_resume
    self._publish(rec)
  File "/opt/miniconda3/envs/lpn_py310/lib/python3.10/site-packages/wandb/sdk/interface/interface_sock.py", line 39, in _publish
    self._sock_client.send_record_publish(record)
  File "/opt/miniconda3/envs/lpn_py310/lib/python3.10/site-packages/wandb/sdk/lib/sock_client.py", line 174, in send_record_publish
    self.send_server_request(server_req)
  File "/opt/miniconda3/envs/lpn_py310/lib/python3.10/site-packages/wandb/sdk/lib/sock_client.py", line 154, in send_server_request
    self._send_message(msg)
  File "/opt/miniconda3/envs/lpn_py310/lib/python3.10/site-packages/wandb/sdk/lib/sock_client.py", line 151, in _send_message
    self._sendall_with_error_handle(header + data)
  File "/opt/miniconda3/envs/lpn_py310/lib/python3.10/site-packages/wandb/sdk/lib/sock_client.py", line 130, in _sendall_with_error_handle
    sent = self._sock.send(data)
BrokenPipeError: [Errno 32] Broken pipe

During handling of the above exception, another exception occurred:

Traceback (most recent call last):
  File "/opt/miniconda3/envs/lpn_py310/lib/python3.10/site-packages/wandb/sdk/lib/redirect.py", line 662, in _on_write
    cb(written_data)
  File "/opt/miniconda3/envs/lpn_py310/lib/python3.10/site-packages/wandb/sdk/wandb_run.py", line 2487, in <lambda>
    lambda data: self._console_raw_callback("stdout", data),
  File "/opt/miniconda3/envs/lpn_py310/lib/python3.10/site-packages/wandb/sdk/wandb_run.py", line 406, in wrapper
    return func(self, *args, **kwargs)
  File "/opt/miniconda3/envs/lpn_py310/lib/python3.10/site-packages/wandb/sdk/wandb_run.py", line 464, in wrapper_fn
    return func(self, *args, **kwargs)
  File "/opt/miniconda3/envs/lpn_py310/lib/python3.10/site-packages/wandb/sdk/wandb_run.py", line 1632, in _console_raw_callback
    self._backend.interface.publish_output_raw(name, data)
  File "/opt/miniconda3/envs/lpn_py310/lib/python3.10/site-packages/wandb/sdk/interface/interface.py", line 763, in publish_output_raw
    self._publish_output_raw(o)
  File "/opt/miniconda3/envs/lpn_py310/lib/python3.10/site-packages/wandb/sdk/interface/interface_shared.py", line 38, in _publish_output_raw
    self._publish(rec)
  File "/opt/miniconda3/envs/lpn_py310/lib/python3.10/site-packages/wandb/sdk/interface/interface_sock.py", line 39, in _publish
    self._sock_client.send_record_publish(record)
  File "/opt/miniconda3/envs/lpn_py310/lib/python3.10/site-packages/wandb/sdk/lib/sock_client.py", line 174, in send_record_publish
    self.send_server_request(server_req)
  File "/opt/miniconda3/envs/lpn_py310/lib/python3.10/site-packages/wandb/sdk/lib/sock_client.py", line 154, in send_server_request
    self._send_message(msg)
  File "/opt/miniconda3/envs/lpn_py310/lib/python3.10/site-packages/wandb/sdk/lib/sock_client.py", line 151, in _send_message
    self._sendall_with_error_handle(header + data)
  File "/opt/miniconda3/envs/lpn_py310/lib/python3.10/site-packages/wandb/sdk/lib/sock_client.py", line 130, in _sendall_with_error_handle
    sent = self._sock.send(data)
BrokenPipeError: [Errno 32] Broken pipe
